{
  "version": 8,
  "blockIdVersion": 10,
  "anchorX": 0,
  "anchorY": 0,
  "anchorZ": 0,
  "blocks": [
    {
      "x": -21,
      "y": 0,
      "z": -19,
      "name": "Soil_Grass_Cold"
    },
    {
      "x": -21,
      "y": 0,
      "z": -18,
      "name": "Soil_Grass_Cold"
    },
    {
      "x": -21,
      "y": 0,
      "z": -17,
      "name": "Soil_Grass_Cold"
    },
    {
      "x": -21,
      "y": 0,
      "z": -16,
      "name": "Soil_Grass_Cold"
    },
    {
      "x": -21,
      "y": 0,
      "z": -15,
      "name": "Soil_Grass_Cold"
    },
    {
      "x": -21,
      "y": 0,
      "z": -14,
      "name": "Soil_Grass_Cold"
    },
    {
      "x": -21,
      "y": 0,
      "z": -13,
      "name": "Soil_Grass_Cold"
    },
    {
      "x": -21,
      "y": 0,
      "z": -12,
      "name": "Soil_Grass_Cold"
    },
    {
      "x": -21,
      "y": 0,
      "z": -11,
      "name": "Soil_Grass_Cold"
    },
    {
      "x": -21,
      "y": 1,
      "z": -11,
      "name": "Plant_Flower_Common_Red2"
    },
    {
      "x": -21,
      "y": 0,
      "z": -10,
      "name": "Soil_Grass_Cold"
    },
    {
      "x": -21,
      "y": 0,
      "z": -9,
      "name": "Soil_Grass_Cold"
    },
    {
      "x": -21,
      "y": 0,
      "z": -8,
      "name": "Soil_Grass_Cold"
    },
    {
      "x": -21,
      "y": 0,
      "z": -7,
      "name": "Soil_Grass_Cold"
    },
    {
      "x": -21,
      "y": 0,
      "z": -6,
      "name": "Soil_Grass_Cold"
    },
    {
      "x": -21,
      "y": 0,
      "z": -5,
      "name": "Soil_Grass_Cold"
    },
    {
      "x": -21,
      "y": 1,
      "z": -5,
      "name": "Plant_Flower_Common_Yellow2"
    },
    {
      "x": -21,
      "y": 0,
      "z": -4,
      "name": "Soil_Grass_Cold"
    },
    {
      "x": -21,
      "y": 0,
      "z": -3,
      "name": "Soil_Grass_Cold"
    },
    {
      "x": -21,
      "y": 0,
      "z": -2,
      "name": "Soil_Grass_Cold"
    },
    {
      "x": -21,
      "y": 0,
      "z": -1,
      "name": "Soil_Grass_Cold"
    },
    {
      "x": -21,
      "y": 0,
      "z": 0,
      "name": "Soil_Grass_Cold"
    },
    {
      "x": -21,
      "y": 0,
      "z": 1,
      "name": "Soil_Grass_Cold"
    },
    {
      "x": -21,
      "y": 1,
      "z": 1,
      "name": "Plant_Flower_Common_White2"
    },
    {
      "x": -21,
      "y": 0,
      "z": 2,
      "name": "Soil_Grass_Cold"
    },
    {
      "x": -21,
      "y": 0,
      "z": 3,
      "name": "Soil_Mud_Dry"
    },
    {
      "x": -21,
      "y": 0,
      "z": 4,
      "name": "Soil_Pathway"
    },
    {
      "x": -21,
      "y": 0,
      "z": 5,
      "name": "Soil_Pathway"
    },
    {
      "x": -21,
      "y": 0,
      "z": 6,
      "name": "Soil_Pathway"
    },
    {
      "x": -21,
      "y": 0,
      "z": 7,
      "name": "Soil_Grass_Cold"
    },
    {
      "x": -21,
      "y": 1,
      "z": 7,
      "name": "Plant_Flower_Water_Duckweed"
    },
    {
      "x": -21,
      "y": 0,
      "z": 8,
      "name": "Soil_Grass_Cold"
    },
    {
      "x": -21,
      "y": 1,
      "z": 8,
      "name": "Plant_Flower_Common_Red2"
    },
    {
      "x": -21,
      "y": 0,
      "z": 9,
      "name": "Soil_Grass_Cold"
    },
    {
      "x": -21,
      "y": 1,
      "z": 9,
      "name": "Plant_Grass_Jungle",
      "support": 15
    },
    {
      "x": -21,
      "y": 0,
      "z": 10,
      "name": "Soil_Grass_Cold"
    },
    {
      "x": -21,
      "y": 0,
      "z": 11,
      "name": "Soil_Grass_Cold"
    },
    {
      "x": -21,
      "y": 1,
      "z": 11,
      "name": "Plant_Fern_Wet_Big",
      "support": 15
    },
    {
      "x": -21,
      "y": 0,
      "z": 12,
      "name": "Soil_Grass_Cold"
    },
    {
      "x": -21,
      "y": 0,
      "z": 13,
      "name": "Soil_Grass_Cold"
    },
    {
      "x": -21,
      "y": 1,
      "z": 13,
      "name": "Plant_Flower_Water_Duckweed"
    },
    {
      "x": -21,
      "y": 0,
      "z": 14,
      "name": "Soil_Grass_Cold"
    },
    {
      "x": -21,
      "y": 1,
      "z": 14,
      "name": "Plant_Grass_Jungle",
      "support": 15
    },
    {
      "x": -21,
      "y": 0,
      "z": 15,
      "name": "Soil_Grass_Cold"
    },
    {
      "x": -21,
      "y": 0,
      "z": 16,
      "name": "Soil_Grass_Cold"
    },
    {
      "x": -20,
      "y": 0,
      "z": -21,
      "name": "Soil_Grass_Cold"
    },
    {
      "x": -20,
      "y": 0,
      "z": -20,
      "name": "Soil_Grass_Cold"
    },
    {
      "x": -20,
      "y": 0,
      "z": -19,
      "name": "Rock_Stone"
    },
    {
      "x": -20,
      "y": 0,
      "z": -18,
      "name": "Soil_Grass_Cold"
    },
    {
      "x": -20,
      "y": 1,
      "z": -18,
      "name": "Rock_Stone_Cobble_Half"
    },
    {
      "x": -20,
      "y": 0,
      "z": -17,
      "name": "Soil_Grass_Cold"
    },
    {
      "x": -20,
      "y": 1,
      "z": -17,
      "name": "Plant_Grass_Jungle",
      "support": 15
    },
    {
      "x": -20,
      "y": 0,
      "z": -16,
      "name": "Soil_Grass_Cold"
    },
    {
      "x": -20,
      "y": 1,
      "z": -16,
      "name": "Plant_Grass_Jungle",
      "support": 15
    },
    {
      "x": -20,
      "y": 0,
      "z": -15,
      "name": "Soil_Grass_Cold"
    },
    {
      "x": -20,
      "y": 0,
      "z": -14,
      "name": "Soil_Grass_Cold"
    },
    {
      "x": -20,
      "y": 0,
      "z": -13,
      "name": "Soil_Grass_Cold"
    },
    {
      "x": -20,
      "y": 1,
      "z": -13,
      "name": "Plant_Fern_Wet_Big",
      "support": 15
    },
    {
      "x": -20,
      "y": 0,
      "z": -12,
      "name": "Soil_Grass_Cold"
    },
    {
      "x": -20,
      "y": 0,
      "z": -11,
      "name": "Soil_Grass_Cold"
    },
    {
      "x": -20,
      "y": 0,
      "z": -10,
      "name": "Soil_Grass_Cold"
    },
    {
      "x": -20,
      "y": 0,
      "z": -9,
      "name": "Soil_Grass_Cold"
    },
    {
      "x": -20,
      "y": 0,
      "z": -8,
      "name": "Soil_Grass_Cold"
    },
    {
      "x": -20,
      "y": 1,
      "z": -8,
      "name": "Plant_Grass_Jungle",
      "support": 15
    },
    {
      "x": -20,
      "y": 0,
      "z": -7,
      "name": "Soil_Grass_Cold"
    },
    {
      "x": -20,
      "y": 1,
      "z": -7,
      "name": "Plant_Grass_Jungle",
      "support": 15
    },
    {
      "x": -20,
      "y": 0,
      "z": -6,
      "name": "Soil_Grass_Cold"
    },
    {
      "x": -20,
      "y": 0,
      "z": -5,
      "name": "Soil_Grass_Cold"
    },
    {
      "x": -20,
      "y": 0,
      "z": -4,
      "name": "Soil_Grass_Cold"
    },
    {
      "x": -20,
      "y": 1,
      "z": -4,
      "name": "Plant_Grass_Lush_Tall",
      "support": 15
    },
    {
      "x": -20,
      "y": 0,
      "z": -3,
      "name": "Soil_Grass_Cold"
    },
    {
      "x": -20,
      "y": 0,
      "z": -2,
      "name": "Soil_Grass_Cold"
    },
    {
      "x": -20,
      "y": 0,
      "z": -1,
      "name": "Soil_Grass_Cold"
    },
    {
      "x": -20,
      "y": 1,
      "z": -1,
      "name": "Plant_Grass_Jungle",
      "support": 15
    },
    {
      "x": -20,
      "y": 0,
      "z": 0,
      "name": "Soil_Grass_Cold"
    },
    {
      "x": -20,
      "y": 0,
      "z": 1,
      "name": "Soil_Grass_Cold"
    },
    {
      "x": -20,
      "y": 0,
      "z": 2,
      "name": "Soil_Pathway"
    },
    {
      "x": -20,
      "y": 0,
      "z": 3,
      "name": "Soil_Pathway"
    },
    {
      "x": -20,
      "y": 0,
      "z": 4,
      "name": "Soil_Pathway"
    },
    {
      "x": -20,
      "y": 0,
      "z": 5,
      "name": "Soil_Mud_Dry"
    },
    {
      "x": -20,
      "y": 0,
      "z": 6,
      "name": "Soil_Pathway"
    },
    {
      "x": -20,
      "y": 0,
      "z": 7,
      "name": "Soil_Grass_Cold"
    },
    {
      "x": -20,
      "y": 0,
      "z": 8,
      "name": "Soil_Grass_Cold"
    },
    {
      "x": -20,
      "y": 1,
      "z": 8,
      "name": "Plant_Flower_Water_Duckweed"
    },
    {
      "x": -20,
      "y": 0,
      "z": 9,
      "name": "Soil_Grass_Cold"
    },
    {
      "x": -20,
      "y": 0,
      "z": 10,
      "name": "Soil_Grass_Cold"
    },
    {
      "x": -20,
      "y": 1,
      "z": 10,
      "name": "Plant_Grass_Lush_Tall",
      "support": 15
    },
    {
      "x": -20,
      "y": 0,
      "z": 11,
      "name": "Soil_Grass_Cold"
    },
    {
      "x": -20,
      "y": 0,
      "z": 12,
      "name": "Soil_Grass_Cold"
    },
    {
      "x": -20,
      "y": 1,
      "z": 12,
      "name": "Plant_Flower_Common_Violet"
    },
    {
      "x": -20,
      "y": 0,
      "z": 13,
      "name": "Soil_Grass_Cold"
    },
    {
      "x": -20,
      "y": 0,
      "z": 14,
      "name": "Soil_Grass_Cold"
    },
    {
      "x": -20,
      "y": 0,
      "z": 15,
      "name": "Soil_Grass_Cold"
    },
    {
      "x": -20,
      "y": 0,
      "z": 16,
      "name": "Soil_Grass_Cold"
    },
    {
      "x": -20,
      "y": 1,
      "z": 16,
      "name": "Plant_Grass_Jungle",
      "support": 15
    },
    {
      "x": -20,
      "y": 0,
      "z": 17,
      "name": "Soil_Grass_Cold"
    },
    {
      "x": -20,
      "y": 0,
      "z": 18,
      "name": "Soil_Grass_Cold"
    },
    {
      "x": -19,
      "y": 0,
      "z": -22,
      "name": "Soil_Grass_Cold"
    },
    {
      "x": -19,
      "y": 0,
      "z": -21,
      "name": "Soil_Grass_Cold"
    },
    {
      "x": -19,
      "y": 1,
      "z": -21,
      "name": "Plant_Grass_Jungle",
      "support": 15
    },
    {
      "x": -19,
      "y": 0,
      "z": -20,
      "name": "Soil_Grass_Cold"
    },
    {
      "x": -19,
      "y": 0,
      "z": -19,
      "name": "Soil_Grass_Cold"
    },
    {
      "x": -19,
      "y": 1,
      "z": -19,
      "name": "Rock_Stone_Cobble_Stairs",
      "rotation": 3
    },
    {
      "x": -19,
      "y": 0,
      "z": -18,
      "name": "Soil_Grass_Cold"
    },
    {
      "x": -19,
      "y": 1,
      "z": -18,
      "name": "Ore_Copper_Stone"
    },
    {
      "x": -19,
      "y": 0,
      "z": -17,
      "name": "Soil_Grass_Cold"
    },
    {
      "x": -19,
      "y": 1,
      "z": -17,
      "name": "Rock_Stone"
    },
    {
      "x": -19,
      "y": 2,
      "z": -17,
      "name": "Rock_Stone_Mossy"
    },
    {
      "x": -19,
      "y": 3,
      "z": -17,
      "name": "Rubble_Stone",
      "support": 15
    },
    {
      "x": -19,
      "y": 0,
      "z": -16,
      "name": "Soil_Grass_Cold"
    },
    {
      "x": -19,
      "y": 1,
      "z": -16,
      "name": "Rock_Stone_Cobble_Half",
      "rotation": 4
    },
    {
      "x": -19,
      "y": 0,
      "z": -15,
      "name": "Soil_Grass_Cold"
    },
    {
      "x": -19,
      "y": 1,
      "z": -15,
      "name": "Plant_Grass_Lush_Tall",
      "support": 15
    },
    {
      "x": -19,
      "y": 0,
      "z": -14,
      "name": "Soil_Grass_Cold"
    },
    {
      "x": -19,
      "y": 0,
      "z": -13,
      "name": "Soil_Grass_Cold"
    },
    {
      "x": -19,
      "y": 0,
      "z": -12,
      "name": "Soil_Grass_Cold"
    },
    {
      "x": -19,
      "y": 0,
      "z": -11,
      "name": "Soil_Grass_Cold"
    },
    {
      "x": -19,
      "y": 1,
      "z": -11,
      "name": "Plant_Grass_Jungle",
      "support": 15
    },
    {
      "x": -19,
      "y": 0,
      "z": -10,
      "name": "Soil_Grass_Cold"
    },
    {
      "x": -19,
      "y": 0,
      "z": -9,
      "name": "Soil_Grass_Cold"
    },
    {
      "x": -19,
      "y": 0,
      "z": -8,
      "name": "Soil_Grass_Cold"
    },
    {
      "x": -19,
      "y": 1,
      "z": -8,
      "name": "Plant_Flower_Common_White2"
    },
    {
      "x": -19,
      "y": 0,
      "z": -7,
      "name": "Soil_Grass_Cold"
    },
    {
      "x": -19,
      "y": 0,
      "z": -6,
      "name": "Soil_Grass_Cold"
    },
    {
      "x": -19,
      "y": 0,
      "z": -5,
      "name": "Soil_Grass_Cold"
    },
    {
      "x": -19,
      "y": 0,
      "z": -4,
      "name": "Soil_Grass_Cold"
    },
    {
      "x": -19,
      "y": 0,
      "z": -3,
      "name": "Soil_Grass_Cold"
    },
    {
      "x": -19,
      "y": 0,
      "z": -2,
      "name": "Soil_Grass_Cold"
    },
    {
      "x": -19,
      "y": 0,
      "z": -1,
      "name": "Soil_Grass_Cold"
    },
    {
      "x": -19,
      "y": 0,
      "z": 0,
      "name": "Soil_Grass_Cold"
    },
    {
      "x": -19,
      "y": 0,
      "z": 1,
      "name": "Soil_Grass_Cold"
    },
    {
      "x": -19,
      "y": 0,
      "z": 2,
      "name": "Soil_Pathway"
    },
    {
      "x": -19,
      "y": 0,
      "z": 3,
      "name": "Soil_Pathway"
    },
    {
      "x": -19,
      "y": 0,
      "z": 4,
      "name": "Soil_Pathway"
    },
    {
      "x": -19,
      "y": 0,
      "z": 5,
      "name": "Soil_Pathway"
    },
    {
      "x": -19,
      "y": 0,
      "z": 6,
      "name": "Soil_Mud_Dry"
    },
    {
      "x": -19,
      "y": 0,
      "z": 7,
      "name": "Soil_Pathway"
    },
    {
      "x": -19,
      "y": 0,
      "z": 8,
      "name": "Soil_Grass_Cold"
    },
    {
      "x": -19,
      "y": 0,
      "z": 9,
      "name": "Soil_Grass_Cold"
    },
    {
      "x": -19,
      "y": 1,
      "z": 9,
      "name": "Plant_Grass_Jungle",
      "support": 15
    },
    {
      "x": -19,
      "y": 0,
      "z": 10,
      "name": "Soil_Grass_Cold"
    },
    {
      "x": -19,
      "y": 0,
      "z": 11,
      "name": "Soil_Grass_Cold"
    },
    {
      "x": -19,
      "y": 0,
      "z": 12,
      "name": "Soil_Grass_Cold"
    },
    {
      "x": -19,
      "y": 1,
      "z": 12,
      "name": "Plant_Flower_Water_Duckweed"
    },
    {
      "x": -19,
      "y": 0,
      "z": 13,
      "name": "Soil_Grass_Cold"
    },
    {
      "x": -19,
      "y": 1,
      "z": 13,
      "name": "Plant_Flower_Water_Duckweed"
    },
    {
      "x": -19,
      "y": 0,
      "z": 14,
      "name": "Soil_Grass_Cold"
    },
    {
      "x": -19,
      "y": 0,
      "z": 15,
      "name": "Soil_Grass_Cold"
    },
    {
      "x": -19,
      "y": 1,
      "z": 15,
      "name": "Plant_Flower_Water_Duckweed"
    },
    {
      "x": -19,
      "y": 0,
      "z": 16,
      "name": "Soil_Grass_Cold"
    },
    {
      "x": -19,
      "y": 1,
      "z": 16,
      "name": "Plant_Flower_Common_Yellow2"
    },
    {
      "x": -19,
      "y": 0,
      "z": 17,
      "name": "Soil_Grass_Cold"
    },
    {
      "x": -19,
      "y": 0,
      "z": 18,
      "name": "Soil_Grass_Cold"
    },
    {
      "x": -19,
      "y": 0,
      "z": 19,
      "name": "Soil_Grass_Cold"
    },
    {
      "x": -19,
      "y": 1,
      "z": 19,
      "name": "Plant_Grass_Jungle",
      "support": 15
    },
    {
      "x": -19,
      "y": 0,
      "z": 20,
      "name": "Soil_Grass_Cold"
    },
    {
      "x": -18,
      "y": 0,
      "z": -23,
      "name": "Soil_Grass_Cold"
    },
    {
      "x": -18,
      "y": 0,
      "z": -22,
      "name": "Soil_Grass_Cold"
    },
    {
      "x": -18,
      "y": 1,
      "z": -22,
      "name": "Plant_Grass_Jungle",
      "support": 15
    },
    {
      "x": -18,
      "y": 0,
      "z": -21,
      "name": "Soil_Grass_Cold"
    },
    {
      "x": -18,
      "y": 0,
      "z": -20,
      "name": "Rock_Stone_Mossy"
    },
    {
      "x": -18,
      "y": 0,
      "z": -19,
      "name": "Soil_Grass_Cold"
    },
    {
      "x": -18,
      "y": 1,
      "z": -19,
      "name": "Rock_Stone_Cobble"
    },
    {
      "x": -18,
      "y": 0,
      "z": -18,
      "name": "Soil_Grass_Cold"
    },
    {
      "x": -18,
      "y": 1,
      "z": -18,
      "name": "Rock_Stone"
    },
    {
      "x": -18,
      "y": 2,
      "z": -18,
      "name": "Ore_Iron_Stone"
    },
    {
      "x": -18,
      "y": 0,
      "z": -17,
      "name": "Soil_Grass_Cold"
    },
    {
      "x": -18,
      "y": 1,
      "z": -17,
      "name": "Rock_Stone"
    },
    {
      "x": -18,
      "y": 2,
      "z": -17,
      "name": "Rock_Stone_Cobble_Half"
    },
    {
      "x": -18,
      "y": 0,
      "z": -16,
      "name": "Rock_Stone_Mossy"
    },
    {
      "x": -18,
      "y": 0,
      "z": -15,
      "name": "Soil_Grass_Cold"
    },
    {
      "x": -18,
      "y": 0,
      "z": -14,
      "name": "Soil_Grass_Cold"
    },
    {
      "x": -18,
      "y": 0,
      "z": -13,
      "name": "Soil_Grass_Cold"
    },
    {
      "x": -18,
      "y": 0,
      "z": -12,
      "name": "Soil_Grass_Cold"
    },
    {
      "x": -18,
      "y": 0,
      "z": -11,
      "name": "Soil_Grass_Cold"
    },
    {
      "x": -18,
      "y": 0,
      "z": -10,
      "name": "Soil_Grass_Cold"
    },
    {
      "x": -18,
      "y": 0,
      "z": -9,
      "name": "Soil_Grass_Cold"
    },
    {
      "x": -18,
      "y": 0,
      "z": -8,
      "name": "Soil_Grass_Cold"
    },
    {
      "x": -18,
      "y": 0,
      "z": -7,
      "name": "Soil_Grass_Cold"
    },
    {
      "x": -18,
      "y": 1,
      "z": -7,
      "name": "Plant_Grass_Lush_Tall",
      "support": 15
    },
    {
      "x": -18,
      "y": 0,
      "z": -6,
      "name": "Soil_Grass_Cold"
    },
    {
      "x": -18,
      "y": 0,
      "z": -5,
      "name": "Soil_Grass_Cold"
    },
    {
      "x": -18,
      "y": 0,
      "z": -4,
      "name": "Soil_Grass_Cold"
    },
    {
      "x": -18,
      "y": 0,
      "z": -3,
      "name": "Soil_Grass_Cold"
    },
    {
      "x": -18,
      "y": 1,
      "z": -3,
      "name": "Plant_Grass_Jungle",
      "support": 15
    },
    {
      "x": -18,
      "y": 0,
      "z": -2,
      "name": "Soil_Grass_Cold"
    },
    {
      "x": -18,
      "y": 0,
      "z": -1,
      "name": "Soil_Grass_Cold"
    },
    {
      "x": -18,
      "y": 1,
      "z": -1,
      "name": "Plant_Fern_Wet_Big",
      "support": 15
    },
    {
      "x": -18,
      "y": 0,
      "z": 0,
      "name": "Soil_Grass_Cold"
    },
    {
      "x": -18,
      "y": 0,
      "z": 1,
      "name": "Soil_Pathway"
    },
    {
      "x": -18,
      "y": 0,
      "z": 2,
      "name": "Soil_Mud_Dry"
    },
    {
      "x": -18,
      "y": 0,
      "z": 3,
      "name": "Soil_Pathway"
    },
    {
      "x": -18,
      "y": 0,
      "z": 4,
      "name": "Soil_Pathway"
    },
    {
      "x": -18,
      "y": 0,
      "z": 5,
      "name": "Soil_Pathway"
    },
    {
      "x": -18,
      "y": 0,
      "z": 6,
      "name": "Soil_Mud_Dry"
    },
    {
      "x": -18,
      "y": 0,
      "z": 7,
      "name": "Soil_Mud_Dry"
    },
    {
      "x": -18,
      "y": 0,
      "z": 8,
      "name": "Soil_Pathway"
    },
    {
      "x": -18,
      "y": 0,
      "z": 9,
      "name": "Soil_Grass_Cold"
    },
    {
      "x": -18,
      "y": 0,
      "z": 10,
      "name": "Soil_Grass_Cold"
    },
    {
      "x": -18,
      "y": 0,
      "z": 11,
      "name": "Soil_Grass_Cold"
    },
    {
      "x": -18,
      "y": 1,
      "z": 11,
      "name": "Plant_Flower_Water_Duckweed"
    },
    {
      "x": -18,
      "y": 0,
      "z": 12,
      "name": "Soil_Grass_Cold"
    },
    {
      "x": -18,
      "y": 1,
      "z": 12,
      "name": "Plant_Flower_Water_Duckweed"
    },
    {
      "x": -18,
      "y": 0,
      "z": 13,
      "name": "Soil_Grass_Cold"
    },
    {
      "x": -18,
      "y": 0,
      "z": 14,
      "name": "Soil_Grass_Cold"
    },
    {
      "x": -18,
      "y": 0,
      "z": 15,
      "name": "Soil_Grass_Cold"
    },
    {
      "x": -18,
      "y": 0,
      "z": 16,
      "name": "Soil_Grass_Cold"
    },
    {
      "x": -18,
      "y": 0,
      "z": 17,
      "name": "Soil_Grass_Cold"
    },
    {
      "x": -18,
      "y": 0,
      "z": 18,
      "name": "Soil_Grass_Cold"
    },
    {
      "x": -18,
      "y": 0,
      "z": 19,
      "name": "Soil_Grass_Cold"
    },
    {
      "x": -18,
      "y": 0,
      "z": 20,
      "name": "Soil_Grass_Cold"
    },
    {
      "x": -18,
      "y": 0,
      "z": 21,
      "name": "Soil_Grass_Cold"
    },
    {
      "x": -18,
      "y": 0,
      "z": 22,
      "name": "Soil_Grass_Cold"
    },
    {
      "x": -17,
      "y": 0,
      "z": -23,
      "name": "Soil_Grass_Cold"
    },
    {
      "x": -17,
      "y": 0,
      "z": -22,
      "name": "Soil_Grass_Cold"
    },
    {
      "x": -17,
      "y": 0,
      "z": -21,
      "name": "Soil_Grass_Cold"
    },
    {
      "x": -17,
      "y": 1,
      "z": -21,
      "name": "Plant_Grass_Lush_Tall",
      "support": 15
    },
    {
      "x": -17,
      "y": 0,
      "z": -20,
      "name": "Soil_Grass_Cold"
    },
    {
      "x": -17,
      "y": 1,
      "z": -20,
      "name": "Rubble_Stone",
      "support": 15
    },
    {
      "x": -17,
      "y": 0,
      "z": -19,
      "name": "Soil_Grass_Cold"
    },
    {
      "x": -17,
      "y": 1,
      "z": -19,
      "name": "Rock_Stone"
    },
    {
      "x": -17,
      "y": 0,
      "z": -18,
      "name": "Soil_Grass_Cold"
    },
    {
      "x": -17,
      "y": 1,
      "z": -18,
      "name": "Rock_Stone_Mossy"
    },
    {
      "x": -17,
      "y": 2,
      "z": -18,
      "name": "Rock_Stone_Cobble_Stairs",
      "rotation": 1
    },
    {
      "x": -17,
      "y": 0,
      "z": -17,
      "name": "Soil_Grass_Cold"
    },
    {
      "x": -17,
      "y": 1,
      "z": -17,
      "name": "Rock_Stone_Cobble_Stairs"
    },
    {
      "x": -17,
      "y": 0,
      "z": -16,
      "name": "Soil_Grass_Cold"
    },
    {
      "x": -17,
      "y": 1,
      "z": -16,
      "name": "Rubble_Stone_Mossy",
      "support": 15
    },
    {
      "x": -17,
      "y": 0,
      "z": -15,
      "name": "Soil_Grass_Cold"
    },
    {
      "x": -17,
      "y": 0,
      "z": -14,
      "name": "Soil_Grass_Cold"
    },
    {
      "x": -17,
      "y": 1,
      "z": -14,
      "name": "Plant_Flower_Common_Violet"
    },
    {
      "x": -17,
      "y": 0,
      "z": -13,
      "name": "Soil_Grass_Cold"
    },
    {
      "x": -17,
      "y": 0,
      "z": -12,
      "name": "Soil_Grass_Cold"
    },
    {
      "x": -17,
      "y": 0,
      "z": -11,
      "name": "Soil_Grass_Cold"
    },
    {
      "x": -17,
      "y": 0,
      "z": -10,
      "name": "Soil_Grass_Cold"
    },
    {
      "x": -17,
      "y": 1,
      "z": -10,
      "name": "Plant_Fern_Wet_Big",
      "support": 15
    },
    {
      "x": -17,
      "y": 0,
      "z": -9,
      "name": "Soil_Grass_Cold"
    },
    {
      "x": -17,
      "y": 1,
      "z": -9,
      "name": "Plant_Flower_Common_Red2"
    },
    {
      "x": -17,
      "y": 0,
      "z": -8,
      "name": "Soil_Grass_Cold"
    },
    {
      "x": -17,
      "y": 0,
      "z": -7,
      "name": "Soil_Grass_Cold"
    },
    {
      "x": -17,
      "y": 0,
      "z": -6,
      "name": "Soil_Grass_Cold"
    },
    {
      "x": -17,
      "y": 0,
      "z": -5,
      "name": "Soil_Grass_Cold"
    },
    {
      "x": -17,
      "y": 0,
      "z": -4,
      "name": "Soil_Grass_Cold"
    },
    {
      "x": -17,
      "y": 1,
      "z": -4,
      "name": "Plant_Grass_Jungle",
      "support": 15
    },
    {
      "x": -17,
      "y": 0,
      "z": -3,
      "name": "Soil_Grass_Cold"
    },
    {
      "x": -17,
      "y": 0,
      "z": -2,
      "name": "Soil_Grass_Cold"
    },
    {
      "x": -17,
      "y": 0,
      "z": -1,
      "name": "Soil_Grass_Cold"
    },
    {
      "x": -17,
      "y": 0,
      "z": 0,
      "name": "Soil_Pathway"
    },
    {
      "x": -17,
      "y": 0,
      "z": 1,
      "name": "Soil_Pathway"
    },
    {
      "x": -17,
      "y": 0,
      "z": 2,
      "name": "Soil_Pathway"
    },
    {
      "x": -17,
      "y": 0,
      "z": 3,
      "name": "Soil_Mud_Dry"
    },
    {
      "x": -17,
      "y": 0,
      "z": 4,
      "name": "Soil_Pathway"
    },
    {
      "x": -17,
      "y": 0,
      "z": 5,
      "name": "Soil_Pathway"
    },
    {
      "x": -17,
      "y": 0,
      "z": 6,
      "name": "Soil_Pathway"
    },
    {
      "x": -17,
      "y": 0,
      "z": 7,
      "name": "Soil_Pathway"
    },
    {
      "x": -17,
      "y": 0,
      "z": 8,
      "name": "Soil_Pathway"
    },
    {
      "x": -17,
      "y": 0,
      "z": 9,
      "name": "Soil_Pathway"
    },
    {
      "x": -17,
      "y": 0,
      "z": 10,
      "name": "Soil_Pathway"
    },
    {
      "x": -17,
      "y": 0,
      "z": 11,
      "name": "Soil_Grass_Cold"
    },
    {
      "x": -17,
      "y": 0,
      "z": 12,
      "name": "Soil_Grass_Cold"
    },
    {
      "x": -17,
      "y": 1,
      "z": 12,
      "name": "Plant_Grass_Jungle",
      "support": 15
    },
    {
      "x": -17,
      "y": 0,
      "z": 13,
      "name": "Soil_Grass_Cold"
    },
    {
      "x": -17,
      "y": 0,
      "z": 14,
      "name": "Soil_Grass_Cold"
    },
    {
      "x": -17,
      "y": 1,
      "z": 14,
      "name": "Plant_Grass_Jungle",
      "support": 15
    },
    {
      "x": -17,
      "y": 0,
      "z": 15,
      "name": "Soil_Grass_Cold"
    },
    {
      "x": -17,
      "y": 0,
      "z": 16,
      "name": "Soil_Grass_Cold"
    },
    {
      "x": -17,
      "y": 1,
      "z": 16,
      "name": "Plant_Grass_Lush_Tall",
      "support": 15
    },
    {
      "x": -17,
      "y": 0,
      "z": 17,
      "name": "Soil_Grass_Cold"
    },
    {
      "x": -17,
      "y": 1,
      "z": 17,
      "name": "Plant_Fern_Wet_Big",
      "support": 15
    },
    {
      "x": -17,
      "y": 0,
      "z": 18,
      "name": "Soil_Grass_Cold"
    },
    {
      "x": -17,
      "y": 0,
      "z": 19,
      "name": "Soil_Grass_Cold"
    },
    {
      "x": -17,
      "y": 1,
      "z": 19,
      "name": "Plant_Grass_Jungle",
      "support": 15
    },
    {
      "x": -17,
      "y": 0,
      "z": 20,
      "name": "Soil_Grass_Cold"
    },
    {
      "x": -17,
      "y": 0,
      "z": 21,
      "name": "Soil_Grass_Cold"
    },
    {
      "x": -17,
      "y": 1,
      "z": 21,
      "name": "Plant_Flower_Common_Red2"
    },
    {
      "x": -17,
      "y": 0,
      "z": 22,
      "name": "Soil_Grass_Cold"
    },
    {
      "x": -17,
      "y": 1,
      "z": 22,
      "name": "Plant_Flower_Water_Duckweed"
    },
    {
      "x": -17,
      "y": 0,
      "z": 23,
      "name": "Soil_Grass_Cold"
    },
    {
      "x": -16,
      "y": 0,
      "z": -24,
      "name": "Soil_Grass_Cold"
    },
    {
      "x": -16,
      "y": 0,
      "z": -23,
      "name": "Soil_Grass_Cold"
    },
    {
      "x": -16,
      "y": 1,
      "z": -23,
      "name": "Plant_Flower_Tall_Purple"
    },
    {
      "x": -16,
      "y": 0,
      "z": -22,
      "name": "Soil_Grass_Cold"
    },
    {
      "x": -16,
      "y": 0,
      "z": -21,
      "name": "Soil_Grass_Cold"
    },
    {
      "x": -16,
      "y": 0,
      "z": -20,
      "name": "Soil_Grass_Cold"
    },
    {
      "x": -16,
      "y": 0,
      "z": -19,
      "name": "Rock_Stone_Cobble"
    },
    {
      "x": -16,
      "y": 0,
      "z": -18,
      "name": "Ore_Copper_Stone"
    },
    {
      "x": -16,
      "y": 0,
      "z": -17,
      "name": "Soil_Grass_Cold"
    },
    {
      "x": -16,
      "y": 1,
      "z": -17,
      "name": "Plant_Grass_Lush_Tall",
      "support": 15
    },
    {
      "x": -16,
      "y": 0,
      "z": -16,
      "name": "Soil_Grass_Cold"
    },
    {
      "x": -16,
      "y": 0,
      "z": -15,
      "name": "Soil_Grass_Cold"
    },
    {
      "x": -16,
      "y": 0,
      "z": -14,
      "name": "Soil_Grass_Cold"
    },
    {
      "x": -16,
      "y": 1,
      "z": -14,
      "name": "Plant_Grass_Jungle",
      "support": 15
    },
    {
      "x": -16,
      "y": 0,
      "z": -13,
      "name": "Soil_Grass_Cold"
    },
    {
      "x": -16,
      "y": 0,
      "z": -12,
      "name": "Soil_Grass_Cold"
    },
    {
      "x": -16,
      "y": 1,
      "z": -12,
      "name": "Plant_Grass_Jungle",
      "support": 15
    },
    {
      "x": -16,
      "y": 0,
      "z": -11,
      "name": "Soil_Grass_Cold"
    },
    {
      "x": -16,
      "y": 0,
      "z": -10,
      "name": "Soil_Grass_Cold"
    },
    {
      "x": -16,
      "y": 1,
      "z": -10,
      "name": "Plant_Grass_Jungle",
      "support": 15
    },
    {
      "x": -16,
      "y": 0,
      "z": -9,
      "name": "Soil_Grass_Cold"
    },
    {
      "x": -16,
      "y": 0,
      "z": -8,
      "name": "Soil_Grass_Cold"
    },
    {
      "x": -16,
      "y": 0,
      "z": -7,
      "name": "Soil_Grass_Cold"
    },
    {
      "x": -16,
      "y": 0,
      "z": -6,
      "name": "Soil_Grass_Cold"
    },
    {
      "x": -16,
      "y": 1,
      "z": -6,
      "name": "Plant_Bush_Lush",
      "support": 15
    },
    {
      "x": -16,
      "y": 0,
      "z": -5,
      "name": "Soil_Grass_Cold"
    },
    {
      "x": -16,
      "y": 1,
      "z": -5,
      "name": "Plant_Bush_Lush",
      "support": 15
    },
    {
      "x": -16,
      "y": 0,
      "z": -4,
      "name": "Soil_Grass_Cold"
    },
    {
      "x": -16,
      "y": 0,
      "z": -3,
      "name": "Soil_Grass_Cold"
    },
    {
      "x": -16,
      "y": 0,
      "z": -2,
      "name": "Soil_Grass_Cold"
    },
    {
      "x": -16,
      "y": 0,
      "z": -1,
      "name": "Soil_Pathway"
    },
    {
      "x": -16,
      "y": 0,
      "z": 0,
      "name": "Soil_Mud_Dry"
    },
    {
      "x": -16,
      "y": 0,
      "z": 1,
      "name": "Soil_Pathway"
    },
    {
      "x": -16,
      "y": 0,
      "z": 2,
      "name": "Soil_Pathway"
    },
    {
      "x": -16,
      "y": 0,
      "z": 3,
      "name": "Soil_Mud_Dry"
    },
    {
      "x": -16,
      "y": 0,
      "z": 4,
      "name": "Soil_Grass_Cold"
    },
    {
      "x": -16,
      "y": 0,
      "z": 5,
      "name": "Soil_Pathway"
    },
    {
      "x": -16,
      "y": 0,
      "z": 6,
      "name": "Soil_Pathway"
    },
    {
      "x": -16,
      "y": 0,
      "z": 7,
      "name": "Soil_Pathway"
    },
    {
      "x": -16,
      "y": 0,
      "z": 8,
      "name": "Soil_Pathway"
    },
    {
      "x": -16,
      "y": 0,
      "z": 9,
      "name": "Soil_Mud_Dry"
    },
    {
      "x": -16,
      "y": 0,
      "z": 10,
      "name": "Soil_Pathway"
    },
    {
      "x": -16,
      "y": 0,
      "z": 11,
      "name": "Soil_Mud_Dry"
    },
    {
      "x": -16,
      "y": 0,
      "z": 12,
      "name": "Soil_Grass_Cold"
    },
    {
      "x": -16,
      "y": 0,
      "z": 13,
      "name": "Soil_Grass_Cold"
    },
    {
      "x": -16,
      "y": 0,
      "z": 14,
      "name": "Soil_Grass_Cold"
    },
    {
      "x": -16,
      "y": 0,
      "z": 15,
      "name": "Soil_Grass_Cold"
    },
    {
      "x": -16,
      "y": 0,
      "z": 16,
      "name": "Soil_Grass_Cold"
    },
    {
      "x": -16,
      "y": 0,
      "z": 17,
      "name": "Soil_Grass_Cold"
    },
    {
      "x": -16,
      "y": 1,
      "z": 17,
      "name": "Plant_Flower_Water_Duckweed"
    },
    {
      "x": -16,
      "y": 0,
      "z": 18,
      "name": "Soil_Grass_Cold"
    },
    {
      "x": -16,
      "y": 0,
      "z": 19,
      "name": "Soil_Grass_Cold"
    },
    {
      "x": -16,
      "y": 0,
      "z": 20,
      "name": "Soil_Grass_Cold"
    },
    {
      "x": -16,
      "y": 1,
      "z": 20,
      "name": "Plant_Grass_Jungle",
      "support": 15
    },
    {
      "x": -16,
      "y": 0,
      "z": 21,
      "name": "Soil_Grass_Cold"
    },
    {
      "x": -16,
      "y": 0,
      "z": 22,
      "name": "Soil_Grass_Cold"
    },
    {
      "x": -16,
      "y": 0,
      "z": 23,
      "name": "Soil_Grass_Cold"
    },
    {
      "x": -16,
      "y": 1,
      "z": 23,
      "name": "Plant_Grass_Jungle",
      "support": 15
    },
    {
      "x": -16,
      "y": 0,
      "z": 24,
      "name": "Soil_Grass_Cold"
    },
    {
      "x": -15,
      "y": 0,
      "z": -24,
      "name": "Soil_Grass_Cold"
    },
    {
      "x": -15,
      "y": 1,
      "z": -24,
      "name": "Plant_Grass_Jungle",
      "support": 15
    },
    {
      "x": -15,
      "y": 0,
      "z": -23,
      "name": "Soil_Grass_Cold"
    },
    {
      "x": -15,
      "y": 1,
      "z": -23,
      "name": "Plant_Flower_Common_Red2"
    },
    {
      "x": -15,
      "y": 0,
      "z": -22,
      "name": "Soil_Grass_Cold"
    },
    {
      "x": -15,
      "y": 0,
      "z": -21,
      "name": "Soil_Grass_Cold"
    },
    {
      "x": -15,
      "y": 1,
      "z": -21,
      "name": "Plant_Grass_Jungle",
      "support": 15
    },
    {
      "x": -15,
      "y": 0,
      "z": -20,
      "name": "Soil_Grass_Cold"
    },
    {
      "x": -15,
      "y": 0,
      "z": -19,
      "name": "Soil_Grass_Cold"
    },
    {
      "x": -15,
      "y": 0,
      "z": -18,
      "name": "Soil_Grass_Cold"
    },
    {
      "x": -15,
      "y": 0,
      "z": -17,
      "name": "Soil_Grass_Cold"
    },
    {
      "x": -15,
      "y": 0,
      "z": -16,
      "name": "Soil_Grass_Cold"
    },
    {
      "x": -15,
      "y": 1,
      "z": -16,
      "name": "Plant_Flower_Common_Yellow2"
    },
    {
      "x": -15,
      "y": 0,
      "z": -15,
      "name": "Soil_Grass_Cold"
    },
    {
      "x": -15,
      "y": 0,
      "z": -14,
      "name": "Soil_Grass_Cold"
    },
    {
      "x": -15,
      "y": 5,
      "z": -14,
      "name": "Wood_Hardwood_Stairs",
      "rotation": 9
    },
    {
      "x": -15,
      "y": 6,
      "z": -14,
      "name": "*Wood_Village_Wall_Full_State_Definitions_Bottom"
    },
    {
      "x": -15,
      "y": 7,
      "z": -14,
      "name": "*Wood_Village_Wall_Full_State_Definitions_Top"
    },
    {
      "x": -15,
      "y": 8,
      "z": -14,
      "name": "Wood_Lightwood_Roof",
      "rotation": 2
    },
    {
      "x": -15,
      "y": 0,
      "z": -13,
      "name": "Soil_Grass_Cold"
    },
    {
      "x": -15,
      "y": 5,
      "z": -13,
      "name": "Furniture_Village_Platform"
    },
    {
      "x": -15,
      "y": 6,
      "z": -13,
      "name": "Furniture_Human_Ruins_Pot_Small"
    },
    {
      "x": -15,
      "y": 8,
      "z": -13,
      "name": "Wood_Lightwood_Stairs",
      "rotation": 10
    },
    {
      "x": -15,
      "y": 9,
      "z": -13,
      "name": "Wood_Lightwood_Roof_Shallow",
      "rotation": 2
    },
    {
      "x": -15,
      "y": 0,
      "z": -12,
      "name": "Soil_Grass_Cold"
    },
    {
      "x": -15,
      "y": 5,
      "z": -12,
      "name": "Furniture_Village_Platform"
    },
    {
      "x": -15,
      "y": 6,
      "z": -12,
      "name": "Rubble_Basalt",
      "support": 15
    },
    {
      "x": -15,
      "y": 9,
      "z": -12,
      "name": "Wood_Lightwood_Roof_Shallow",
      "filler": 32,
      "rotation": 2
    },
    {
      "x": -15,
      "y": 0,
      "z": -11,
      "name": "Soil_Grass_Cold"
    },
    {
      "x": -15,
      "y": 5,
      "z": -11,
      "name": "Furniture_Village_Platform"
    },
    {
      "x": -15,
      "y": 9,
      "z": -11,
      "name": "Wood_Lightwood_Stairs",
      "rotation": 9
    },
    {
      "x": -15,
      "y": 10,
      "z": -11,
      "name": "Wood_Lightwood_Roof_Flat"
    },
    {
      "x": -15,
      "y": 0,
      "z": -10,
      "name": "Soil_Grass_Cold"
    },
    {
      "x": -15,
      "y": 1,
      "z": -10,
      "name": "Plant_Grass_Jungle",
      "support": 15
    },
    {
      "x": -15,
      "y": 5,
      "z": -10,
      "name": "Furniture_Village_Platform"
    },
    {
      "x": -15,
      "y": 9,
      "z": -10,
      "name": "Wood_Lightwood_Roof_Shallow",
      "filler": 992
    },
    {
      "x": -15,
      "y": 0,
      "z": -9,
      "name": "Soil_Grass_Cold"
    },
    {
      "x": -15,
      "y": 5,
      "z": -9,
      "name": "Furniture_Village_Platform"
    },
    {
      "x": -15,
      "y": 6,
      "z": -9,
      "name": "Furniture_Feran_Pot"
    },
    {
      "x": -15,
      "y": 8,
      "z": -9,
      "name": "Wood_Lightwood_Stairs",
      "rotation": 8
    },
    {
      "x": -15,
      "y": 9,
      "z": -9,
      "name": "Wood_Lightwood_Roof_Shallow"
    },
    {
      "x": -15,
      "y": 0,
      "z": -8,
      "name": "Soil_Grass_Cold"
    },
    {
      "x": -15,
      "y": 5,
      "z": -8,
      "name": "Wood_Hardwood_Stairs",
      "rotation": 9
    },
    {
      "x": -15,
      "y": 6,
      "z": -8,
      "name": "*Wood_Village_Wall_Full_State_Definitions_Bottom"
    },
    {
      "x": -15,
      "y": 7,
      "z": -8,
      "name": "*Wood_Village_Wall_Full_State_Definitions_Top"
    },
    {
      "x": -15,
      "y": 8,
      "z": -8,
      "name": "Wood_Lightwood_Roof"
    },
    {
      "x": -15,
      "y": 0,
      "z": -7,
      "name": "Soil_Grass_Cold"
    },
    {
      "x": -15,
      "y": 1,
      "z": -7,
      "name": "Plant_Bush_Lush",
      "support": 15
    },
    {
      "x": -15,
      "y": 0,
      "z": -6,
      "name": "Soil_Grass_Cold"
    },
    {
      "x": -15,
      "y": 1,
      "z": -6,
      "name": "Plant_Bush_Lush",
      "support": 15
    },
    {
      "x": -15,
      "y": 0,
      "z": -5,
      "name": "Soil_Grass_Cold"
    },
    {
      "x": -15,
      "y": 1,
      "z": -5,
      "name": "Plant_Bush_Lush",
      "support": 15
    },
    {
      "x": -15,
      "y": 2,
      "z": -5,
      "name": "Plant_Bush_Lush",
      "support": 15
    },
    {
      "x": -15,
      "y": 0,
      "z": -4,
      "name": "Soil_Grass_Cold"
    },
    {
      "x": -15,
      "y": 1,
      "z": -4,
      "name": "Plant_Bush_Lush",
      "support": 15
    },
    {
      "x": -15,
      "y": 0,
      "z": -3,
      "name": "Soil_Grass_Cold"
    },
    {
      "x": -15,
      "y": 0,
      "z": -2,
      "name": "Soil_Grass_Cold"
    },
    {
      "x": -15,
      "y": 0,
      "z": -1,
      "name": "Soil_Pathway"
    },
    {
      "x": -15,
      "y": 0,
      "z": 0,
      "name": "Soil_Mud_Dry"
    },
    {
      "x": -15,
      "y": 0,
      "z": 1,
      "name": "Soil_Pathway"
    },
    {
      "x": -15,
      "y": 0,
      "z": 2,
      "name": "Soil_Pathway"
    },
    {
      "x": -15,
      "y": 0,
      "z": 3,
      "name": "Soil_Grass_Cold"
    },
    {
      "x": -15,
      "y": 0,
      "z": 4,
      "name": "Soil_Grass_Cold"
    },
    {
      "x": -15,
      "y": 0,
      "z": 5,
      "name": "Soil_Grass_Cold"
    },
    {
      "x": -15,
      "y": 1,
      "z": 5,
      "name": "Plant_Grass_Lush_Tall",
      "support": 15
    },
    {
      "x": -15,
      "y": 0,
      "z": 6,
      "name": "Soil_Grass_Cold"
    },
    {
      "x": -15,
      "y": 0,
      "z": 7,
      "name": "Soil_Mud_Dry"
    },
    {
      "x": -15,
      "y": 0,
      "z": 8,
      "name": "Soil_Mud_Dry"
    },
    {
      "x": -15,
      "y": 0,
      "z": 9,
      "name": "Soil_Pathway"
    },
    {
      "x": -15,
      "y": 0,
      "z": 10,
      "name": "Soil_Pathway"
    },
    {
      "x": -15,
      "y": 0,
      "z": 11,
      "name": "Soil_Mud_Dry"
    },
    {
      "x": -15,
      "y": 0,
      "z": 12,
      "name": "Soil_Pathway"
    },
    {
      "x": -15,
      "y": 0,
      "z": 13,
      "name": "Soil_Pathway"
    },
    {
      "x": -15,
      "y": 0,
      "z": 14,
      "name": "Soil_Grass_Cold"
    },
    {
      "x": -15,
      "y": 0,
      "z": 15,
      "name": "Soil_Grass_Cold"
    },
    {
      "x": -15,
      "y": 0,
      "z": 16,
      "name": "Soil_Grass_Cold"
    },
    {
      "x": -15,
      "y": 1,
      "z": 16,
      "name": "Plant_Grass_Lush_Tall",
      "support": 15
    },
    {
      "x": -15,
      "y": 0,
      "z": 17,
      "name": "Soil_Grass_Cold"
    },
    {
      "x": -15,
      "y": 0,
      "z": 18,
      "name": "Soil_Grass_Cold"
    },
    {
      "x": -15,
      "y": 0,
      "z": 19,
      "name": "Soil_Grass_Cold"
    },
    {
      "x": -15,
      "y": 1,
      "z": 19,
      "name": "Plant_Flower_Water_Duckweed"
    },
    {
      "x": -15,
      "y": 0,
      "z": 20,
      "name": "Soil_Grass_Cold"
    },
    {
      "x": -15,
      "y": 0,
      "z": 21,
      "name": "Soil_Grass_Cold"
    },
    {
      "x": -15,
      "y": 0,
      "z": 22,
      "name": "Soil_Grass_Cold"
    },
    {
      "x": -15,
      "y": 1,
      "z": 22,
      "name": "Plant_Grass_Lush_Tall",
      "support": 15
    },
    {
      "x": -15,
      "y": 0,
      "z": 23,
      "name": "Soil_Grass_Cold"
    },
    {
      "x": -15,
      "y": 0,
      "z": 24,
      "name": "Soil_Grass_Cold"
    },
    {
      "x": -14,
      "y": 0,
      "z": -25,
      "name": "Soil_Grass_Cold"
    },
    {
      "x": -14,
      "y": 0,
      "z": -24,
      "name": "Soil_Grass_Cold"
    },
    {
      "x": -14,
      "y": 1,
      "z": -24,
      "name": "Plant_Flower_Common_White2"
    },
    {
      "x": -14,
      "y": 0,
      "z": -23,
      "name": "Soil_Grass_Cold"
    },
    {
      "x": -14,
      "y": 1,
      "z": -23,
      "name": "Plant_Grass_Jungle",
      "support": 15
    },
    {
      "x": -14,
      "y": 0,
      "z": -22,
      "name": "Soil_Grass_Cold"
    },
    {
      "x": -14,
      "y": 0,
      "z": -21,
      "name": "Soil_Grass_Cold"
    },
    {
      "x": -14,
      "y": 0,
      "z": -20,
      "name": "Soil_Grass_Cold"
    },
    {
      "x": -14,
      "y": 1,
      "z": -20,
      "name": "Plant_Grass_Jungle",
      "support": 15
    },
    {
      "x": -14,
      "y": 0,
      "z": -19,
      "name": "Soil_Grass_Cold"
    },
    {
      "x": -14,
      "y": 0,
      "z": -18,
      "name": "Soil_Grass_Cold"
    },
    {
      "x": -14,
      "y": 1,
      "z": -18,
      "name": "Rubble_Stone_Mossy",
      "support": 15
    },
    {
      "x": -14,
      "y": 0,
      "z": -17,
      "name": "Soil_Grass"
    },
    {
      "x": -14,
      "y": 1,
      "z": -17,
      "name": "Rock_Volcanic_Cobble"
    },
    {
      "x": -14,
      "y": 2,
      "z": -17,
      "name": "Rock_Volcanic_Brick_Smooth"
    },
    {
      "x": -14,
      "y": 3,
      "z": -17,
      "name": "Wood_Beech_Trunk_Full",
      "support": 15
    },
    {
      "x": -14,
      "y": 4,
      "z": -17,
      "name": "Wood_Beech_Trunk_Full",
      "support": 15
    },
    {
      "x": -14,
      "y": 5,
      "z": -17,
      "name": "Wood_Beech_Trunk_Full",
      "support": 15
    },
    {
      "x": -14,
      "y": 6,
      "z": -17,
      "name": "Wood_Beech_Trunk_Full",
      "support": 15
    },
    {
      "x": -14,
      "y": 7,
      "z": -17,
      "name": "Wood_Beech_Trunk_Full",
      "support": 15
    },
    {
      "x": -14,
      "y": 8,
      "z": -17,
      "name": "*Wood_Lightwood_Roof_State_Definitions_Corner_Left",
      "rotation": 2
    },
    {
      "x": -14,
      "y": 0,
      "z": -16,
      "name": "Soil_Grass"
    },
    {
      "x": -14,
      "y": 1,
      "z": -16,
      "name": "Rock_Volcanic_Brick_Smooth"
    },
    {
      "x": -14,
      "y": 2,
      "z": -16,
      "name": "Rock_Volcanic_Cobble"
    },
    {
      "x": -14,
      "y": 3,
      "z": -16,
      "name": "Wood_Drywood_Decorative"
    },
    {
      "x": -14,
      "y": 4,
      "z": -16,
      "name": "Wood_Lightwood_Planks"
    },
    {
      "x": -14,
      "y": 5,
      "z": -16,
      "name": "Wood_Lightwood_Planks"
    },
    {
      "x": -14,
      "y": 6,
      "z": -16,
      "name": "*Wood_Village_Wall_Full_State_Definitions_Bottom"
    },
    {
      "x": -14,
      "y": 7,
      "z": -16,
      "name": "*Wood_Village_Wall_Full_State_Definitions_Top"
    },
    {
      "x": -14,
      "y": 8,
      "z": -16,
      "name": "Wood_Lightwood_Roof",
      "rotation": 3
    },
    {
      "x": -14,
      "y": 0,
      "z": -15,
      "name": "Soil_Grass"
    },
    {
      "x": -14,
      "y": 1,
      "z": -15,
      "name": "Rock_Volcanic_Brick"
    },
    {
      "x": -14,
      "y": 2,
      "z": -15,
      "name": "Rock_Ledge_Brick"
    },
    {
      "x": -14,
      "y": 3,
      "z": -15,
      "name": "Wood_Drywood_Decorative"
    },
    {
      "x": -14,
      "y": 4,
      "z": -15,
      "name": "Wood_Lightwood_Planks"
    },
    {
      "x": -14,
      "y": 5,
      "z": -15,
      "name": "Wood_Lightwood_Planks"
    },
    {
      "x": -14,
      "y": 6,
      "z": -15,
      "name": "*Wood_Village_Wall_Full_State_Definitions_Bottom"
    },
    {
      "x": -14,
      "y": 7,
      "z": -15,
      "name": "*Wood_Village_Wall_Full_State_Definitions_Top"
    },
    {
      "x": -14,
      "y": 8,
      "z": -15,
      "name": "Wood_Lightwood_Roof",
      "rotation": 3
    },
    {
      "x": -14,
      "y": 0,
      "z": -14,
      "name": "Soil_Grass"
    },
    {
      "x": -14,
      "y": 1,
      "z": -14,
      "name": "Rock_Ledge_Brick_Decorative"
    },
    {
      "x": -14,
      "y": 2,
      "z": -14,
      "name": "Rock_Ledge_Brick_Stairs",
      "rotation": 9
    },
    {
      "x": -14,
      "y": 3,
      "z": -14,
      "name": "Wood_Drywood_Decorative"
    },
    {
      "x": -14,
      "y": 4,
      "z": -14,
      "name": "Wood_Lightwood_Planks"
    },
    {
      "x": -14,
      "y": 5,
      "z": -14,
      "name": "Wood_Lightwood_Planks"
    },
    {
      "x": -14,
      "y": 6,
      "z": -14,
      "name": "*Wood_Village_Wall_Full_State_Definitions_Bottom"
    },
    {
      "x": -14,
      "y": 7,
      "z": -14,
      "name": "*Wood_Village_Wall_Full_State_Definitions_Top"
    },
    {
      "x": -14,
      "y": 8,
      "z": -14,
      "name": "*Wood_Lightwood_Roof_State_Definitions_Inverted_Corner_Right",
      "rotation": 3
    },
    {
      "x": -14,
      "y": 0,
      "z": -13,
      "name": "Soil_Grass"
    },
    {
      "x": -14,
      "y": 1,
      "z": -13,
      "name": "Rock_Ledge_Brick"
    },
    {
      "x": -14,
      "y": 2,
      "z": -13,
      "name": "Rock_Ledge_Brick_Smooth"
    },
    {
      "x": -14,
      "y": 3,
      "z": -13,
      "name": "Wood_Drywood_Decorative"
    },
    {
      "x": -14,
      "y": 4,
      "z": -13,
      "name": "Wood_Lightwood_Planks"
    },
    {
      "x": -14,
      "y": 5,
      "z": -13,
      "name": "Wood_Lightwood_Planks"
    },
    {
      "x": -14,
      "y": 6,
      "z": -13,
      "name": "Furniture_Village_Window",
      "rotation": 1
    },
    {
      "x": -14,
      "y": 7,
      "z": -13,
      "name": "Furniture_Village_Window",
      "rotation": 1
    },
    {
      "x": -14,
      "y": 8,
      "z": -13,
      "name": "Wood_Lightwood_Planks"
    },
    {
      "x": -14,
      "y": 9,
      "z": -13,
      "name": "Wood_Lightwood_Roof_Shallow",
      "rotation": 2
    },
    {
      "x": -14,
      "y": 0,
      "z": -12,
      "name": "Soil_Grass"
    },
    {
      "x": -14,
      "y": 1,
      "z": -12,
      "name": "Rock_Ledge_Brick_Smooth"
    },
    {
      "x": -14,
      "y": 2,
      "z": -12,
      "name": "Rock_Ledge_Brick"
    },
    {
      "x": -14,
      "y": 3,
      "z": -12,
      "name": "Wood_Drywood_Decorative"
    },
    {
      "x": -14,
      "y": 4,
      "z": -12,
      "name": "Wood_Lightwood_Planks"
    },
    {
      "x": -14,
      "y": 5,
      "z": -12,
      "name": "Wood_Lightwood_Planks"
    },
    {
      "x": -14,
      "y": 6,
      "z": -12,
      "name": "Furniture_Village_Window",
      "rotation": 1
    },
    {
      "x": -14,
      "y": 7,
      "z": -12,
      "name": "Furniture_Village_Window",
      "rotation": 1
    },
    {
      "x": -14,
      "y": 8,
      "z": -12,
      "name": "Furniture_Village_Window",
      "rotation": 1
    },
    {
      "x": -14,
      "y": 9,
      "z": -12,
      "name": "Wood_Lightwood_Roof_Shallow",
      "filler": 32,
      "rotation": 2
    },
    {
      "x": -14,
      "y": 0,
      "z": -11,
      "name": "Soil_Grass"
    },
    {
      "x": -14,
      "y": 1,
      "z": -11,
      "name": "Rock_Ledge_Brick_Smooth"
    },
    {
      "x": -14,
      "y": 2,
      "z": -11,
      "name": "Rock_Ledge_Brick_Stairs",
      "rotation": 1
    },
    {
      "x": -14,
      "y": 3,
      "z": -11,
      "name": "Wood_Drywood_Decorative"
    },
    {
      "x": -14,
      "y": 4,
      "z": -11,
      "name": "Wood_Lightwood_Planks"
    },
    {
      "x": -14,
      "y": 5,
      "z": -11,
      "name": "Wood_Lightwood_Planks"
    },
    {
      "x": -14,
      "y": 6,
      "z": -11,
      "name": "Furniture_Village_Window",
      "rotation": 1
    },
    {
      "x": -14,
      "y": 7,
      "z": -11,
      "name": "Furniture_Village_Window",
      "rotation": 1
    },
    {
      "x": -14,
      "y": 8,
      "z": -11,
      "name": "Furniture_Village_Window",
      "rotation": 1
    },
    {
      "x": -14,
      "y": 9,
      "z": -11,
      "name": "Wood_Lightwood_Planks"
    },
    {
      "x": -14,
      "y": 10,
      "z": -11,
      "name": "Wood_Lightwood_Roof_Flat"
    },
    {
      "x": -14,
      "y": 0,
      "z": -10,
      "name": "Soil_Grass"
    },
    {
      "x": -14,
      "y": 1,
      "z": -10,
      "name": "Rock_Ledge_Brick"
    },
    {
      "x": -14,
      "y": 2,
      "z": -10,
      "name": "Rock_Ledge_Brick"
    },
    {
      "x": -14,
      "y": 3,
      "z": -10,
      "name": "Wood_Drywood_Decorative"
    },
    {
      "x": -14,
      "y": 4,
      "z": -10,
      "name": "Wood_Lightwood_Planks"
    },
    {
      "x": -14,
      "y": 5,
      "z": -10,
      "name": "Wood_Lightwood_Planks"
    },
    {
      "x": -14,
      "y": 6,
      "z": -10,
      "name": "Furniture_Village_Window",
      "rotation": 1
    },
    {
      "x": -14,
      "y": 7,
      "z": -10,
      "name": "Furniture_Village_Window",
      "rotation": 1
    },
    {
      "x": -14,
      "y": 8,
      "z": -10,
      "name": "Furniture_Village_Window",
      "rotation": 1
    },
    {
      "x": -14,
      "y": 9,
      "z": -10,
      "name": "Wood_Lightwood_Roof_Shallow",
      "filler": 992
    },
    {
      "x": -14,
      "y": 0,
      "z": -9,
      "name": "Rock_Ledge_Brick"
    },
    {
      "x": -14,
      "y": 1,
      "z": -9,
      "name": "Rock_Ledge_Brick_Stairs",
      "rotation": 3
    },
    {
      "x": -14,
      "y": 2,
      "z": -9,
      "name": "Rock_Ledge_Brick_Decorative"
    },
    {
      "x": -14,
      "y": 3,
      "z": -9,
      "name": "Wood_Drywood_Decorative"
    },
    {
      "x": -14,
      "y": 4,
      "z": -9,
      "name": "Wood_Lightwood_Planks"
    },
    {
      "x": -14,
      "y": 5,
      "z": -9,
      "name": "Wood_Lightwood_Planks"
    },
    {
      "x": -14,
      "y": 6,
      "z": -9,
      "name": "Furniture_Village_Window",
      "rotation": 1
    },
    {
      "x": -14,
      "y": 7,
      "z": -9,
      "name": "Furniture_Village_Window",
      "rotation": 1
    },
    {
      "x": -14,
      "y": 8,
      "z": -9,
      "name": "Wood_Lightwood_Planks"
    },
    {
      "x": -14,
      "y": 9,
      "z": -9,
      "name": "Wood_Lightwood_Roof_Shallow"
    },
    {
      "x": -14,
      "y": 0,
      "z": -8,
      "name": "Soil_Grass"
    },
    {
      "x": -14,
      "y": 1,
      "z": -8,
      "name": "Rock_Ledge_Brick_Smooth"
    },
    {
      "x": -14,
      "y": 2,
      "z": -8,
      "name": "Rock_Ledge_Brick"
    },
    {
      "x": -14,
      "y": 3,
      "z": -8,
      "name": "Wood_Drywood_Decorative"
    },
    {
      "x": -14,
      "y": 4,
      "z": -8,
      "name": "Wood_Lightwood_Planks"
    },
    {
      "x": -14,
      "y": 5,
      "z": -8,
      "name": "Wood_Lightwood_Planks"
    },
    {
      "x": -14,
      "y": 6,
      "z": -8,
      "name": "*Wood_Village_Wall_Full_State_Definitions_Bottom"
    },
    {
      "x": -14,
      "y": 7,
      "z": -8,
      "name": "*Wood_Village_Wall_Full_State_Definitions_Top"
    },
    {
      "x": -14,
      "y": 8,
      "z": -8,
      "name": "*Wood_Lightwood_Roof_State_Definitions_Inverted_Corner_Left",
      "rotation": 3
    },
    {
      "x": -14,
      "y": 0,
      "z": -7,
      "name": "Soil_Grass"
    },
    {
      "x": -14,
      "y": 1,
      "z": -7,
      "name": "Rock_Volcanic_Cobble"
    },
    {
      "x": -14,
      "y": 2,
      "z": -7,
      "name": "Rock_Ledge_Brick"
    },
    {
      "x": -14,
      "y": 3,
      "z": -7,
      "name": "Wood_Drywood_Decorative"
    },
    {
      "x": -14,
      "y": 4,
      "z": -7,
      "name": "Wood_Lightwood_Planks"
    },
    {
      "x": -14,
      "y": 5,
      "z": -7,
      "name": "Wood_Lightwood_Planks"
    },
    {
      "x": -14,
      "y": 6,
      "z": -7,
      "name": "*Wood_Village_Wall_Full_State_Definitions_Bottom"
    },
    {
      "x": -14,
      "y": 7,
      "z": -7,
      "name": "*Wood_Village_Wall_Full_State_Definitions_Top"
    },
    {
      "x": -14,
      "y": 8,
      "z": -7,
      "name": "Wood_Lightwood_Roof",
      "rotation": 3
    },
    {
      "x": -14,
      "y": 0,
      "z": -6,
      "name": "Soil_Grass"
    },
    {
      "x": -14,
      "y": 1,
      "z": -6,
      "name": "Rock_Volcanic_Brick"
    },
    {
      "x": -14,
      "y": 2,
      "z": -6,
      "name": "Rock_Volcanic_Brick_Smooth"
    },
    {
      "x": -14,
      "y": 3,
      "z": -6,
      "name": "Wood_Drywood_Decorative"
    },
    {
      "x": -14,
      "y": 4,
      "z": -6,
      "name": "Wood_Lightwood_Planks"
    },
    {
      "x": -14,
      "y": 5,
      "z": -6,
      "name": "Wood_Lightwood_Planks"
    },
    {
      "x": -14,
      "y": 6,
      "z": -6,
      "name": "*Wood_Village_Wall_Full_State_Definitions_Bottom"
    },
    {
      "x": -14,
      "y": 7,
      "z": -6,
      "name": "*Wood_Village_Wall_Full_State_Definitions_Top"
    },
    {
      "x": -14,
      "y": 8,
      "z": -6,
      "name": "Wood_Lightwood_Roof",
      "rotation": 3
    },
    {
      "x": -14,
      "y": 0,
      "z": -5,
      "name": "Soil_Grass"
    },
    {
      "x": -14,
      "y": 1,
      "z": -5,
      "name": "Rock_Volcanic_Cobble"
    },
    {
      "x": -14,
      "y": 2,
      "z": -5,
      "name": "Rock_Volcanic_Brick"
    },
    {
      "x": -14,
      "y": 3,
      "z": -5,
      "name": "Wood_Beech_Trunk_Full",
      "support": 15
    },
    {
      "x": -14,
      "y": 4,
      "z": -5,
      "name": "Wood_Beech_Trunk_Full",
      "support": 15
    },
    {
      "x": -14,
      "y": 5,
      "z": -5,
      "name": "Wood_Beech_Trunk_Full",
      "support": 15
    },
    {
      "x": -14,
      "y": 6,
      "z": -5,
      "name": "Wood_Beech_Trunk_Full",
      "support": 15
    },
    {
      "x": -14,
      "y": 7,
      "z": -5,
      "name": "Wood_Beech_Trunk_Full",
      "support": 15
    },
    {
      "x": -14,
      "y": 8,
      "z": -5,
      "name": "*Wood_Lightwood_Roof_State_Definitions_Corner_Right"
    },
    {
      "x": -14,
      "y": 0,
      "z": -4,
      "name": "Soil_Grass_Cold"
    },
    {
      "x": -14,
      "y": 1,
      "z": -4,
      "name": "Plant_Bush_Lush",
      "support": 15
    },
    {
      "x": -14,
      "y": 2,
      "z": -4,
      "name": "Plant_Bush_Lush",
      "support": 15
    },
    {
      "x": -14,
      "y": 0,
      "z": -3,
      "name": "Soil_Pathway"
    },
    {
      "x": -14,
      "y": 1,
      "z": -3,
      "name": "Plant_Bush_Lush",
      "support": 15
    },
    {
      "x": -14,
      "y": 0,
      "z": -2,
      "name": "Soil_Pathway"
    },
    {
      "x": -14,
      "y": 0,
      "z": -1,
      "name": "Soil_Pathway"
    },
    {
      "x": -14,
      "y": 0,
      "z": 0,
      "name": "Soil_Pathway"
    },
    {
      "x": -14,
      "y": 0,
      "z": 1,
      "name": "Soil_Pathway"
    },
    {
      "x": -14,
      "y": 0,
      "z": 2,
      "name": "Soil_Grass_Cold"
    },
    {
      "x": -14,
      "y": 0,
      "z": 3,
      "name": "Soil_Grass_Cold"
    },
    {
      "x": -14,
      "y": 0,
      "z": 4,
      "name": "Soil_Grass_Cold"
    },
    {
      "x": -14,
      "y": 0,
      "z": 5,
      "name": "Soil_Grass_Cold"
    },
    {
      "x": -14,
      "y": 0,
      "z": 6,
      "name": "Soil_Grass_Cold"
    },
    {
      "x": -14,
      "y": 0,
      "z": 7,
      "name": "Soil_Grass_Cold"
    },
    {
      "x": -14,
      "y": 0,
      "z": 8,
      "name": "Soil_Mud_Dry"
    },
    {
      "x": -14,
      "y": 0,
      "z": 9,
      "name": "Soil_Pathway"
    },
    {
      "x": -14,
      "y": 0,
      "z": 10,
      "name": "Soil_Mud_Dry"
    },
    {
      "x": -14,
      "y": 0,
      "z": 11,
      "name": "Soil_Pathway"
    },
    {
      "x": -14,
      "y": 0,
      "z": 12,
      "name": "Soil_Mud_Dry"
    },
    {
      "x": -14,
      "y": 0,
      "z": 13,
      "name": "Soil_Pathway"
    },
    {
      "x": -14,
      "y": 0,
      "z": 14,
      "name": "Soil_Pathway"
    },
    {
      "x": -14,
      "y": 1,
      "z": 14,
      "name": "Halloween_Wagon",
      "filler": 1023,
      "rotation": 2
    },
    {
      "x": -14,
      "y": 2,
      "z": 14,
      "name": "Barrier"
    },
    {
      "x": -14,
      "y": 3,
      "z": 14,
      "name": "Barrier"
    },
    {
      "x": -14,
      "y": 0,
      "z": 15,
      "name": "Soil_Grass_Cold"
    },
    {
      "x": -14,
      "y": 1,
      "z": 15,
      "name": "Halloween_Wagon",
      "filler": 31,
      "rotation": 2
    },
    {
      "x": -14,
      "y": 2,
      "z": 15,
      "name": "Barrier"
    },
    {
      "x": -14,
      "y": 3,
      "z": 15,
      "name": "Barrier"
    },
    {
      "x": -14,
      "y": 0,
      "z": 16,
      "name": "Soil_Grass_Cold"
    },
    {
      "x": -14,
      "y": 0,
      "z": 17,
      "name": "Soil_Grass_Cold"
    },
    {
      "x": -14,
      "y": 1,
      "z": 17,
      "name": "Plant_Grass_Lush_Tall",
      "support": 15
    },
    {
      "x": -14,
      "y": 0,
      "z": 18,
      "name": "Soil_Grass_Cold"
    },
    {
      "x": -14,
      "y": 0,
      "z": 19,
      "name": "Soil_Grass_Cold"
    },
    {
      "x": -14,
      "y": 1,
      "z": 19,
      "name": "Plant_Flower_Common_White2"
    },
    {
      "x": -14,
      "y": 0,
      "z": 20,
      "name": "Soil_Grass_Cold"
    },
    {
      "x": -14,
      "y": 0,
      "z": 21,
      "name": "Soil_Grass_Cold"
    },
    {
      "x": -14,
      "y": 1,
      "z": 21,
      "name": "Plant_Bush_Lush",
      "support": 15
    },
    {
      "x": -14,
      "y": 0,
      "z": 22,
      "name": "Soil_Grass_Cold"
    },
    {
      "x": -14,
      "y": 1,
      "z": 22,
      "name": "Plant_Bush_Lush",
      "support": 15
    },
    {
      "x": -14,
      "y": 0,
      "z": 23,
      "name": "Soil_Grass_Cold"
    },
    {
      "x": -14,
      "y": 1,
      "z": 23,
      "name": "Plant_Bush_Lush",
      "support": 15
    },
    {
      "x": -14,
      "y": 0,
      "z": 24,
      "name": "Soil_Grass_Cold"
    },
    {
      "x": -14,
      "y": 1,
      "z": 24,
      "name": "Plant_Flower_Common_Violet"
    },
    {
      "x": -14,
      "y": 0,
      "z": 25,
      "name": "Soil_Grass_Cold"
    },
    {
      "x": -13,
      "y": 0,
      "z": -25,
      "name": "Soil_Grass_Cold"
    },
    {
      "x": -13,
      "y": 0,
      "z": -24,
      "name": "Soil_Grass_Cold"
    },
    {
      "x": -13,
      "y": 0,
      "z": -23,
      "name": "Soil_Grass_Cold"
    },
    {
      "x": -13,
      "y": 0,
      "z": -22,
      "name": "Soil_Grass_Cold"
    },
    {
      "x": -13,
      "y": 0,
      "z": -21,
      "name": "Soil_Grass_Cold"
    },
    {
      "x": -13,
      "y": 0,
      "z": -20,
      "name": "Soil_Grass_Cold"
    },
    {
      "x": -13,
      "y": 0,
      "z": -19,
      "name": "Soil_Grass_Cold"
    },
    {
      "x": -13,
      "y": 1,
      "z": -19,
      "name": "Plant_Flower_Tall_Violet"
    },
    {
      "x": -13,
      "y": 0,
      "z": -18,
      "name": "Soil_Grass_Cold"
    },
    {
      "x": -13,
      "y": 1,
      "z": -18,
      "name": "Plant_Flower_Tall_Purple"
    },
    {
      "x": -13,
      "y": 0,
      "z": -17,
      "name": "Rock_Volcanic_Brick"
    },
    {
      "x": -13,
      "y": 1,
      "z": -17,
      "name": "Rock_Volcanic_Cobble"
    },
    {
      "x": -13,
      "y": 2,
      "z": -17,
      "name": "Rock_Volcanic_Brick"
    },
    {
      "x": -13,
      "y": 3,
      "z": -17,
      "name": "Wood_Drywood_Decorative"
    },
    {
      "x": -13,
      "y": 4,
      "z": -17,
      "name": "Wood_Lightwood_Planks"
    },
    {
      "x": -13,
      "y": 5,
      "z": -17,
      "name": "Wood_Lightwood_Planks"
    },
    {
      "x": -13,
      "y": 6,
      "z": -17,
      "name": "*Wood_Village_Wall_Full_State_Definitions_Bottom"
    },
    {
      "x": -13,
      "y": 7,
      "z": -17,
      "name": "*Wood_Village_Wall_Full_State_Definitions_Top"
    },
    {
      "x": -13,
      "y": 8,
      "z": -17,
      "name": "Wood_Lightwood_Roof",
      "rotation": 2
    },
    {
      "x": -13,
      "y": 0,
      "z": -16,
      "name": "Rock_Ledge_Brick"
    },
    {
      "x": -13,
      "y": 1,
      "z": -16,
      "name": "Rock_Ledge_Brick_Half"
    },
    {
      "x": -13,
      "y": 8,
      "z": -16,
      "name": "*Wood_Lightwood_Stairs_State_Definitions_Inverted_Corner_Right",
      "rotation": 10
    },
    {
      "x": -13,
      "y": 9,
      "z": -16,
      "name": "*Wood_Lightwood_Roof_State_Definitions_Corner_Right",
      "rotation": 3
    },
    {
      "x": -13,
      "y": 0,
      "z": -15,
      "name": "Rock_Ledge_Brick"
    },
    {
      "x": -13,
      "y": 1,
      "z": -15,
      "name": "Rock_Ledge_Brick_Half"
    },
    {
      "x": -13,
      "y": 8,
      "z": -15,
      "name": "Wood_Lightwood_Stairs",
      "rotation": 11
    },
    {
      "x": -13,
      "y": 9,
      "z": -15,
      "name": "Wood_Lightwood_Roof",
      "rotation": 3
    },
    {
      "x": -13,
      "y": 0,
      "z": -14,
      "name": "Rock_Ledge_Brick"
    },
    {
      "x": -13,
      "y": 4,
      "z": -14,
      "name": "Wood_Drywood_Planks"
    },
    {
      "x": -13,
      "y": 5,
      "z": -14,
      "name": "Wood_Drywood_Fence"
    },
    {
      "x": -13,
      "y": 8,
      "z": -14,
      "name": "Wood_Lightwood_Stairs",
      "rotation": 11
    },
    {
      "x": -13,
      "y": 9,
      "z": -14,
      "name": "Wood_Lightwood_Roof",
      "rotation": 3
    },
    {
      "x": -13,
      "y": 0,
      "z": -13,
      "name": "Rock_Ledge_Brick"
    },
    {
      "x": -13,
      "y": 3,
      "z": -13,
      "name": "*Wood_Drywood_Stairs_State_Definitions_Corner_Left",
      "rotation": 8
    },
    {
      "x": -13,
      "y": 4,
      "z": -13,
      "name": "Wood_Drywood_Planks"
    },
    {
      "x": -13,
      "y": 5,
      "z": -13,
      "name": "Furniture_Feran_Pot"
    },
    {
      "x": -13,
      "y": 8,
      "z": -13,
      "name": "*Wood_Lightwood_Stairs_State_Definitions_Corner_Right",
      "rotation": 10
    },
    {
      "x": -13,
      "y": 9,
      "z": -13,
      "name": "Wood_Lightwood_Roof",
      "rotation": 3
    },
    {
      "x": -13,
      "y": 0,
      "z": -12,
      "name": "Rock_Ledge_Brick"
    },
    {
      "x": -13,
      "y": 3,
      "z": -12,
      "name": "Wood_Drywood_Stairs",
      "rotation": 11
    },
    {
      "x": -13,
      "y": 4,
      "z": -12,
      "name": "Wood_Drywood_Planks"
    },
    {
      "x": -13,
      "y": 5,
      "z": -12,
      "name": "Furniture_Crude_Shelf",
      "rotation": 1
    },
    {
      "x": -13,
      "y": 9,
      "z": -12,
      "name": "*Wood_Lightwood_Roof_Hollow_State_Definitions_Inverted_Corner_Left",
      "rotation": 2
    },
    {
      "x": -13,
      "y": 0,
      "z": -11,
      "name": "Rock_Ledge_Brick"
    },
    {
      "x": -13,
      "y": 1,
      "z": -11,
      "name": "Furniture_Desert_Torch"
    },
    {
      "x": -13,
      "y": 2,
      "z": -11,
      "name": "Furniture_Desert_Torch",
      "filler": 1024
    },
    {
      "x": -13,
      "y": 3,
      "z": -11,
      "name": "Wood_Drywood_Stairs",
      "rotation": 11
    },
    {
      "x": -13,
      "y": 4,
      "z": -11,
      "name": "Wood_Drywood_Planks"
    },
    {
      "x": -13,
      "y": 5,
      "z": -11,
      "name": "Furniture_Crude_Shelf",
      "rotation": 1
    },
    {
      "x": -13,
      "y": 10,
      "z": -11,
      "name": "Wood_Lightwood_Roof_Flat"
    },
    {
      "x": -13,
      "y": 0,
      "z": -10,
      "name": "Rock_Ledge_Brick"
    },
    {
      "x": -13,
      "y": 1,
      "z": -10,
      "name": "Rail",
      "rotation": 1
    },
    {
      "x": -13,
      "y": 3,
      "z": -10,
      "name": "Wood_Drywood_Stairs",
      "rotation": 11
    },
    {
      "x": -13,
      "y": 4,
      "z": -10,
      "name": "Wood_Drywood_Planks"
    },
    {
      "x": -13,
      "y": 5,
      "z": -10,
      "name": "Furniture_Crude_Shelf",
      "rotation": 1
    },
    {
      "x": -13,
      "y": 9,
      "z": -10,
      "name": "*Wood_Lightwood_Roof_Hollow_State_Definitions_Inverted_Corner_Right"
    },
    {
      "x": -13,
      "y": 0,
      "z": -9,
      "name": "Rock_Ledge_Brick"
    },
    {
      "x": -13,
      "y": 3,
      "z": -9,
      "name": "Wood_Drywood_Stairs",
      "rotation": 11
    },
    {
      "x": -13,
      "y": 4,
      "z": -9,
      "name": "Wood_Drywood_Planks"
    },
    {
      "x": -13,
      "y": 5,
      "z": -9,
      "name": "Furniture_Tavern_Barrel"
    },
    {
      "x": -13,
      "y": 8,
      "z": -9,
      "name": "*Wood_Lightwood_Stairs_State_Definitions_Corner_Left",
      "rotation": 8
    },
    {
      "x": -13,
      "y": 9,
      "z": -9,
      "name": "Wood_Lightwood_Roof",
      "rotation": 3
    },
    {
      "x": -13,
      "y": 0,
      "z": -8,
      "name": "Rock_Ledge_Brick_Smooth"
    },
    {
      "x": -13,
      "y": 3,
      "z": -8,
      "name": "Wood_Drywood_Stairs",
      "rotation": 11
    },
    {
      "x": -13,
      "y": 4,
      "z": -8,
      "name": "Wood_Drywood_Planks"
    },
    {
      "x": -13,
      "y": 8,
      "z": -8,
      "name": "Wood_Lightwood_Stairs",
      "rotation": 11
    },
    {
      "x": -13,
      "y": 9,
      "z": -8,
      "name": "Wood_Lightwood_Roof",
      "rotation": 3
    },
    {
      "x": -13,
      "y": 0,
      "z": -7,
      "name": "Rock_Ledge_Brick"
    },
    {
      "x": -13,
      "y": 3,
      "z": -7,
      "name": "Wood_Drywood_Stairs",
      "rotation": 11
    },
    {
      "x": -13,
      "y": 4,
      "z": -7,
      "name": "Wood_Drywood_Planks"
    },
    {
      "x": -13,
      "y": 8,
      "z": -7,
      "name": "Wood_Lightwood_Stairs",
      "rotation": 11
    },
    {
      "x": -13,
      "y": 9,
      "z": -7,
      "name": "Wood_Lightwood_Roof",
      "rotation": 3
    },
    {
      "x": -13,
      "y": 0,
      "z": -6,
      "name": "Rock_Ledge_Brick"
    },
    {
      "x": -13,
      "y": 1,
      "z": -6,
      "name": "Furniture_Ancient_Barrel"
    },
    {
      "x": -13,
      "y": 3,
      "z": -6,
      "name": "*Wood_Drywood_Stairs_State_Definitions_Inverted_Corner_Left",
      "rotation": 8
    },
    {
      "x": -13,
      "y": 4,
      "z": -6,
      "name": "Wood_Drywood_Planks"
    },
    {
      "x": -13,
      "y": 5,
      "z": -6,
      "name": "Furniture_Human_Ruins_Pot"
    },
    {
      "x": -13,
      "y": 8,
      "z": -6,
      "name": "*Wood_Lightwood_Stairs_State_Definitions_Inverted_Corner_Left",
      "rotation": 8
    },
    {
      "x": -13,
      "y": 9,
      "z": -6,
      "name": "*Wood_Lightwood_Roof_State_Definitions_Corner_Right"
    },
    {
      "x": -13,
      "y": 0,
      "z": -5,
      "name": "Soil_Grass"
    },
    {
      "x": -13,
      "y": 1,
      "z": -5,
      "name": "Rock_Volcanic_Cobble"
    },
    {
      "x": -13,
      "y": 2,
      "z": -5,
      "name": "Rock_Volcanic_Brick"
    },
    {
      "x": -13,
      "y": 3,
      "z": -5,
      "name": "Wood_Drywood_Decorative"
    },
    {
      "x": -13,
      "y": 4,
      "z": -5,
      "name": "Wood_Lightwood_Planks"
    },
    {
      "x": -13,
      "y": 5,
      "z": -5,
      "name": "Wood_Lightwood_Planks"
    },
    {
      "x": -13,
      "y": 6,
      "z": -5,
      "name": "*Wood_Village_Wall_Full_State_Definitions_Bottom"
    },
    {
      "x": -13,
      "y": 7,
      "z": -5,
      "name": "*Wood_Village_Wall_Full_State_Definitions_Top"
    },
    {
      "x": -13,
      "y": 8,
      "z": -5,
      "name": "Wood_Lightwood_Roof"
    },
    {
      "x": -13,
      "y": 0,
      "z": -4,
      "name": "Soil_Pathway"
    },
    {
      "x": -13,
      "y": 1,
      "z": -4,
      "name": "Plant_Bush_Lush",
      "support": 15
    },
    {
      "x": -13,
      "y": 7,
      "z": -4,
      "name": "Plant_Vine_Wall",
      "support": 15
    },
    {
      "x": -13,
      "y": 0,
      "z": -3,
      "name": "Soil_Mud_Dry"
    },
    {
      "x": -13,
      "y": 0,
      "z": -2,
      "name": "Soil_Mud_Dry"
    },
    {
      "x": -13,
      "y": 0,
      "z": -1,
      "name": "Soil_Pathway"
    },
    {
      "x": -13,
      "y": 0,
      "z": 0,
      "name": "Soil_Mud_Dry"
    },
    {
      "x": -13,
      "y": 0,
      "z": 1,
      "name": "Soil_Grass_Cold"
    },
    {
      "x": -13,
      "y": 0,
      "z": 2,
      "name": "Soil_Grass_Cold"
    },
    {
      "x": -13,
      "y": 1,
      "z": 2,
      "name": "Plant_Grass_Jungle",
      "support": 15
    },
    {
      "x": -13,
      "y": 0,
      "z": 3,
      "name": "Soil_Grass_Cold"
    },
    {
      "x": -13,
      "y": 0,
      "z": 4,
      "name": "Soil_Grass_Cold"
    },
    {
      "x": -13,
      "y": 0,
      "z": 5,
      "name": "Soil_Grass_Cold"
    },
    {
      "x": -13,
      "y": 1,
      "z": 5,
      "name": "Plant_Flower_Common_White2"
    },
    {
      "x": -13,
      "y": 0,
      "z": 6,
      "name": "Soil_Grass_Cold"
    },
    {
      "x": -13,
      "y": 0,
      "z": 7,
      "name": "Soil_Grass_Cold"
    },
    {
      "x": -13,
      "y": 0,
      "z": 8,
      "name": "Soil_Grass_Cold"
    },
    {
      "x": -13,
      "y": 1,
      "z": 8,
      "name": "Plant_Grass_Jungle",
      "support": 15
    },
    {
      "x": -13,
      "y": 0,
      "z": 9,
      "name": "Soil_Pathway"
    },
    {
      "x": -13,
      "y": 0,
      "z": 10,
      "name": "Soil_Mud_Dry"
    },
    {
      "x": -13,
      "y": 0,
      "z": 11,
      "name": "Soil_Pathway"
    },
    {
      "x": -13,
      "y": 0,
      "z": 12,
      "name": "Soil_Pathway"
    },
    {
      "x": -13,
      "y": 0,
      "z": 13,
      "name": "Soil_Pathway"
    },
    {
      "x": -13,
      "y": 0,
      "z": 14,
      "name": "Soil_Pathway"
    },
    {
      "x": -13,
      "y": 1,
      "z": 14,
      "name": "Halloween_Wagon",
      "filler": 992,
      "rotation": 2
    },
    {
      "x": -13,
      "y": 2,
      "z": 14,
      "name": "Barrier"
    },
    {
      "x": -13,
      "y": 3,
      "z": 14,
      "name": "Barrier"
    },
    {
      "x": -13,
      "y": 0,
      "z": 15,
      "name": "Soil_Pathway"
    },
    {
      "x": -13,
      "y": 1,
      "z": 15,
      "name": "Halloween_Wagon",
      "rotation": 2
    },
    {
      "x": -13,
      "y": 2,
      "z": 15,
      "name": "Barrier"
    },
    {
      "x": -13,
      "y": 3,
      "z": 15,
      "name": "Barrier"
    },
    {
      "x": -13,
      "y": 0,
      "z": 16,
      "name": "Soil_Grass_Cold"
    },
    {
      "x": -13,
      "y": 0,
      "z": 17,
      "name": "Soil_Grass_Cold"
    },
    {
      "x": -13,
      "y": 0,
      "z": 18,
      "name": "Soil_Grass_Cold"
    },
    {
      "x": -13,
      "y": 0,
      "z": 19,
      "name": "Soil_Grass_Cold"
    },
    {
      "x": -13,
      "y": 0,
      "z": 20,
      "name": "Soil_Grass_Cold"
    },
    {
      "x": -13,
      "y": 1,
      "z": 20,
      "name": "Plant_Bush_Lush",
      "support": 15
    },
    {
      "x": -13,
      "y": 0,
      "z": 21,
      "name": "Soil_Grass_Cold"
    },
    {
      "x": -13,
      "y": 1,
      "z": 21,
      "name": "Plant_Bush_Lush",
      "support": 15
    },
    {
      "x": -13,
      "y": 2,
      "z": 21,
      "name": "Plant_Bush_Lush",
      "support": 15
    },
    {
      "x": -13,
      "y": 0,
      "z": 22,
      "name": "Soil_Grass_Cold"
    },
    {
      "x": -13,
      "y": 1,
      "z": 22,
      "name": "Plant_Bush_Lush",
      "support": 15
    },
    {
      "x": -13,
      "y": 0,
      "z": 23,
      "name": "Soil_Grass_Cold"
    },
    {
      "x": -13,
      "y": 1,
      "z": 23,
      "name": "Plant_Flower_Water_Duckweed"
    },
    {
      "x": -13,
      "y": 0,
      "z": 24,
      "name": "Soil_Grass_Cold"
    },
    {
      "x": -13,
      "y": 0,
      "z": 25,
      "name": "Soil_Grass_Cold"
    },
    {
      "x": -12,
      "y": 0,
      "z": -25,
      "name": "Soil_Grass_Cold"
    },
    {
      "x": -12,
      "y": 0,
      "z": -24,
      "name": "Soil_Grass_Cold"
    },
    {
      "x": -12,
      "y": 1,
      "z": -24,
      "name": "Plant_Flower_Tall_Violet"
    },
    {
      "x": -12,
      "y": 0,
      "z": -23,
      "name": "Soil_Grass_Cold"
    },
    {
      "x": -12,
      "y": 1,
      "z": -23,
      "name": "Plant_Grass_Lush_Tall",
      "support": 15
    },
    {
      "x": -12,
      "y": 0,
      "z": -22,
      "name": "Soil_Grass_Cold"
    },
    {
      "x": -12,
      "y": 4,
      "z": -22,
      "name": "Plant_Leaves_Fir",
      "support": 15,
      "rotation": 3
    },
    {
      "x": -12,
      "y": 5,
      "z": -22,
      "name": "Plant_Leaves_Fir",
      "support": 15,
      "rotation": 3
    },
    {
      "x": -12,
      "y": 0,
      "z": -21,
      "name": "Soil_Grass_Cold"
    },
    {
      "x": -12,
      "y": 1,
      "z": -21,
      "name": "Plant_Fern_Wet_Big",
      "support": 15
    },
    {
      "x": -12,
      "y": 0,
      "z": -20,
      "name": "Soil_Grass_Cold"
    },
    {
      "x": -12,
      "y": 0,
      "z": -19,
      "name": "Soil_Grass_Cold"
    },
    {
      "x": -12,
      "y": 0,
      "z": -18,
      "name": "Soil_Grass_Cold"
    },
    {
      "x": -12,
      "y": 1,
      "z": -18,
      "name": "Plant_Flower_Common_Red2"
    },
    {
      "x": -12,
      "y": 0,
      "z": -17,
      "name": "Soil_Grass"
    },
    {
      "x": -12,
      "y": 1,
      "z": -17,
      "name": "Rock_Volcanic_Cobble"
    },
    {
      "x": -12,
      "y": 2,
      "z": -17,
      "name": "Rock_Ledge_Brick_Stairs",
      "rotation": 2
    },
    {
      "x": -12,
      "y": 3,
      "z": -17,
      "name": "Wood_Drywood_Decorative"
    },
    {
      "x": -12,
      "y": 4,
      "z": -17,
      "name": "Wood_Lightwood_Planks"
    },
    {
      "x": -12,
      "y": 5,
      "z": -17,
      "name": "Wood_Lightwood_Planks"
    },
    {
      "x": -12,
      "y": 6,
      "z": -17,
      "name": "*Wood_Village_Wall_Full_State_Definitions_Bottom"
    },
    {
      "x": -12,
      "y": 7,
      "z": -17,
      "name": "*Wood_Village_Wall_Full_State_Definitions_Top"
    },
    {
      "x": -12,
      "y": 8,
      "z": -17,
      "name": "Wood_Lightwood_Roof",
      "rotation": 2
    },
    {
      "x": -12,
      "y": 0,
      "z": -16,
      "name": "Rock_Ledge_Brick"
    },
    {
      "x": -12,
      "y": 1,
      "z": -16,
      "name": "Rock_Ledge_Brick_Half"
    },
    {
      "x": -12,
      "y": 8,
      "z": -16,
      "name": "Wood_Lightwood_Stairs",
      "rotation": 10
    },
    {
      "x": -12,
      "y": 9,
      "z": -16,
      "name": "Wood_Lightwood_Roof",
      "rotation": 2
    },
    {
      "x": -12,
      "y": 0,
      "z": -15,
      "name": "Rock_Ledge_Brick"
    },
    {
      "x": -12,
      "y": 1,
      "z": -15,
      "name": "Rock_Ledge_Brick_Half"
    },
    {
      "x": -12,
      "y": 9,
      "z": -15,
      "name": "*Wood_Lightwood_Stairs_State_Definitions_Inverted_Corner_Right",
      "rotation": 10
    },
    {
      "x": -12,
      "y": 10,
      "z": -15,
      "name": "*Wood_Lightwood_Roof_State_Definitions_Corner_Right",
      "rotation": 3
    },
    {
      "x": -12,
      "y": 0,
      "z": -14,
      "name": "Soil_Leaves"
    },
    {
      "x": -12,
      "y": 4,
      "z": -14,
      "name": "Wood_Drywood_Planks"
    },
    {
      "x": -12,
      "y": 5,
      "z": -14,
      "name": "Wood_Drywood_Fence"
    },
    {
      "x": -12,
      "y": 9,
      "z": -14,
      "name": "Wood_Lightwood_Stairs",
      "rotation": 11
    },
    {
      "x": -12,
      "y": 10,
      "z": -14,
      "name": "Wood_Lightwood_Roof",
      "rotation": 3
    },
    {
      "x": -12,
      "y": 0,
      "z": -13,
      "name": "Rock_Ledge_Brick_Decorative"
    },
    {
      "x": -12,
      "y": 4,
      "z": -13,
      "name": "Wood_Drywood_Planks"
    },
    {
      "x": -12,
      "y": 9,
      "z": -13,
      "name": "*Wood_Lightwood_Stairs_State_Definitions_Corner_Right",
      "rotation": 10
    },
    {
      "x": -12,
      "y": 10,
      "z": -13,
      "name": "Wood_Lightwood_Roof",
      "rotation": 3
    },
    {
      "x": -12,
      "y": 0,
      "z": -12,
      "name": "Rock_Ledge_Brick"
    },
    {
      "x": -12,
      "y": 4,
      "z": -12,
      "name": "Wood_Drywood_Planks"
    },
    {
      "x": -12,
      "y": 10,
      "z": -12,
      "name": "Wood_Lightwood_Roof_Hollow",
      "rotation": 3
    },
    {
      "x": -12,
      "y": 0,
      "z": -11,
      "name": "Rock_Ledge_Brick_Smooth"
    },
    {
      "x": -12,
      "y": 4,
      "z": -11,
      "name": "Wood_Drywood_Planks"
    },
    {
      "x": -12,
      "y": 10,
      "z": -11,
      "name": "Wood_Lightwood_Roof_Hollow",
      "rotation": 3
    },
    {
      "x": -12,
      "y": 0,
      "z": -10,
      "name": "Rock_Ledge_Brick"
    },
    {
      "x": -12,
      "y": 1,
      "z": -10,
      "name": "Rail",
      "rotation": 1
    },
    {
      "x": -12,
      "y": 4,
      "z": -10,
      "name": "Wood_Drywood_Planks"
    },
    {
      "x": -12,
      "y": 10,
      "z": -10,
      "name": "Wood_Lightwood_Roof_Hollow",
      "rotation": 3
    },
    {
      "x": -12,
      "y": 0,
      "z": -9,
      "name": "Rock_Ledge_Brick"
    },
    {
      "x": -12,
      "y": 4,
      "z": -9,
      "name": "Wood_Drywood_Planks"
    },
    {
      "x": -12,
      "y": 5,
      "z": -9,
      "name": "Barrier"
    },
    {
      "x": -12,
      "y": 9,
      "z": -9,
      "name": "*Wood_Lightwood_Stairs_State_Definitions_Corner_Left",
      "rotation": 8
    },
    {
      "x": -12,
      "y": 10,
      "z": -9,
      "name": "Wood_Lightwood_Roof",
      "rotation": 3
    },
    {
      "x": -12,
      "y": 0,
      "z": -8,
      "name": "Rock_Ledge_Brick"
    },
    {
      "x": -12,
      "y": 4,
      "z": -8,
      "name": "Wood_Drywood_Planks"
    },
    {
      "x": -12,
      "y": 9,
      "z": -8,
      "name": "Wood_Lightwood_Stairs",
      "rotation": 11
    },
    {
      "x": -12,
      "y": 10,
      "z": -8,
      "name": "Wood_Lightwood_Roof",
      "rotation": 3
    },
    {
      "x": -12,
      "y": 0,
      "z": -7,
      "name": "Rock_Ledge_Brick_Smooth"
    },
    {
      "x": -12,
      "y": 1,
      "z": -7,
      "name": "Deco_Scarak_Spit",
      "rotation": 2
    },
    {
      "x": -12,
      "y": 4,
      "z": -7,
      "name": "Wood_Drywood_Planks"
    },
    {
      "x": -12,
      "y": 9,
      "z": -7,
      "name": "*Wood_Lightwood_Stairs_State_Definitions_Inverted_Corner_Right",
      "rotation": 11
    },
    {
      "x": -12,
      "y": 10,
      "z": -7,
      "name": "*Wood_Lightwood_Roof_State_Definitions_Corner_Right"
    },
    {
      "x": -12,
      "y": 0,
      "z": -6,
      "name": "Rock_Ledge_Brick"
    },
    {
      "x": -12,
      "y": 1,
      "z": -6,
      "name": "Furniture_Ancient_Crate",
      "rotation": 2
    },
    {
      "x": -12,
      "y": 2,
      "z": -6,
      "name": "Deco_Bone_Skulls_Feran"
    },
    {
      "x": -12,
      "y": 3,
      "z": -6,
      "name": "Wood_Drywood_Stairs",
      "rotation": 8
    },
    {
      "x": -12,
      "y": 4,
      "z": -6,
      "name": "Wood_Drywood_Planks"
    },
    {
      "x": -12,
      "y": 5,
      "z": -6,
      "name": "Furniture_Tavern_Wardrobe",
      "rotation": 2
    },
    {
      "x": -12,
      "y": 6,
      "z": -6,
      "name": "Furniture_Tavern_Wardrobe",
      "filler": 1024,
      "rotation": 2
    },
    {
      "x": -12,
      "y": 8,
      "z": -6,
      "name": "Wood_Lightwood_Stairs",
      "rotation": 8
    },
    {
      "x": -12,
      "y": 9,
      "z": -6,
      "name": "Wood_Lightwood_Roof"
    },
    {
      "x": -12,
      "y": 0,
      "z": -5,
      "name": "Soil_Grass"
    },
    {
      "x": -12,
      "y": 1,
      "z": -5,
      "name": "Rock_Volcanic_Cobble"
    },
    {
      "x": -12,
      "y": 2,
      "z": -5,
      "name": "Rock_Ledge_Brick_Decorative"
    },
    {
      "x": -12,
      "y": 3,
      "z": -5,
      "name": "Wood_Drywood_Decorative"
    },
    {
      "x": -12,
      "y": 4,
      "z": -5,
      "name": "Wood_Lightwood_Planks"
    },
    {
      "x": -12,
      "y": 5,
      "z": -5,
      "name": "Wood_Lightwood_Planks"
    },
    {
      "x": -12,
      "y": 6,
      "z": -5,
      "name": "*Wood_Village_Wall_Full_State_Definitions_Bottom"
    },
    {
      "x": -12,
      "y": 7,
      "z": -5,
      "name": "*Wood_Village_Wall_Full_State_Definitions_Top"
    },
    {
      "x": -12,
      "y": 8,
      "z": -5,
      "name": "Wood_Lightwood_Roof"
    },
    {
      "x": -12,
      "y": 0,
      "z": -4,
      "name": "Soil_Pathway"
    },
    {
      "x": -12,
      "y": 0,
      "z": -3,
      "name": "Soil_Mud_Dry"
    },
    {
      "x": -12,
      "y": 0,
      "z": -2,
      "name": "Soil_Pathway"
    },
    {
      "x": -12,
      "y": 0,
      "z": -1,
      "name": "Soil_Grass_Cold"
    },
    {
      "x": -12,
      "y": 0,
      "z": 0,
      "name": "Soil_Grass_Cold"
    },
    {
      "x": -12,
      "y": 1,
      "z": 0,
      "name": "Plant_Grass_Lush_Tall",
      "support": 15
    },
    {
      "x": -12,
      "y": 0,
      "z": 1,
      "name": "Soil_Grass_Cold"
    },
    {
      "x": -12,
      "y": 0,
      "z": 2,
      "name": "Soil_Grass_Cold"
    },
    {
      "x": -12,
      "y": 0,
      "z": 3,
      "name": "Soil_Grass_Cold"
    },
    {
      "x": -12,
      "y": 1,
      "z": 3,
      "name": "Plant_Grass_Jungle",
      "support": 15
    },
    {
      "x": -12,
      "y": 0,
      "z": 4,
      "name": "Soil_Grass_Cold"
    },
    {
      "x": -12,
      "y": 0,
      "z": 5,
      "name": "Soil_Grass_Cold"
    },
    {
      "x": -12,
      "y": 0,
      "z": 6,
      "name": "Soil_Grass_Cold"
    },
    {
      "x": -12,
      "y": 1,
      "z": 6,
      "name": "Plant_Flower_Common_Red2"
    },
    {
      "x": -12,
      "y": 0,
      "z": 7,
      "name": "Soil_Grass_Cold"
    },
    {
      "x": -12,
      "y": 0,
      "z": 8,
      "name": "Soil_Grass_Cold"
    },
    {
      "x": -12,
      "y": 0,
      "z": 9,
      "name": "Soil_Grass_Cold"
    },
    {
      "x": -12,
      "y": 0,
      "z": 10,
      "name": "Soil_Mud_Dry"
    },
    {
      "x": -12,
      "y": 0,
      "z": 11,
      "name": "Soil_Mud_Dry"
    },
    {
      "x": -12,
      "y": 0,
      "z": 12,
      "name": "Soil_Pathway"
    },
    {
      "x": -12,
      "y": 0,
      "z": 13,
      "name": "Soil_Pathway"
    },
    {
      "x": -12,
      "y": 0,
      "z": 14,
      "name": "Soil_Pathway"
    },
    {
      "x": -12,
      "y": 0,
      "z": 15,
      "name": "Soil_Pathway"
    },
    {
      "x": -12,
      "y": 0,
      "z": 16,
      "name": "Soil_Grass_Cold"
    },
    {
      "x": -12,
      "y": 0,
      "z": 17,
      "name": "Soil_Grass_Cold"
    },
    {
      "x": -12,
      "y": 1,
      "z": 17,
      "name": "Plant_Grass_Jungle",
      "support": 15
    },
    {
      "x": -12,
      "y": 0,
      "z": 18,
      "name": "Soil_Grass_Cold"
    },
    {
      "x": -12,
      "y": 0,
      "z": 19,
      "name": "Soil_Grass_Cold"
    },
    {
      "x": -12,
      "y": 1,
      "z": 19,
      "name": "Plant_Grass_Lush_Tall",
      "support": 15
    },
    {
      "x": -12,
      "y": 0,
      "z": 20,
      "name": "Soil_Grass_Cold"
    },
    {
      "x": -12,
      "y": 0,
      "z": 21,
      "name": "Soil_Grass_Cold"
    },
    {
      "x": -12,
      "y": 1,
      "z": 21,
      "name": "Plant_Bush_Lush",
      "support": 15
    },
    {
      "x": -12,
      "y": 0,
      "z": 22,
      "name": "Soil_Grass_Cold"
    },
    {
      "x": -12,
      "y": 0,
      "z": 23,
      "name": "Soil_Grass_Cold"
    },
    {
      "x": -12,
      "y": 0,
      "z": 24,
      "name": "Soil_Grass_Cold"
    },
    {
      "x": -12,
      "y": 0,
      "z": 25,
      "name": "Soil_Grass_Cold"
    },
    {
      "x": -11,
      "y": 0,
      "z": -26,
      "name": "Soil_Grass_Cold"
    },
    {
      "x": -11,
      "y": 0,
      "z": -25,
      "name": "Soil_Grass_Cold"
    },
    {
      "x": -11,
      "y": 1,
      "z": -25,
      "name": "Plant_Flower_Common_Yellow2"
    },
    {
      "x": -11,
      "y": 0,
      "z": -24,
      "name": "Soil_Grass_Cold"
    },
    {
      "x": -11,
      "y": 0,
      "z": -23,
      "name": "Soil_Grass_Cold"
    },
    {
      "x": -11,
      "y": 4,
      "z": -23,
      "name": "Plant_Leaves_Fir",
      "support": 15,
      "rotation": 3
    },
    {
      "x": -11,
      "y": 5,
      "z": -23,
      "name": "Plant_Leaves_Fir",
      "support": 15,
      "rotation": 3
    },
    {
      "x": -11,
      "y": 0,
      "z": -22,
      "name": "Soil_Grass_Cold"
    },
    {
      "x": -11,
      "y": 1,
      "z": -22,
      "name": "Plant_Grass_Jungle",
      "support": 15
    },
    {
      "x": -11,
      "y": 4,
      "z": -22,
      "name": "Plant_Leaves_Fir",
      "support": 15,
      "rotation": 3
    },
    {
      "x": -11,
      "y": 5,
      "z": -22,
      "name": "Plant_Leaves_Fir",
      "support": 15,
      "rotation": 3
    },
    {
      "x": -11,
      "y": 6,
      "z": -22,
      "name": "Plant_Leaves_Fir",
      "support": 15,
      "rotation": 3
    },
    {
      "x": -11,
      "y": 7,
      "z": -22,
      "name": "Plant_Leaves_Fir",
      "support": 15,
      "rotation": 3
    },
    {
      "x": -11,
      "y": 0,
      "z": -21,
      "name": "Soil_Grass_Cold"
    },
    {
      "x": -11,
      "y": 4,
      "z": -21,
      "name": "Plant_Leaves_Fir",
      "support": 15,
      "rotation": 3
    },
    {
      "x": -11,
      "y": 5,
      "z": -21,
      "name": "Plant_Leaves_Fir",
      "support": 15,
      "rotation": 3
    },
    {
      "x": -11,
      "y": 0,
      "z": -20,
      "name": "Soil_Grass_Cold"
    },
    {
      "x": -11,
      "y": 0,
      "z": -19,
      "name": "Soil_Grass_Cold"
    },
    {
      "x": -11,
      "y": 1,
      "z": -19,
      "name": "Plant_Grass_Lush_Tall",
      "support": 15
    },
    {
      "x": -11,
      "y": 0,
      "z": -18,
      "name": "Soil_Grass_Cold"
    },
    {
      "x": -11,
      "y": 0,
      "z": -17,
      "name": "Soil_Grass"
    },
    {
      "x": -11,
      "y": 1,
      "z": -17,
      "name": "Rock_Ledge_Brick_Decorative"
    },
    {
      "x": -11,
      "y": 2,
      "z": -17,
      "name": "Rock_Ledge_Brick_Smooth"
    },
    {
      "x": -11,
      "y": 3,
      "z": -17,
      "name": "Wood_Drywood_Decorative"
    },
    {
      "x": -11,
      "y": 4,
      "z": -17,
      "name": "Wood_Lightwood_Planks"
    },
    {
      "x": -11,
      "y": 5,
      "z": -17,
      "name": "Wood_Lightwood_Planks"
    },
    {
      "x": -11,
      "y": 6,
      "z": -17,
      "name": "*Wood_Village_Wall_Full_State_Definitions_Bottom"
    },
    {
      "x": -11,
      "y": 7,
      "z": -17,
      "name": "*Wood_Village_Wall_Full_State_Definitions_Top"
    },
    {
      "x": -11,
      "y": 8,
      "z": -17,
      "name": "Wood_Lightwood_Roof",
      "rotation": 2
    },
    {
      "x": -11,
      "y": 0,
      "z": -16,
      "name": "Rock_Ledge_Brick"
    },
    {
      "x": -11,
      "y": 1,
      "z": -16,
      "name": "Rock_Ledge_Brick"
    },
    {
      "x": -11,
      "y": 8,
      "z": -16,
      "name": "Wood_Lightwood_Stairs",
      "rotation": 10
    },
    {
      "x": -11,
      "y": 9,
      "z": -16,
      "name": "Wood_Lightwood_Roof",
      "rotation": 2
    },
    {
      "x": -11,
      "y": 0,
      "z": -15,
      "name": "Rock_Ledge_Brick"
    },
    {
      "x": -11,
      "y": 1,
      "z": -15,
      "name": "Rock_Ledge_Brick"
    },
    {
      "x": -11,
      "y": 9,
      "z": -15,
      "name": "Wood_Lightwood_Stairs",
      "rotation": 10
    },
    {
      "x": -11,
      "y": 10,
      "z": -15,
      "name": "Wood_Lightwood_Roof",
      "rotation": 2
    },
    {
      "x": -11,
      "y": 0,
      "z": -14,
      "name": "Rock_Ledge_Brick"
    },
    {
      "x": -11,
      "y": 4,
      "z": -14,
      "name": "Wood_Drywood_Planks"
    },
    {
      "x": -11,
      "y": 5,
      "z": -14,
      "name": "Wood_Drywood_Fence"
    },
    {
      "x": -11,
      "y": 10,
      "z": -14,
      "name": "Wood_Drywood_Planks"
    },
    {
      "x": -11,
      "y": 11,
      "z": -14,
      "name": "*Wood_Drywood_Fence_State_Definitions_Corner",
      "rotation": 1
    },
    {
      "x": -11,
      "y": 0,
      "z": -13,
      "name": "Rock_Ledge_Brick"
    },
    {
      "x": -11,
      "y": 4,
      "z": -13,
      "name": "Wood_Drywood_Planks"
    },
    {
      "x": -11,
      "y": 10,
      "z": -13,
      "name": "Wood_Drywood_Planks"
    },
    {
      "x": -11,
      "y": 11,
      "z": -13,
      "name": "Wood_Drywood_Fence",
      "rotation": 3
    },
    {
      "x": -11,
      "y": 0,
      "z": -12,
      "name": "Rock_Ledge_Brick_Smooth"
    },
    {
      "x": -11,
      "y": 4,
      "z": -12,
      "name": "Wood_Drywood_Planks"
    },
    {
      "x": -11,
      "y": 5,
      "z": -12,
      "name": "Furniture_Village_Chair"
    },
    {
      "x": -11,
      "y": 6,
      "z": -12,
      "name": "Furniture_Village_Chair",
      "filler": 1024
    },
    {
      "x": -11,
      "y": 10,
      "z": -12,
      "name": "Wood_Drywood_Planks"
    },
    {
      "x": -11,
      "y": 11,
      "z": -12,
      "name": "Wood_Drywood_Fence",
      "rotation": 3
    },
    {
      "x": -11,
      "y": 0,
      "z": -11,
      "name": "Rock_Ledge_Brick_Smooth"
    },
    {
      "x": -11,
      "y": 4,
      "z": -11,
      "name": "Wood_Drywood_Planks"
    },
    {
      "x": -11,
      "y": 5,
      "z": -11,
      "name": "Furniture_Village_Table",
      "filler": 992,
      "rotation": 1
    },
    {
      "x": -11,
      "y": 10,
      "z": -11,
      "name": "Wood_Drywood_Planks"
    },
    {
      "x": -11,
      "y": 11,
      "z": -11,
      "name": "Wood_Drywood_Fence",
      "rotation": 3
    },
    {
      "x": -11,
      "y": 0,
      "z": -10,
      "name": "Rock_Ledge_Brick"
    },
    {
      "x": -11,
      "y": 1,
      "z": -10,
      "name": "Rail",
      "rotation": 1
    },
    {
      "x": -11,
      "y": 4,
      "z": -10,
      "name": "Wood_Drywood_Planks"
    },
    {
      "x": -11,
      "y": 5,
      "z": -10,
      "name": "Furniture_Village_Table",
      "rotation": 1
    },
    {
      "x": -11,
      "y": 10,
      "z": -10,
      "name": "Wood_Drywood_Planks"
    },
    {
      "x": -11,
      "y": 11,
      "z": -10,
      "name": "Wood_Drywood_Fence",
      "rotation": 3
    },
    {
      "x": -11,
      "y": 0,
      "z": -9,
      "name": "Rock_Ledge_Brick"
    },
    {
      "x": -11,
      "y": 1,
      "z": -9,
      "name": "Deco_Lever",
      "rotation": 3
    },
    {
      "x": -11,
      "y": 4,
      "z": -9,
      "name": "Wood_Drywood_Planks"
    },
    {
      "x": -11,
      "y": 10,
      "z": -9,
      "name": "Wood_Drywood_Planks"
    },
    {
      "x": -11,
      "y": 11,
      "z": -9,
      "name": "Wood_Drywood_Fence",
      "rotation": 3
    },
    {
      "x": -11,
      "y": 0,
      "z": -8,
      "name": "Rock_Ledge_Brick"
    },
    {
      "x": -11,
      "y": 1,
      "z": -8,
      "name": "Furniture_Ancient_Chair",
      "rotation": 1
    },
    {
      "x": -11,
      "y": 4,
      "z": -8,
      "name": "Wood_Drywood_Planks"
    },
    {
      "x": -11,
      "y": 10,
      "z": -8,
      "name": "Wood_Drywood_Planks"
    },
    {
      "x": -11,
      "y": 11,
      "z": -8,
      "name": "*Wood_Drywood_Fence_State_Definitions_Corner",
      "rotation": 2
    },
    {
      "x": -11,
      "y": 0,
      "z": -7,
      "name": "Rock_Ledge_Brick"
    },
    {
      "x": -11,
      "y": 4,
      "z": -7,
      "name": "Wood_Drywood_Planks"
    },
    {
      "x": -11,
      "y": 9,
      "z": -7,
      "name": "Wood_Lightwood_Stairs",
      "rotation": 8
    },
    {
      "x": -11,
      "y": 10,
      "z": -7,
      "name": "Wood_Lightwood_Roof"
    },
    {
      "x": -11,
      "y": 0,
      "z": -6,
      "name": "Rock_Ledge_Brick"
    },
    {
      "x": -11,
      "y": 1,
      "z": -6,
      "name": "Furniture_Ancient_Wardrobe",
      "rotation": 2
    },
    {
      "x": -11,
      "y": 2,
      "z": -6,
      "name": "Furniture_Ancient_Wardrobe",
      "filler": 1024,
      "rotation": 2
    },
    {
      "x": -11,
      "y": 3,
      "z": -6,
      "name": "Wood_Drywood_Stairs",
      "rotation": 8
    },
    {
      "x": -11,
      "y": 4,
      "z": -6,
      "name": "Wood_Drywood_Planks"
    },
    {
      "x": -11,
      "y": 5,
      "z": -6,
      "name": "Furniture_Tavern_Wardrobe",
      "filler": 1,
      "rotation": 2
    },
    {
      "x": -11,
      "y": 6,
      "z": -6,
      "name": "Furniture_Tavern_Wardrobe",
      "filler": 1025,
      "rotation": 2
    },
    {
      "x": -11,
      "y": 8,
      "z": -6,
      "name": "Wood_Lightwood_Stairs",
      "rotation": 8
    },
    {
      "x": -11,
      "y": 9,
      "z": -6,
      "name": "Wood_Lightwood_Roof"
    },
    {
      "x": -11,
      "y": 0,
      "z": -5,
      "name": "Rock_Ledge_Brick_Smooth"
    },
    {
      "x": -11,
      "y": 1,
      "z": -5,
      "name": "Rock_Ledge_Brick_Smooth"
    },
    {
      "x": -11,
      "y": 2,
      "z": -5,
      "name": "Rock_Ledge_Brick"
    },
    {
      "x": -11,
      "y": 3,
      "z": -5,
      "name": "Wood_Drywood_Decorative"
    },
    {
      "x": -11,
      "y": 4,
      "z": -5,
      "name": "Wood_Lightwood_Planks"
    },
    {
      "x": -11,
      "y": 5,
      "z": -5,
      "name": "Wood_Lightwood_Planks"
    },
    {
      "x": -11,
      "y": 6,
      "z": -5,
      "name": "*Wood_Village_Wall_Full_State_Definitions_Bottom"
    },
    {
      "x": -11,
      "y": 7,
      "z": -5,
      "name": "*Wood_Village_Wall_Full_State_Definitions_Top"
    },
    {
      "x": -11,
      "y": 8,
      "z": -5,
      "name": "Wood_Lightwood_Roof"
    },
    {
      "x": -11,
      "y": 0,
      "z": -4,
      "name": "Soil_Pathway"
    },
    {
      "x": -11,
      "y": 1,
      "z": -4,
      "name": "Rock_Ledge_Brick_Stairs",
      "rotation": 3
    },
    {
      "x": -11,
      "y": 0,
      "z": -3,
      "name": "Soil_Pathway"
    },
    {
      "x": -11,
      "y": 1,
      "z": -3,
      "name": "Rock_Ledge_Brick_Smooth_Half"
    },
    {
      "x": -11,
      "y": 0,
      "z": -2,
      "name": "Soil_Grass_Cold"
    },
    {
      "x": -11,
      "y": 0,
      "z": -1,
      "name": "Soil_Grass_Cold"
    },
    {
      "x": -11,
      "y": 0,
      "z": 0,
      "name": "Soil_Grass_Cold"
    },
    {
      "x": -11,
      "y": 0,
      "z": 1,
      "name": "Soil_Grass_Cold"
    },
    {
      "x": -11,
      "y": 0,
      "z": 2,
      "name": "Soil_Grass_Cold"
    },
    {
      "x": -11,
      "y": 0,
      "z": 3,
      "name": "Soil_Grass_Cold"
    },
    {
      "x": -11,
      "y": 0,
      "z": 4,
      "name": "Soil_Grass_Cold"
    },
    {
      "x": -11,
      "y": 0,
      "z": 5,
      "name": "Soil_Grass_Cold"
    },
    {
      "x": -11,
      "y": 1,
      "z": 5,
      "name": "Plant_Grass_Jungle",
      "support": 15
    },
    {
      "x": -11,
      "y": 0,
      "z": 6,
      "name": "Soil_Grass_Cold"
    },
    {
      "x": -11,
      "y": 0,
      "z": 7,
      "name": "Soil_Grass_Cold"
    },
    {
      "x": -11,
      "y": 0,
      "z": 8,
      "name": "Soil_Grass_Cold"
    },
    {
      "x": -11,
      "y": 0,
      "z": 9,
      "name": "Soil_Grass_Cold"
    },
    {
      "x": -11,
      "y": 0,
      "z": 10,
      "name": "Soil_Pathway"
    },
    {
      "x": -11,
      "y": 0,
      "z": 11,
      "name": "Soil_Pathway"
    },
    {
      "x": -11,
      "y": 0,
      "z": 12,
      "name": "Soil_Mud_Dry"
    },
    {
      "x": -11,
      "y": 0,
      "z": 13,
      "name": "Soil_Pathway"
    },
    {
      "x": -11,
      "y": 0,
      "z": 14,
      "name": "Soil_Pathway"
    },
    {
      "x": -11,
      "y": 0,
      "z": 15,
      "name": "Soil_Mud_Dry"
    },
    {
      "x": -11,
      "y": 0,
      "z": 16,
      "name": "Soil_Grass_Cold"
    },
    {
      "x": -11,
      "y": 0,
      "z": 17,
      "name": "Soil_Grass_Cold"
    },
    {
      "x": -11,
      "y": 1,
      "z": 17,
      "name": "Plant_Grass_Jungle",
      "support": 15
    },
    {
      "x": -11,
      "y": 0,
      "z": 18,
      "name": "Soil_Grass_Cold"
    },
    {
      "x": -11,
      "y": 1,
      "z": 18,
      "name": "Plant_Flower_Water_Duckweed"
    },
    {
      "x": -11,
      "y": 0,
      "z": 19,
      "name": "Soil_Grass_Cold"
    },
    {
      "x": -11,
      "y": 0,
      "z": 20,
      "name": "Soil_Grass_Cold"
    },
    {
      "x": -11,
      "y": 0,
      "z": 21,
      "name": "Soil_Grass_Cold"
    },
    {
      "x": -11,
      "y": 0,
      "z": 22,
      "name": "Soil_Grass_Cold"
    },
    {
      "x": -11,
      "y": 0,
      "z": 23,
      "name": "Soil_Grass_Cold"
    },
    {
      "x": -11,
      "y": 0,
      "z": 24,
      "name": "Soil_Grass_Cold"
    },
    {
      "x": -11,
      "y": 0,
      "z": 25,
      "name": "Soil_Grass_Cold"
    },
    {
      "x": -11,
      "y": 0,
      "z": 26,
      "name": "Soil_Grass_Cold"
    },
    {
      "x": -10,
      "y": 0,
      "z": -26,
      "name": "Soil_Grass_Cold"
    },
    {
      "x": -10,
      "y": 0,
      "z": -25,
      "name": "Soil_Grass_Cold"
    },
    {
      "x": -10,
      "y": 0,
      "z": -24,
      "name": "Soil_Grass_Cold"
    },
    {
      "x": -10,
      "y": 1,
      "z": -24,
      "name": "Plant_Flower_Tall_Violet"
    },
    {
      "x": -10,
      "y": 4,
      "z": -24,
      "name": "Plant_Leaves_Fir",
      "support": 15,
      "rotation": 2
    },
    {
      "x": -10,
      "y": 5,
      "z": -24,
      "name": "Plant_Leaves_Fir",
      "support": 15,
      "rotation": 2
    },
    {
      "x": -10,
      "y": 0,
      "z": -23,
      "name": "Soil_Grass_Cold"
    },
    {
      "x": -10,
      "y": 4,
      "z": -23,
      "name": "Plant_Leaves_Fir",
      "support": 15,
      "rotation": 3
    },
    {
      "x": -10,
      "y": 5,
      "z": -23,
      "name": "Plant_Leaves_Fir",
      "support": 15,
      "rotation": 3
    },
    {
      "x": -10,
      "y": 6,
      "z": -23,
      "name": "Plant_Leaves_Fir",
      "support": 15,
      "rotation": 3
    },
    {
      "x": -10,
      "y": 7,
      "z": -23,
      "name": "Plant_Leaves_Fir",
      "support": 15,
      "rotation": 3
    },
    {
      "x": -10,
      "y": 0,
      "z": -22,
      "name": "Soil_Grass_Cold"
    },
    {
      "x": -10,
      "y": 4,
      "z": -22,
      "name": "Plant_Leaves_Fir",
      "support": 15,
      "rotation": 3
    },
    {
      "x": -10,
      "y": 5,
      "z": -22,
      "name": "Plant_Leaves_Fir",
      "support": 15,
      "rotation": 3
    },
    {
      "x": -10,
      "y": 6,
      "z": -22,
      "name": "Plant_Leaves_Fir",
      "support": 15,
      "rotation": 3
    },
    {
      "x": -10,
      "y": 7,
      "z": -22,
      "name": "Plant_Leaves_Fir",
      "support": 15,
      "rotation": 3
    },
    {
      "x": -10,
      "y": 8,
      "z": -22,
