{
  "version": 8,
  "blockIdVersion": 10,
  "anchorX": 0,
  "anchorY": 0,
  "anchorZ": 0,
  "blocks": [
    {
      "x": -22,
      "y": 0,
      "z": -8,
      "name": "Soil_Snow_Half"
    },
    {
      "x": -22,
      "y": 0,
      "z": -7,
      "name": "Soil_Snow_Half"
    },
    {
      "x": -22,
      "y": 4,
      "z": -7,
      "name": "Plant_Leaves_Fir",
      "support": 15,
      "rotation": 3
    },
    {
      "x": -22,
      "y": 0,
      "z": -6,
      "name": "Soil_Snow_Half"
    },
    {
      "x": -22,
      "y": 0,
      "z": -5,
      "name": "Soil_Snow_Half"
    },
    {
      "x": -22,
      "y": 0,
      "z": -4,
      "name": "Soil_Snow_Half"
    },
    {
      "x": -22,
      "y": 0,
      "z": -3,
      "name": "Soil_Snow_Half"
    },
    {
      "x": -22,
      "y": 0,
      "z": -2,
      "name": "Soil_Snow_Half"
    },
    {
      "x": -22,
      "y": 0,
      "z": -1,
      "name": "Soil_Snow_Half"
    },
    {
      "x": -22,
      "y": 0,
      "z": 0,
      "name": "Soil_Snow_Half"
    },
    {
      "x": -22,
      "y": 0,
      "z": 1,
      "name": "Soil_Snow_Half"
    },
    {
      "x": -22,
      "y": 0,
      "z": 2,
      "name": "Soil_Snow_Half"
    },
    {
      "x": -22,
      "y": 0,
      "z": 3,
      "name": "Soil_Snow_Half"
    },
    {
      "x": -22,
      "y": 0,
      "z": 4,
      "name": "Soil_Snow_Half"
    },
    {
      "x": -22,
      "y": 0,
      "z": 5,
      "name": "Soil_Snow_Half"
    },
    {
      "x": -22,
      "y": 0,
      "z": 6,
      "name": "Soil_Snow_Half"
    },
    {
      "x": -22,
      "y": 0,
      "z": 7,
      "name": "Soil_Snow_Half"
    },
    {
      "x": -21,
      "y": 0,
      "z": -9,
      "name": "Soil_Snow_Half"
    },
    {
      "x": -21,
      "y": 0,
      "z": -8,
      "name": "Soil_Snow"
    },
    {
      "x": -21,
      "y": 4,
      "z": -8,
      "name": "Plant_Leaves_Fir",
      "support": 15,
      "rotation": 3
    },
    {
      "x": -21,
      "y": 5,
      "z": -8,
      "name": "Plant_Leaves_Fir",
      "support": 15,
      "rotation": 3
    },
    {
      "x": -21,
      "y": 0,
      "z": -7,
      "name": "Soil_Snow"
    },
    {
      "x": -21,
      "y": 4,
      "z": -7,
      "name": "Plant_Leaves_Fir",
      "support": 15,
      "rotation": 3
    },
    {
      "x": -21,
      "y": 5,
      "z": -7,
      "name": "Plant_Leaves_Fir",
      "support": 15,
      "rotation": 3
    },
    {
      "x": -21,
      "y": 6,
      "z": -7,
      "name": "Plant_Leaves_Fir",
      "support": 15,
      "rotation": 3
    },
    {
      "x": -21,
      "y": 0,
      "z": -6,
      "name": "Soil_Snow"
    },
    {
      "x": -21,
      "y": 1,
      "z": -6,
      "name": "Plant_Bush_Winter_Snow",
      "support": 15
    },
    {
      "x": -21,
      "y": 4,
      "z": -6,
      "name": "Plant_Leaves_Fir",
      "support": 15,
      "rotation": 3
    },
    {
      "x": -21,
      "y": 5,
      "z": -6,
      "name": "Plant_Leaves_Fir",
      "support": 15
    },
    {
      "x": -21,
      "y": 0,
      "z": -5,
      "name": "Soil_Snow"
    },
    {
      "x": -21,
      "y": 0,
      "z": -4,
      "name": "Soil_Snow"
    },
    {
      "x": -21,
      "y": 0,
      "z": -3,
      "name": "Soil_Snow"
    },
    {
      "x": -21,
      "y": 0,
      "z": -2,
      "name": "Soil_Snow"
    },
    {
      "x": -21,
      "y": 0,
      "z": -1,
      "name": "Soil_Snow"
    },
    {
      "x": -21,
      "y": 0,
      "z": 0,
      "name": "Soil_Snow"
    },
    {
      "x": -21,
      "y": 0,
      "z": 1,
      "name": "Soil_Snow"
    },
    {
      "x": -21,
      "y": 0,
      "z": 2,
      "name": "Soil_Snow"
    },
    {
      "x": -21,
      "y": 0,
      "z": 3,
      "name": "Soil_Snow"
    },
    {
      "x": -21,
      "y": 0,
      "z": 4,
      "name": "Soil_Snow"
    },
    {
      "x": -21,
      "y": 0,
      "z": 5,
      "name": "Soil_Snow"
    },
    {
      "x": -21,
      "y": 0,
      "z": 6,
      "name": "Soil_Snow"
    },
    {
      "x": -21,
      "y": 0,
      "z": 7,
      "name": "Soil_Snow"
    },
    {
      "x": -21,
      "y": 0,
      "z": 8,
      "name": "Soil_Snow_Half"
    },
    {
      "x": -20,
      "y": 0,
      "z": -11,
      "name": "Soil_Snow_Half"
    },
    {
      "x": -20,
      "y": 0,
      "z": -10,
      "name": "Soil_Snow_Half"
    },
    {
      "x": -20,
      "y": 0,
      "z": -9,
      "name": "Soil_Snow"
    },
    {
      "x": -20,
      "y": 4,
      "z": -9,
      "name": "Plant_Leaves_Fir",
      "support": 15,
      "rotation": 2
    },
    {
      "x": -20,
      "y": 0,
      "z": -8,
      "name": "Soil_Snow"
    },
    {
      "x": -20,
      "y": 4,
      "z": -8,
      "name": "Plant_Leaves_Fir",
      "support": 15,
      "rotation": 3
    },
    {
      "x": -20,
      "y": 5,
      "z": -8,
      "name": "Plant_Leaves_Fir",
      "support": 15,
      "rotation": 3
    },
    {
      "x": -20,
      "y": 6,
      "z": -8,
      "name": "Plant_Leaves_Fir",
      "support": 15,
      "rotation": 2
    },
    {
      "x": -20,
      "y": 0,
      "z": -7,
      "name": "Soil_Snow"
    },
    {
      "x": -20,
      "y": 1,
      "z": -7,
      "name": "Plant_Bush_Winter_Snow",
      "support": 15
    },
    {
      "x": -20,
      "y": 4,
      "z": -7,
      "name": "Plant_Leaves_Fir",
      "support": 15,
      "rotation": 3
    },
    {
      "x": -20,
      "y": 5,
      "z": -7,
      "name": "Plant_Leaves_Fir",
      "support": 15,
      "rotation": 3
    },
    {
      "x": -20,
      "y": 6,
      "z": -7,
      "name": "Plant_Leaves_Fir",
      "support": 15,
      "rotation": 3
    },
    {
      "x": -20,
      "y": 7,
      "z": -7,
      "name": "Plant_Leaves_Fir",
      "support": 15,
      "rotation": 3
    },
    {
      "x": -20,
      "y": 8,
      "z": -7,
      "name": "Plant_Leaves_Fir",
      "support": 15,
      "rotation": 3
    },
    {
      "x": -20,
      "y": 0,
      "z": -6,
      "name": "Soil_Snow"
    },
    {
      "x": -20,
      "y": 4,
      "z": -6,
      "name": "Plant_Leaves_Fir",
      "support": 15,
      "rotation": 3
    },
    {
      "x": -20,
      "y": 5,
      "z": -6,
      "name": "Plant_Leaves_Fir",
      "support": 15
    },
    {
      "x": -20,
      "y": 6,
      "z": -6,
      "name": "Plant_Leaves_Fir",
      "support": 15,
      "rotation": 3
    },
    {
      "x": -20,
      "y": 7,
      "z": -6,
      "name": "Plant_Leaves_Fir",
      "support": 15,
      "rotation": 3
    },
    {
      "x": -20,
      "y": 0,
      "z": -5,
      "name": "Soil_Snow"
    },
    {
      "x": -20,
      "y": 4,
      "z": -5,
      "name": "Plant_Leaves_Fir",
      "support": 15,
      "rotation": 3
    },
    {
      "x": -20,
      "y": 5,
      "z": -5,
      "name": "Plant_Leaves_Fir",
      "support": 15,
      "rotation": 3
    },
    {
      "x": -20,
      "y": 0,
      "z": -4,
      "name": "Soil_Snow"
    },
    {
      "x": -20,
      "y": 0,
      "z": -3,
      "name": "Soil_Snow"
    },
    {
      "x": -20,
      "y": 0,
      "z": -2,
      "name": "Soil_Snow"
    },
    {
      "x": -20,
      "y": 0,
      "z": -1,
      "name": "Soil_Snow"
    },
    {
      "x": -20,
      "y": 0,
      "z": 0,
      "name": "Soil_Snow"
    },
    {
      "x": -20,
      "y": 0,
      "z": 1,
      "name": "Soil_Snow"
    },
    {
      "x": -20,
      "y": 0,
      "z": 2,
      "name": "Soil_Clay_Smooth_White"
    },
    {
      "x": -20,
      "y": 0,
      "z": 3,
      "name": "Soil_Clay_Smooth_White"
    },
    {
      "x": -20,
      "y": 0,
      "z": 4,
      "name": "Soil_Snow"
    },
    {
      "x": -20,
      "y": 0,
      "z": 5,
      "name": "Soil_Snow"
    },
    {
      "x": -20,
      "y": 0,
      "z": 6,
      "name": "Soil_Snow"
    },
    {
      "x": -20,
      "y": 0,
      "z": 7,
      "name": "Soil_Snow"
    },
    {
      "x": -20,
      "y": 0,
      "z": 8,
      "name": "Soil_Snow"
    },
    {
      "x": -20,
      "y": 0,
      "z": 9,
      "name": "Soil_Snow_Half"
    },
    {
      "x": -20,
      "y": 0,
      "z": 10,
      "name": "Soil_Snow_Half"
    },
    {
      "x": -19,
      "y": 0,
      "z": -12,
      "name": "Soil_Snow_Half"
    },
    {
      "x": -19,
      "y": 0,
      "z": -11,
      "name": "Soil_Snow"
    },
    {
      "x": -19,
      "y": 0,
      "z": -10,
      "name": "Soil_Snow"
    },
    {
      "x": -19,
      "y": 4,
      "z": -10,
      "name": "Plant_Leaves_Fir",
      "support": 15,
      "rotation": 2
    },
    {
      "x": -19,
      "y": 0,
      "z": -9,
      "name": "Soil_Snow"
    },
    {
      "x": -19,
      "y": 4,
      "z": -9,
      "name": "Plant_Leaves_Fir",
      "support": 15,
      "rotation": 2
    },
    {
      "x": -19,
      "y": 5,
      "z": -9,
      "name": "Plant_Leaves_Fir",
      "support": 15,
      "rotation": 2
    },
    {
      "x": -19,
      "y": 6,
      "z": -9,
      "name": "Plant_Leaves_Fir",
      "support": 15,
      "rotation": 2
    },
    {
      "x": -19,
      "y": 0,
      "z": -8,
      "name": "Soil_Snow"
    },
    {
      "x": -19,
      "y": 4,
      "z": -8,
      "name": "Plant_Leaves_Fir",
      "support": 15,
      "rotation": 2
    },
    {
      "x": -19,
      "y": 5,
      "z": -8,
      "name": "Plant_Leaves_Fir",
      "support": 15,
      "rotation": 2
    },
    {
      "x": -19,
      "y": 6,
      "z": -8,
      "name": "Plant_Leaves_Fir",
      "support": 15,
      "rotation": 2
    },
    {
      "x": -19,
      "y": 7,
      "z": -8,
      "name": "Plant_Leaves_Fir",
      "support": 15,
      "rotation": 2
    },
    {
      "x": -19,
      "y": 8,
      "z": -8,
      "name": "Plant_Leaves_Fir",
      "support": 15,
      "rotation": 2
    },
    {
      "x": -19,
      "y": 0,
      "z": -7,
      "name": "Soil_Snow"
    },
    {
      "x": -19,
      "y": 1,
      "z": -7,
      "name": "Wood_Fir_Trunk_Full",
      "support": 15
    },
    {
      "x": -19,
      "y": 2,
      "z": -7,
      "name": "Wood_Fir_Trunk_Full",
      "support": 15
    },
    {
      "x": -19,
      "y": 3,
      "z": -7,
      "name": "Wood_Fir_Trunk_Full",
      "support": 15
    },
    {
      "x": -19,
      "y": 4,
      "z": -7,
      "name": "Wood_Fir_Trunk_Full",
      "support": 15
    },
    {
      "x": -19,
      "y": 5,
      "z": -7,
      "name": "Wood_Fir_Trunk_Full",
      "support": 15
    },
    {
      "x": -19,
      "y": 6,
      "z": -7,
      "name": "Wood_Fir_Trunk_Full",
      "support": 15
    },
    {
      "x": -19,
      "y": 7,
      "z": -7,
      "name": "Wood_Fir_Trunk_Full",
      "support": 15
    },
    {
      "x": -19,
      "y": 8,
      "z": -7,
      "name": "Plant_Leaves_Fir",
      "support": 15,
      "rotation": 3
    },
    {
      "x": -19,
      "y": 9,
      "z": -7,
      "name": "Plant_Leaves_Fir_Tip",
      "support": 15
    },
    {
      "x": -19,
      "y": 0,
      "z": -6,
      "name": "Soil_Snow"
    },
    {
      "x": -19,
      "y": 4,
      "z": -6,
      "name": "Plant_Leaves_Fir",
      "support": 15
    },
    {
      "x": -19,
      "y": 5,
      "z": -6,
      "name": "Plant_Leaves_Fir",
      "support": 15
    },
    {
      "x": -19,
      "y": 6,
      "z": -6,
      "name": "Plant_Leaves_Fir",
      "support": 15
    },
    {
      "x": -19,
      "y": 7,
      "z": -6,
      "name": "Plant_Leaves_Fir",
      "support": 15
    },
    {
      "x": -19,
      "y": 8,
      "z": -6,
      "name": "Plant_Leaves_Fir",
      "support": 15
    },
    {
      "x": -19,
      "y": 0,
      "z": -5,
      "name": "Soil_Snow"
    },
    {
      "x": -19,
      "y": 4,
      "z": -5,
      "name": "Plant_Leaves_Fir",
      "support": 15
    },
    {
      "x": -19,
      "y": 5,
      "z": -5,
      "name": "Plant_Leaves_Fir",
      "support": 15
    },
    {
      "x": -19,
      "y": 0,
      "z": -4,
      "name": "Soil_Snow"
    },
    {
      "x": -19,
      "y": 1,
      "z": -4,
      "name": "Plant_Crop_Mushroom_Shelve_Brown"
    },
    {
      "x": -19,
      "y": 4,
      "z": -4,
      "name": "Plant_Leaves_Fir",
      "support": 15
    },
    {
      "x": -19,
      "y": 0,
      "z": -3,
      "name": "Soil_Snow"
    },
    {
      "x": -19,
      "y": 0,
      "z": -2,
      "name": "Soil_Snow"
    },
    {
      "x": -19,
      "y": 0,
      "z": -1,
      "name": "Soil_Snow"
    },
    {
      "x": -19,
      "y": 0,
      "z": 0,
      "name": "Soil_Snow"
    },
    {
      "x": -19,
      "y": 0,
      "z": 1,
      "name": "Soil_Snow"
    },
    {
      "x": -19,
      "y": 1,
      "z": 1,
      "name": "Plant_Crop_Mushroom_Glowing_Green"
    },
    {
      "x": -19,
      "y": 0,
      "z": 2,
      "name": "Soil_Snow"
    },
    {
      "x": -19,
      "y": 1,
      "z": 2,
      "name": "Rock_Stone_Cobble_Mossy_Half"
    },
    {
      "x": -19,
      "y": 0,
      "z": 3,
      "name": "Soil_Snow"
    },
    {
      "x": -19,
      "y": 1,
      "z": 3,
      "name": "Rock_Stone_Mossy"
    },
    {
      "x": -19,
      "y": 0,
      "z": 4,
      "name": "Soil_Snow"
    },
    {
      "x": -19,
      "y": 1,
      "z": 4,
      "name": "Rock_Stone_Cobble_Stairs"
    },
    {
      "x": -19,
      "y": 0,
      "z": 5,
      "name": "Soil_Snow"
    },
    {
      "x": -19,
      "y": 0,
      "z": 6,
      "name": "Soil_Snow"
    },
    {
      "x": -19,
      "y": 1,
      "z": 6,
      "name": "Rubble_Stone",
      "support": 15
    },
    {
      "x": -19,
      "y": 0,
      "z": 7,
      "name": "Soil_Snow"
    },
    {
      "x": -19,
      "y": 0,
      "z": 8,
      "name": "Soil_Snow"
    },
    {
      "x": -19,
      "y": 0,
      "z": 9,
      "name": "Soil_Snow"
    },
    {
      "x": -19,
      "y": 0,
      "z": 10,
      "name": "Soil_Snow"
    },
    {
      "x": -19,
      "y": 0,
      "z": 11,
      "name": "Soil_Snow_Half"
    },
    {
      "x": -18,
      "y": 0,
      "z": -13,
      "name": "Soil_Snow_Half"
    },
    {
      "x": -18,
      "y": 0,
      "z": -12,
      "name": "Soil_Snow"
    },
    {
      "x": -18,
      "y": 0,
      "z": -11,
      "name": "Soil_Snow"
    },
    {
      "x": -18,
      "y": 0,
      "z": -10,
      "name": "Soil_Snow"
    },
    {
      "x": -18,
      "y": 1,
      "z": -10,
      "name": "Rubble_Stone",
      "support": 15
    },
    {
      "x": -18,
      "y": 0,
      "z": -9,
      "name": "Soil_Snow"
    },
    {
      "x": -18,
      "y": 4,
      "z": -9,
      "name": "Plant_Leaves_Fir",
      "support": 15,
      "rotation": 2
    },
    {
      "x": -18,
      "y": 0,
      "z": -8,
      "name": "Soil_Snow"
    },
    {
      "x": -18,
      "y": 1,
      "z": -8,
      "name": "Plant_Bush_Winter_Sharp",
      "support": 15
    },
    {
      "x": -18,
      "y": 4,
      "z": -8,
      "name": "Plant_Leaves_Fir",
      "support": 15,
      "rotation": 1
    },
    {
      "x": -18,
      "y": 5,
      "z": -8,
      "name": "Plant_Leaves_Fir",
      "support": 15,
      "rotation": 2
    },
    {
      "x": -18,
      "y": 6,
      "z": -8,
      "name": "Plant_Leaves_Fir",
      "support": 15,
      "rotation": 1
    },
    {
      "x": -18,
      "y": 7,
      "z": -8,
      "name": "Plant_Leaves_Fir",
      "support": 15,
      "rotation": 2
    },
    {
      "x": -18,
      "y": 0,
      "z": -7,
      "name": "Soil_Snow"
    },
    {
      "x": -18,
      "y": 4,
      "z": -7,
      "name": "Plant_Leaves_Fir",
      "support": 15,
      "rotation": 1
    },
    {
      "x": -18,
      "y": 5,
      "z": -7,
      "name": "Plant_Leaves_Fir",
      "support": 15,
      "rotation": 1
    },
    {
      "x": -18,
      "y": 6,
      "z": -7,
      "name": "Plant_Leaves_Fir",
      "support": 15,
      "rotation": 1
    },
    {
      "x": -18,
      "y": 7,
      "z": -7,
      "name": "Plant_Leaves_Fir",
      "support": 15,
      "rotation": 1
    },
    {
      "x": -18,
      "y": 8,
      "z": -7,
      "name": "Plant_Leaves_Fir",
      "support": 15,
      "rotation": 1
    },
    {
      "x": -18,
      "y": 0,
      "z": -6,
      "name": "Soil_Snow"
    },
    {
      "x": -18,
      "y": 4,
      "z": -6,
      "name": "Plant_Leaves_Fir",
      "support": 15
    },
    {
      "x": -18,
      "y": 5,
      "z": -6,
      "name": "Plant_Leaves_Fir",
      "support": 15,
      "rotation": 1
    },
    {
      "x": -18,
      "y": 6,
      "z": -6,
      "name": "Plant_Leaves_Fir",
      "support": 15
    },
    {
      "x": -18,
      "y": 7,
      "z": -6,
      "name": "Plant_Leaves_Fir",
      "support": 15
    },
    {
      "x": -18,
      "y": 0,
      "z": -5,
      "name": "Soil_Snow"
    },
    {
      "x": -18,
      "y": 4,
      "z": -5,
      "name": "Plant_Leaves_Fir",
      "support": 15
    },
    {
      "x": -18,
      "y": 5,
      "z": -5,
      "name": "Plant_Leaves_Fir",
      "support": 15
    },
    {
      "x": -18,
      "y": 0,
      "z": -4,
      "name": "Soil_Snow"
    },
    {
      "x": -18,
      "y": 0,
      "z": -3,
      "name": "Soil_Snow"
    },
    {
      "x": -18,
      "y": 0,
      "z": -2,
      "name": "Soil_Snow"
    },
    {
      "x": -18,
      "y": 0,
      "z": -1,
      "name": "Soil_Snow"
    },
    {
      "x": -18,
      "y": 0,
      "z": 0,
      "name": "Soil_Snow"
    },
    {
      "x": -18,
      "y": 0,
      "z": 1,
      "name": "Soil_Snow"
    },
    {
      "x": -18,
      "y": 1,
      "z": 1,
      "name": "Rock_Stone_Cobble_Half"
    },
    {
      "x": -18,
      "y": 0,
      "z": 2,
      "name": "Soil_Snow"
    },
    {
      "x": -18,
      "y": 1,
      "z": 2,
      "name": "Ore_Thorium_Stone"
    },
    {
      "x": -18,
      "y": 2,
      "z": 2,
      "name": "Rock_Stone_Cobble_Stairs",
      "rotation": 2
    },
    {
      "x": -18,
      "y": 0,
      "z": 3,
      "name": "Soil_Snow"
    },
    {
      "x": -18,
      "y": 1,
      "z": 3,
      "name": "Rock_Stone"
    },
    {
      "x": -18,
      "y": 2,
      "z": 3,
      "name": "Rock_Stone"
    },
    {
      "x": -18,
      "y": 3,
      "z": 3,
      "name": "Rubble_Stone",
      "support": 15
    },
    {
      "x": -18,
      "y": 0,
      "z": 4,
      "name": "Soil_Snow"
    },
    {
      "x": -18,
      "y": 1,
      "z": 4,
      "name": "Rock_Stone"
    },
    {
      "x": -18,
      "y": 2,
      "z": 4,
      "name": "Rock_Stone_Cobble_Mossy"
    },
    {
      "x": -18,
      "y": 3,
      "z": 4,
      "name": "Rock_Stone_Cobble_Mossy_Half"
    },
    {
      "x": -18,
      "y": 0,
      "z": 5,
      "name": "Soil_Snow"
    },
    {
      "x": -18,
      "y": 1,
      "z": 5,
      "name": "Rock_Stone_Cobble"
    },
    {
      "x": -18,
      "y": 0,
      "z": 6,
      "name": "Soil_Snow"
    },
    {
      "x": -18,
      "y": 0,
      "z": 7,
      "name": "Soil_Snow"
    },
    {
      "x": -18,
      "y": 0,
      "z": 8,
      "name": "Soil_Snow"
    },
    {
      "x": -18,
      "y": 0,
      "z": 9,
      "name": "Soil_Snow"
    },
    {
      "x": -18,
      "y": 0,
      "z": 10,
      "name": "Soil_Snow"
    },
    {
      "x": -18,
      "y": 0,
      "z": 11,
      "name": "Soil_Snow"
    },
    {
      "x": -18,
      "y": 0,
      "z": 12,
      "name": "Soil_Snow_Half"
    },
    {
      "x": -18,
      "y": 0,
      "z": 13,
      "name": "Soil_Snow_Half"
    },
    {
      "x": -17,
      "y": 0,
      "z": -14,
      "name": "Soil_Snow_Half"
    },
    {
      "x": -17,
      "y": 0,
      "z": -13,
      "name": "Soil_Snow"
    },
    {
      "x": -17,
      "y": 0,
      "z": -12,
      "name": "Soil_Snow"
    },
    {
      "x": -17,
      "y": 0,
      "z": -11,
      "name": "Soil_Snow"
    },
    {
      "x": -17,
      "y": 0,
      "z": -10,
      "name": "Soil_Snow"
    },
    {
      "x": -17,
      "y": 0,
      "z": -9,
      "name": "Soil_Snow"
    },
    {
      "x": -17,
      "y": 0,
      "z": -8,
      "name": "Soil_Snow"
    },
    {
      "x": -17,
      "y": 4,
      "z": -8,
      "name": "Plant_Leaves_Fir",
      "support": 15,
      "rotation": 2
    },
    {
      "x": -17,
      "y": 0,
      "z": -7,
      "name": "Soil_Snow"
    },
    {
      "x": -17,
      "y": 4,
      "z": -7,
      "name": "Plant_Leaves_Fir",
      "support": 15,
      "rotation": 1
    },
    {
      "x": -17,
      "y": 5,
      "z": -7,
      "name": "Plant_Leaves_Fir",
      "support": 15,
      "rotation": 1
    },
    {
      "x": -17,
      "y": 6,
      "z": -7,
      "name": "Plant_Leaves_Fir",
      "support": 15,
      "rotation": 1
    },
    {
      "x": -17,
      "y": 0,
      "z": -6,
      "name": "Soil_Snow"
    },
    {
      "x": -17,
      "y": 4,
      "z": -6,
      "name": "Plant_Leaves_Fir",
      "support": 15
    },
    {
      "x": -17,
      "y": 5,
      "z": -6,
      "name": "Plant_Leaves_Fir",
      "support": 15,
      "rotation": 1
    },
    {
      "x": -17,
      "y": 0,
      "z": -5,
      "name": "Soil_Snow"
    },
    {
      "x": -17,
      "y": 1,
      "z": -5,
      "name": "Deco_SpiderWeb",
      "support": 15,
      "rotation": 3
    },
    {
      "x": -17,
      "y": 0,
      "z": -4,
      "name": "Soil_Snow"
    },
    {
      "x": -17,
      "y": 0,
      "z": -3,
      "name": "Soil_Snow"
    },
    {
      "x": -17,
      "y": 0,
      "z": -2,
      "name": "Soil_Snow"
    },
    {
      "x": -17,
      "y": 0,
      "z": -1,
      "name": "Soil_Snow"
    },
    {
      "x": -17,
      "y": 0,
      "z": 0,
      "name": "Soil_Snow"
    },
    {
      "x": -17,
      "y": 1,
      "z": 0,
      "name": "Rubble_Stone_Medium",
      "support": 15
    },
    {
      "x": -17,
      "y": 0,
      "z": 1,
      "name": "Soil_Snow"
    },
    {
      "x": -17,
      "y": 1,
      "z": 1,
      "name": "Rock_Stone_Cobble_Mossy_Half"
    },
    {
      "x": -17,
      "y": 0,
      "z": 2,
      "name": "Soil_Snow"
    },
    {
      "x": -17,
      "y": 1,
      "z": 2,
      "name": "Rock_Stone"
    },
    {
      "x": -17,
      "y": 2,
      "z": 2,
      "name": "Ore_Thorium_Stone"
    },
    {
      "x": -17,
      "y": 0,
      "z": 3,
      "name": "Soil_Snow"
    },
    {
      "x": -17,
      "y": 1,
      "z": 3,
      "name": "Rock_Stone"
    },
    {
      "x": -17,
      "y": 2,
      "z": 3,
      "name": "Rock_Stone_Cobble"
    },
    {
      "x": -17,
      "y": 3,
      "z": 3,
      "name": "Plant_Crop_Mushroom_Glowing_Green"
    },
    {
      "x": -17,
      "y": 0,
      "z": 4,
      "name": "Soil_Snow"
    },
    {
      "x": -17,
      "y": 1,
      "z": 4,
      "name": "Rock_Stone_Cobble"
    },
    {
      "x": -17,
      "y": 2,
      "z": 4,
      "name": "Rock_Stone_Cobble_Stairs",
      "rotation": 1
    },
    {
      "x": -17,
      "y": 0,
      "z": 5,
      "name": "Soil_Snow"
    },
    {
      "x": -17,
      "y": 1,
      "z": 5,
      "name": "Rock_Stone_Mossy"
    },
    {
      "x": -17,
      "y": 0,
      "z": 6,
      "name": "Rock_Stone_Cobble"
    },
    {
      "x": -17,
      "y": 1,
      "z": 6,
      "name": "Plant_Crop_Mushroom_Glowing_Green"
    },
    {
      "x": -17,
      "y": 0,
      "z": 7,
      "name": "Soil_Snow"
    },
    {
      "x": -17,
      "y": 0,
      "z": 8,
      "name": "Soil_Snow"
    },
    {
      "x": -17,
      "y": 0,
      "z": 9,
      "name": "Soil_Snow"
    },
    {
      "x": -17,
      "y": 1,
      "z": 9,
      "name": "Plant_Bush_Winter_Sharp",
      "support": 15
    },
    {
      "x": -17,
      "y": 0,
      "z": 10,
      "name": "Soil_Snow"
    },
    {
      "x": -17,
      "y": 0,
      "z": 11,
      "name": "Soil_Snow"
    },
    {
      "x": -17,
      "y": 1,
      "z": 11,
      "name": "Plant_Bush_Lush",
      "support": 15
    },
    {
      "x": -17,
      "y": 0,
      "z": 12,
      "name": "Soil_Snow"
    },
    {
      "x": -17,
      "y": 0,
      "z": 13,
      "name": "Soil_Snow"
    },
    {
      "x": -17,
      "y": 0,
      "z": 14,
      "name": "Soil_Snow_Half"
    },
    {
      "x": -16,
      "y": 0,
      "z": -15,
      "name": "Soil_Snow_Half"
    },
    {
      "x": -16,
      "y": 0,
      "z": -14,
      "name": "Soil_Snow"
    },
    {
      "x": -16,
      "y": 0,
      "z": -13,
      "name": "Soil_Snow"
    },
    {
      "x": -16,
      "y": 0,
      "z": -12,
      "name": "Soil_Snow"
    },
    {
      "x": -16,
      "y": 0,
      "z": -11,
      "name": "Soil_Snow"
    },
    {
      "x": -16,
      "y": 0,
      "z": -10,
      "name": "Soil_Snow"
    },
    {
      "x": -16,
      "y": 0,
      "z": -9,
      "name": "Soil_Snow"
    },
    {
      "x": -16,
      "y": 0,
      "z": -8,
      "name": "Soil_Snow"
    },
    {
      "x": -16,
      "y": 0,
      "z": -7,
      "name": "Soil_Snow"
    },
    {
      "x": -16,
      "y": 4,
      "z": -7,
      "name": "Plant_Leaves_Fir",
      "support": 15,
      "rotation": 1
    },
    {
      "x": -16,
      "y": 0,
      "z": -6,
      "name": "Soil_Snow"
    },
    {
      "x": -16,
      "y": 0,
      "z": -5,
      "name": "Soil_Snow"
    },
    {
      "x": -16,
      "y": 1,
      "z": -5,
      "name": "Furniture_Village_Tombstone",
      "rotation": 1
    },
    {
      "x": -16,
      "y": 2,
      "z": -5,
      "name": "Furniture_Village_Tombstone",
      "filler": 1024,
      "rotation": 1
    },
    {
      "x": -16,
      "y": 0,
      "z": -4,
      "name": "Soil_Snow"
    },
    {
      "x": -16,
      "y": 1,
      "z": -4,
      "name": "Deco_SpiderWeb",
      "support": 15
    },
    {
      "x": -16,
      "y": 0,
      "z": -3,
      "name": "Soil_Snow"
    },
    {
      "x": -16,
      "y": 0,
      "z": -2,
      "name": "Soil_Snow"
    },
    {
      "x": -16,
      "y": 0,
      "z": -1,
      "name": "Soil_Snow"
    },
    {
      "x": -16,
      "y": 0,
      "z": 0,
      "name": "Soil_Snow"
    },
    {
      "x": -16,
      "y": 0,
      "z": 1,
      "name": "Soil_Snow"
    },
    {
      "x": -16,
      "y": 1,
      "z": 1,
      "name": "Rock_Stone_Cobble_Stairs",
      "rotation": 2
    },
    {
      "x": -16,
      "y": 0,
      "z": 2,
      "name": "Soil_Snow"
    },
    {
      "x": -16,
      "y": 1,
      "z": 2,
      "name": "Rock_Stone"
    },
    {
      "x": -16,
      "y": 2,
      "z": 2,
      "name": "Rubble_Stone",
      "support": 15
    },
    {
      "x": -16,
      "y": 0,
      "z": 3,
      "name": "Soil_Snow"
    },
    {
      "x": -16,
      "y": 1,
      "z": 3,
      "name": "Ore_Thorium_Stone"
    },
    {
      "x": -16,
      "y": 2,
      "z": 3,
      "name": "Rock_Stone_Cobble_Mossy_Half"
    },
    {
      "x": -16,
      "y": 0,
      "z": 4,
      "name": "Soil_Snow"
    },
    {
      "x": -16,
      "y": 1,
      "z": 4,
      "name": "Rock_Stone_Cobble"
    },
    {
      "x": -16,
      "y": 0,
      "z": 5,
      "name": "Soil_Snow"
    },
    {
      "x": -16,
      "y": 1,
      "z": 5,
      "name": "Rock_Stone_Cobble_Mossy_Half"
    },
    {
      "x": -16,
      "y": 0,
      "z": 6,
      "name": "Soil_Snow"
    },
    {
      "x": -16,
      "y": 0,
      "z": 7,
      "name": "Soil_Snow"
    },
    {
      "x": -16,
      "y": 0,
      "z": 8,
      "name": "Soil_Snow"
    },
    {
      "x": -16,
      "y": 0,
      "z": 9,
      "name": "Soil_Snow"
    },
    {
      "x": -16,
      "y": 0,
      "z": 10,
      "name": "Soil_Snow"
    },
    {
      "x": -16,
      "y": 0,
      "z": 11,
      "name": "Soil_Snow"
    },
    {
      "x": -16,
      "y": 1,
      "z": 11,
      "name": "Plant_Bush_Lush",
      "support": 15
    },
    {
      "x": -16,
      "y": 0,
      "z": 12,
      "name": "Soil_Snow"
    },
    {
      "x": -16,
      "y": 1,
      "z": 12,
      "name": "Plant_Bush_Lush",
      "support": 15
    },
    {
      "x": -16,
      "y": 0,
      "z": 13,
      "name": "Soil_Snow"
    },
    {
      "x": -16,
      "y": 0,
      "z": 14,
      "name": "Soil_Snow_Half"
    },
    {
      "x": -16,
      "y": 0,
      "z": 15,
      "name": "Soil_Snow_Half"
    },
    {
      "x": -15,
      "y": 0,
      "z": -15,
      "name": "Soil_Snow_Half"
    },
    {
      "x": -15,
      "y": 0,
      "z": -14,
      "name": "Soil_Snow"
    },
    {
      "x": -15,
      "y": 0,
      "z": -13,
      "name": "Soil_Snow"
    },
    {
      "x": -15,
      "y": 0,
      "z": -12,
      "name": "Rock_Ice"
    },
    {
      "x": -15,
      "y": 0,
      "z": -11,
      "name": "Soil_Snow"
    },
    {
      "x": -15,
      "y": 1,
      "z": -11,
      "name": "Plant_Bush_Winter_Sharp",
      "support": 15
    },
    {
      "x": -15,
      "y": 0,
      "z": -10,
      "name": "Soil_Snow"
    },
    {
      "x": -15,
      "y": 0,
      "z": -9,
      "name": "Soil_Snow"
    },
    {
      "x": -15,
      "y": 1,
      "z": -9,
      "name": "Plant_Bush_Lush",
      "support": 15
    },
    {
      "x": -15,
      "y": 0,
      "z": -8,
      "name": "Soil_Snow"
    },
    {
      "x": -15,
      "y": 1,
      "z": -8,
      "name": "Plant_Bush_Lush",
      "support": 15
    },
    {
      "x": -15,
      "y": 0,
      "z": -7,
      "name": "Soil_Snow"
    },
    {
      "x": -15,
      "y": 0,
      "z": -6,
      "name": "Soil_Snow"
    },
    {
      "x": -15,
      "y": 0,
      "z": -5,
      "name": "Soil_Snow"
    },
    {
      "x": -15,
      "y": 0,
      "z": -4,
      "name": "Soil_Snow"
    },
    {
      "x": -15,
      "y": 0,
      "z": -3,
      "name": "Soil_Snow"
    },
    {
      "x": -15,
      "y": 0,
      "z": -2,
      "name": "Soil_Snow"
    },
    {
      "x": -15,
      "y": 0,
      "z": -1,
      "name": "Soil_Snow"
    },
    {
      "x": -15,
      "y": 0,
      "z": 0,
      "name": "Soil_Snow"
    },
    {
      "x": -15,
      "y": 0,
      "z": 1,
      "name": "Soil_Snow"
    },
    {
      "x": -15,
      "y": 0,
      "z": 2,
      "name": "Soil_Snow"
    },
    {
      "x": -15,
      "y": 1,
      "z": 2,
      "name": "Plant_Crop_Mushroom_Shelve_Brown"
    },
    {
      "x": -15,
      "y": 0,
      "z": 3,
      "name": "Soil_Snow"
    },
    {
      "x": -15,
      "y": 1,
      "z": 3,
      "name": "Rock_Stone_Cobble_Half"
    },
    {
      "x": -15,
      "y": 0,
      "z": 4,
      "name": "Soil_Snow"
    },
    {
      "x": -15,
      "y": 1,
      "z": 4,
      "name": "Rock_Stone_Cobble_Half"
    },
    {
      "x": -15,
      "y": 0,
      "z": 5,
      "name": "Soil_Snow"
    },
    {
      "x": -15,
      "y": 1,
      "z": 5,
      "name": "Rubble_Stone_Medium",
      "support": 15
    },
    {
      "x": -15,
      "y": 0,
      "z": 6,
      "name": "Soil_Snow"
    },
    {
      "x": -15,
      "y": 0,
      "z": 7,
      "name": "Soil_Snow"
    },
    {
      "x": -15,
      "y": 0,
      "z": 8,
      "name": "Soil_Snow"
    },
    {
      "x": -15,
      "y": 0,
      "z": 9,
      "name": "Soil_Snow"
    },
    {
      "x": -15,
      "y": 0,
      "z": 10,
      "name": "Soil_Snow"
    },
    {
      "x": -15,
      "y": 0,
      "z": 11,
      "name": "Soil_Snow"
    },
    {
      "x": -15,
      "y": 0,
      "z": 12,
      "name": "Soil_Snow"
    },
    {
      "x": -15,
      "y": 0,
      "z": 13,
      "name": "Soil_Snow"
    },
    {
      "x": -15,
      "y": 0,
      "z": 14,
      "name": "Soil_Snow"
    },
    {
      "x": -15,
      "y": 0,
      "z": 15,
      "name": "Soil_Snow"
    },
    {
      "x": -15,
      "y": 0,
      "z": 16,
      "name": "Soil_Snow_Half"
    },
    {
      "x": -14,
      "y": 0,
      "z": -16,
      "name": "Soil_Snow_Half"
    },
    {
      "x": -14,
      "y": 0,
      "z": -15,
      "name": "Soil_Snow"
    },
    {
      "x": -14,
      "y": 0,
      "z": -14,
      "name": "Soil_Snow"
    },
    {
      "x": -14,
      "y": 0,
      "z": -13,
      "name": "Soil_Snow"
    },
    {
      "x": -14,
      "y": 0,
      "z": -12,
      "name": "Soil_Snow"
    },
    {
      "x": -14,
      "y": 0,
      "z": -11,
      "name": "Soil_Snow"
    },
    {
      "x": -14,
      "y": 0,
      "z": -10,
      "name": "Soil_Snow"
    },
    {
      "x": -14,
      "y": 1,
      "z": -10,
      "name": "Plant_Bush_Lush",
      "support": 15
    },
    {
      "x": -14,
      "y": 0,
      "z": -9,
      "name": "Soil_Snow"
    },
    {
      "x": -14,
      "y": 1,
      "z": -9,
      "name": "Plant_Bush_Lush",
      "support": 15
    },
    {
      "x": -14,
      "y": 2,
      "z": -9,
      "name": "Plant_Bush_Lush",
      "support": 15
    },
    {
      "x": -14,
      "y": 0,
      "z": -8,
      "name": "Soil_Snow"
    },
    {
      "x": -14,
      "y": 1,
      "z": -8,
      "name": "Plant_Bush_Lush",
      "support": 15
    },
    {
      "x": -14,
      "y": 0,
      "z": -7,
      "name": "Soil_Snow"
    },
    {
      "x": -14,
      "y": 0,
      "z": -6,
      "name": "Soil_Snow"
    },
    {
      "x": -14,
      "y": 0,
      "z": -5,
      "name": "Soil_Snow"
    },
    {
      "x": -14,
      "y": 0,
      "z": -4,
      "name": "Soil_Snow"
    },
    {
      "x": -14,
      "y": 0,
      "z": -3,
      "name": "Soil_Snow"
    },
    {
      "x": -14,
      "y": 0,
      "z": -2,
      "name": "Soil_Snow"
    },
    {
      "x": -14,
      "y": 0,
      "z": -1,
      "name": "Soil_Snow"
    },
    {
      "x": -14,
      "y": 0,
      "z": 0,
      "name": "Soil_Snow"
    },
    {
      "x": -14,
      "y": 0,
      "z": 1,
      "name": "Soil_Snow"
    },
    {
      "x": -14,
      "y": 0,
      "z": 2,
      "name": "Soil_Snow"
    },
    {
      "x": -14,
      "y": 0,
      "z": 3,
      "name": "Rock_Ice"
    },
    {
      "x": -14,
      "y": 0,
      "z": 4,
      "name": "Rock_Ice"
    },
    {
      "x": -14,
      "y": 0,
      "z": 5,
      "name": "Soil_Snow"
    },
    {
      "x": -14,
      "y": 0,
      "z": 6,
      "name": "Soil_Snow"
    },
    {
      "x": -14,
      "y": 0,
      "z": 7,
      "name": "Soil_Snow"
    },
    {
      "x": -14,
      "y": 0,
      "z": 8,
      "name": "Soil_Snow"
    },
    {
      "x": -14,
      "y": 0,
      "z": 9,
      "name": "Soil_Clay_Smooth_White"
    },
    {
      "x": -14,
      "y": 0,
      "z": 10,
      "name": "Soil_Clay_Smooth_White"
    },
    {
      "x": -14,
      "y": 0,
      "z": 11,
      "name": "Rock_Ice"
    },
    {
      "x": -14,
      "y": 0,
      "z": 12,
      "name": "Soil_Snow"
    },
    {
      "x": -14,
      "y": 0,
      "z": 13,
      "name": "Soil_Snow"
    },
    {
      "x": -14,
      "y": 0,
      "z": 14,
      "name": "Soil_Snow"
    },
    {
      "x": -14,
      "y": 1,
      "z": 14,
      "name": "Rubble_Stone_Medium",
      "support": 15
    },
    {
      "x": -14,
      "y": 0,
      "z": 15,
      "name": "Soil_Snow"
    },
    {
      "x": -14,
      "y": 0,
      "z": 16,
      "name": "Soil_Snow"
    },
    {
      "x": -14,
      "y": 0,
      "z": 17,
      "name": "Soil_Snow_Half"
    },
    {
      "x": -13,
      "y": 0,
      "z": -17,
      "name": "Soil_Snow_Half"
    },
    {
      "x": -13,
      "y": 0,
      "z": -16,
      "name": "Soil_Snow"
    },
    {
      "x": -13,
      "y": 0,
      "z": -15,
      "name": "Soil_Snow"
    },
    {
      "x": -13,
      "y": 1,
      "z": -15,
      "name": "Plant_Bush_Winter_Sharp",
      "support": 15
    },
    {
      "x": -13,
      "y": 0,
      "z": -14,
      "name": "Soil_Snow"
    },
    {
      "x": -13,
      "y": 0,
      "z": -13,
      "name": "Soil_Snow"
    },
    {
      "x": -13,
      "y": 0,
      "z": -12,
      "name": "Soil_Snow"
    },
    {
      "x": -13,
      "y": 0,
      "z": -11,
      "name": "Soil_Snow"
    },
    {
      "x": -13,
      "y": 0,
      "z": -10,
      "name": "Soil_Snow"
    },
    {
      "x": -13,
      "y": 0,
      "z": -9,
      "name": "Soil_Snow"
    },
    {
      "x": -13,
      "y": 1,
      "z": -9,
      "name": "Plant_Bush_Lush",
      "support": 15
    },
    {
      "x": -13,
      "y": 0,
      "z": -8,
      "name": "Soil_Snow"
    },
    {
      "x": -13,
      "y": 0,
      "z": -7,
      "name": "Soil_Snow"
    },
    {
      "x": -13,
      "y": 0,
      "z": -6,
      "name": "Soil_Snow"
    },
    {
      "x": -13,
      "y": 0,
      "z": -5,
      "name": "Soil_Snow"
    },
    {
      "x": -13,
      "y": 0,
      "z": -4,
      "name": "Soil_Snow"
    },
    {
      "x": -13,
      "y": 0,
      "z": -3,
      "name": "Soil_Snow"
    },
    {
      "x": -13,
      "y": 0,
      "z": -2,
      "name": "Soil_Clay_Smooth_White"
    },
    {
      "x": -13,
      "y": 0,
      "z": -1,
      "name": "Soil_Snow"
    },
    {
      "x": -13,
      "y": 0,
      "z": 0,
      "name": "Soil_Snow"
    },
    {
      "x": -13,
      "y": 0,
      "z": 1,
      "name": "Soil_Snow"
    },
    {
      "x": -13,
      "y": 0,
      "z": 2,
      "name": "Soil_Snow"
    },
    {
      "x": -13,
      "y": 0,
      "z": 3,
      "name": "Soil_Snow"
    },
    {
      "x": -13,
      "y": 0,
      "z": 4,
      "name": "Rock_Ice"
    },
    {
      "x": -13,
      "y": 0,
      "z": 5,
      "name": "Rock_Ice"
    },
    {
      "x": -13,
      "y": 0,
      "z": 6,
      "name": "Soil_Snow"
    },
    {
      "x": -13,
      "y": 1,
      "z": 6,
      "name": "Plant_Bush_Winter_Sharp",
      "support": 15
    },
    {
      "x": -13,
      "y": 0,
      "z": 7,
      "name": "Soil_Snow"
    },
    {
      "x": -13,
      "y": 0,
      "z": 8,
      "name": "Soil_Snow"
    },
    {
      "x": -13,
      "y": 0,
      "z": 9,
      "name": "Soil_Clay_Smooth_White"
    },
    {
      "x": -13,
      "y": 0,
      "z": 10,
      "name": "Soil_Clay_Smooth_White"
    },
    {
      "x": -13,
      "y": 0,
      "z": 11,
      "name": "Rock_Ice"
    },
    {
      "x": -13,
      "y": 0,
      "z": 12,
      "name": "Rock_Ice"
    },
    {
      "x": -13,
      "y": 0,
      "z": 13,
      "name": "Soil_Snow"
    },
    {
      "x": -13,
      "y": 0,
      "z": 14,
      "name": "Soil_Snow"
    },
    {
      "x": -13,
      "y": 0,
      "z": 15,
      "name": "Soil_Snow"
    },
    {
      "x": -13,
      "y": 0,
      "z": 16,
      "name": "Soil_Snow"
    },
    {
      "x": -13,
      "y": 0,
      "z": 17,
      "name": "Soil_Snow"
    },
    {
      "x": -13,
      "y": 0,
      "z": 18,
      "name": "Soil_Snow_Half"
    },
    {
      "x": -12,
      "y": 0,
      "z": -17,
      "name": "Soil_Snow_Half"
    },
    {
      "x": -12,
      "y": 0,
      "z": -16,
      "name": "Soil_Snow"
    },
    {
      "x": -12,
      "y": 0,
      "z": -15,
      "name": "Soil_Snow"
    },
    {
      "x": -12,
      "y": 0,
      "z": -14,
      "name": "Soil_Snow"
    },
    {
      "x": -12,
      "y": 0,
      "z": -13,
      "name": "Soil_Snow"
    },
    {
      "x": -12,
      "y": 0,
      "z": -12,
      "name": "Soil_Snow"
    },
    {
      "x": -12,
      "y": 0,
      "z": -11,
      "name": "Soil_Snow"
    },
    {
      "x": -12,
      "y": 0,
      "z": -10,
      "name": "Soil_Snow"
    },
    {
      "x": -12,
      "y": 0,
      "z": -9,
      "name": "Soil_Snow"
    },
    {
      "x": -12,
      "y": 0,
      "z": -8,
      "name": "Soil_Snow"
    },
    {
      "x": -12,
      "y": 0,
      "z": -7,
      "name": "Soil_Snow"
    },
    {
      "x": -12,
      "y": 0,
      "z": -6,
      "name": "Soil_Snow"
    },
    {
      "x": -12,
      "y": 0,
      "z": -5,
      "name": "Soil_Snow"
    },
    {
      "x": -12,
      "y": 0,
      "z": -4,
      "name": "Soil_Snow"
    },
    {
      "x": -12,
      "y": 0,
      "z": -3,
      "name": "Soil_Snow"
    },
    {
      "x": -12,
      "y": 0,
      "z": -2,
      "name": "Soil_Snow"
    },
    {
      "x": -12,
      "y": 0,
      "z": -1,
      "name": "Soil_Snow"
    },
    {
      "x": -12,
      "y": 0,
      "z": 0,
      "name": "Soil_Snow"
    },
    {
      "x": -12,
      "y": 0,
      "z": 1,
      "name": "Soil_Snow"
    },
    {
      "x": -12,
      "y": 0,
      "z": 2,
      "name": "Soil_Snow"
    },
    {
      "x": -12,
      "y": 0,
      "z": 3,
      "name": "Soil_Snow"
    },
    {
      "x": -12,
      "y": 1,
      "z": 3,
      "name": "Rubble_Stone",
      "support": 15
    },
    {
      "x": -12,
      "y": 0,
      "z": 4,
      "name": "Soil_Snow"
    },
    {
      "x": -12,
      "y": 0,
      "z": 5,
      "name": "Soil_Snow"
    },
    {
      "x": -12,
      "y": 0,
      "z": 6,
      "name": "Soil_Snow"
    },
    {
      "x": -12,
      "y": 0,
      "z": 7,
      "name": "Soil_Snow"
    },
    {
      "x": -12,
      "y": 0,
      "z": 8,
      "name": "Soil_Snow"
    },
    {
      "x": -12,
      "y": 0,
      "z": 9,
      "name": "Soil_Snow"
    },
    {
      "x": -12,
      "y": 0,
      "z": 10,
      "name": "Soil_Clay_Smooth_White"
    },
    {
      "x": -12,
      "y": 0,
      "z": 11,
      "name": "Soil_Clay_Smooth_White"
    },
    {
      "x": -12,
      "y": 0,
      "z": 12,
      "name": "Soil_Snow"
    },
    {
      "x": -12,
      "y": 0,
      "z": 13,
      "name": "Soil_Snow"
    },
    {
      "x": -12,
      "y": 0,
      "z": 14,
      "name": "Soil_Snow"
    },
    {
      "x": -12,
      "y": 0,
      "z": 15,
      "name": "Soil_Snow"
    },
    {
      "x": -12,
      "y": 0,
      "z": 16,
      "name": "Soil_Snow"
    },
    {
      "x": -12,
      "y": 0,
      "z": 17,
      "name": "Soil_Snow"
    },
    {
      "x": -12,
      "y": 0,
      "z": 18,
      "name": "Soil_Snow"
    },
    {
      "x": -12,
      "y": 0,
      "z": 19,
      "name": "Soil_Snow_Half"
    },
    {
      "x": -11,
      "y": 0,
      "z": -18,
      "name": "Soil_Snow_Half"
    },
    {
      "x": -11,
      "y": 0,
      "z": -17,
      "name": "Soil_Snow"
    },
    {
      "x": -11,
      "y": 0,
      "z": -16,
      "name": "Soil_Snow"
    },
    {
      "x": -11,
      "y": 0,
      "z": -15,
      "name": "Soil_Snow"
    },
    {
      "x": -11,
      "y": 0,
      "z": -14,
      "name": "Soil_Snow"
    },
    {
      "x": -11,
      "y": 1,
      "z": -14,
      "name": "Plant_Bush_Winter_Snow",
      "support": 15
    },
    {
      "x": -11,
      "y": 0,
      "z": -13,
      "name": "Soil_Snow"
    },
    {
      "x": -11,
      "y": 0,
      "z": -12,
      "name": "Soil_Snow"
    },
    {
      "x": -11,
      "y": 0,
      "z": -11,
      "name": "Soil_Snow"
    },
    {
      "x": -11,
      "y": 0,
      "z": -10,
      "name": "Soil_Snow"
    },
    {
      "x": -11,
      "y": 0,
      "z": -9,
      "name": "Soil_Snow"
    },
    {
      "x": -11,
      "y": 0,
      "z": -8,
      "name": "Soil_Snow"
    },
    {
      "x": -11,
      "y": 0,
      "z": -7,
      "name": "Soil_Snow"
    },
    {
      "x": -11,
      "y": 0,
      "z": -6,
      "name": "Soil_Snow"
    },
    {
      "x": -11,
      "y": 0,
      "z": -5,
      "name": "Soil_Snow"
    },
    {
      "x": -11,
      "y": 1,
      "z": -5,
      "name": "Rubble_Stone_Medium",
      "support": 15
    },
    {
      "x": -11,
      "y": 0,
      "z": -4,
      "name": "Soil_Clay_Smooth_White"
    },
    {
      "x": -11,
      "y": 0,
      "z": -3,
      "name": "Soil_Snow"
    },
    {
      "x": -11,
      "y": 0,
      "z": -2,
      "name": "Soil_Snow"
    },
    {
      "x": -11,
      "y": 0,
      "z": -1,
      "name": "Soil_Snow"
    },
    {
      "x": -11,
      "y": 0,
      "z": 0,
      "name": "Soil_Snow"
    },
    {
      "x": -11,
      "y": 0,
      "z": 1,
      "name": "Soil_Snow"
    },
    {
      "x": -11,
      "y": 0,
      "z": 2,
      "name": "Soil_Snow"
    },
    {
      "x": -11,
      "y": 0,
      "z": 3,
      "name": "Soil_Snow"
    },
    {
      "x": -11,
      "y": 0,
      "z": 4,
      "name": "Soil_Snow"
    },
    {
      "x": -11,
      "y": 0,
      "z": 5,
      "name": "Soil_Snow"
    },
    {
      "x": -11,
      "y": 0,
      "z": 6,
      "name": "Soil_Snow"
    },
    {
      "x": -11,
      "y": 0,
      "z": 7,
      "name": "Soil_Snow"
    },
    {
      "x": -11,
      "y": 0,
      "z": 8,
      "name": "Soil_Snow"
    },
    {
      "x": -11,
      "y": 0,
      "z": 9,
      "name": "Soil_Snow"
    },
    {
      "x": -11,
      "y": 0,
      "z": 10,
      "name": "Soil_Snow"
    },
    {
      "x": -11,
      "y": 0,
      "z": 11,
      "name": "Soil_Snow"
    },
    {
      "x": -11,
      "y": 0,
      "z": 12,
      "name": "Soil_Snow"
    },
    {
      "x": -11,
      "y": 0,
      "z": 13,
      "name": "Soil_Snow"
    },
    {
      "x": -11,
      "y": 1,
      "z": 13,
      "name": "Plant_Bush_Winter_Snow",
      "support": 15
    },
    {
      "x": -11,
      "y": 0,
      "z": 14,
      "name": "Soil_Snow"
    },
    {
      "x": -11,
      "y": 0,
      "z": 15,
      "name": "Soil_Snow"
    },
    {
      "x": -11,
      "y": 1,
      "z": 15,
      "name": "Plant_Bush_Winter_Snow",
      "support": 15
    },
    {
      "x": -11,
      "y": 0,
      "z": 16,
      "name": "Soil_Snow"
    },
    {
      "x": -11,
      "y": 0,
      "z": 17,
      "name": "Soil_Snow"
    },
    {
      "x": -11,
      "y": 1,
      "z": 17,
      "name": "Plant_Crop_Mana1"
    },
    {
      "x": -11,
      "y": 0,
      "z": 18,
      "name": "Soil_Snow"
    },
    {
      "x": -11,
      "y": 0,
      "z": 19,
      "name": "Soil_Snow_Half"
    },
    {
      "x": -10,
      "y": 0,
      "z": -19,
      "name": "Soil_Snow_Half"
    },
    {
      "x": -10,
      "y": 0,
      "z": -18,
      "name": "Soil_Snow"
    },
    {
      "x": -10,
      "y": 0,
      "z": -17,
      "name": "Soil_Snow"
    },
    {
      "x": -10,
      "y": 0,
      "z": -16,
      "name": "Soil_Snow"
    },
    {
      "x": -10,
      "y": 0,
      "z": -15,
      "name": "Soil_Snow"
    },
    {
      "x": -10,
      "y": 1,
      "z": -15,
      "name": "Plant_Bush_Winter_Snow",
      "support": 15
    },
    {
      "x": -10,
      "y": 0,
      "z": -14,
      "name": "Soil_Snow"
    },
    {
      "x": -10,
      "y": 1,
      "z": -14,
      "name": "Plant_Bush_Winter_Snow",
      "support": 15
    },
    {
      "x": -10,
      "y": 0,
      "z": -13,
      "name": "Soil_Snow"
    },
    {
      "x": -10,
      "y": 1,
      "z": -13,
      "name": "Plant_Bush_Winter_Snow",
      "support": 15
    },
    {
      "x": -10,
      "y": 0,
      "z": -12,
      "name": "Soil_Snow"
    },
    {
      "x": -10,
      "y": 0,
      "z": -11,
      "name": "Soil_Snow"
    },
    {
      "x": -10,
      "y": 0,
      "z": -10,
      "name": "Soil_Snow"
    },
    {
      "x": -10,
      "y": 0,
      "z": -9,
      "name": "Soil_Snow"
    },
    {
      "x": -10,
      "y": 0,
      "z": -8,
      "name": "Soil_Snow"
    },
    {
      "x": -10,
      "y": 0,
      "z": -7,
      "name": "Soil_Snow"
    },
    {
      "x": -10,
      "y": 0,
      "z": -6,
      "name": "Soil_Snow"
    },
    {
      "x": -10,
      "y": 0,
      "z": -5,
      "name": "Soil_Snow"
    },
    {
      "x": -10,
      "y": 0,
      "z": -4,
      "name": "Soil_Clay_Smooth_White"
    },
    {
      "x": -10,
      "y": 0,
      "z": -3,
      "name": "Soil_Clay_Smooth_White"
    },
    {
      "x": -10,
      "y": 0,
      "z": -2,
      "name": "Soil_Snow"
    },
    {
      "x": -10,
      "y": 0,
      "z": -1,
      "name": "Soil_Snow"
    },
    {
      "x": -10,
      "y": 0,
      "z": 0,
      "name": "Soil_Snow"
    },
    {
      "x": -10,
      "y": 0,
      "z": 1,
      "name": "Soil_Snow"
    },
    {
      "x": -10,
      "y": 0,
      "z": 2,
      "name": "Soil_Snow"
    },
    {
      "x": -10,
      "y": 0,
      "z": 3,
      "name": "Soil_Snow"
    },
    {
      "x": -10,
      "y": 0,
      "z": 4,
      "name": "Soil_Snow"
    },
    {
      "x": -10,
      "y": 0,
      "z": 5,
      "name": "Soil_Snow"
    },
    {
      "x": -10,
      "y": 1,
      "z": 5,
      "name": "Plant_Bush_Winter_Snow",
      "support": 15
    },
    {
      "x": -10,
      "y": 0,
      "z": 6,
      "name": "Soil_Snow"
    },
    {
      "x": -10,
      "y": 0,
      "z": 7,
      "name": "Soil_Snow"
    },
    {
      "x": -10,
      "y": 0,
      "z": 8,
      "name": "Soil_Snow"
    },
    {
      "x": -10,
      "y": 0,
      "z": 9,
      "name": "Soil_Snow"
    },
    {
      "x": -10,
      "y": 0,
      "z": 10,
      "name": "Soil_Snow"
    },
    {
      "x": -10,
      "y": 0,
      "z": 11,
      "name": "Soil_Snow"
    },
    {
      "x": -10,
      "y": 0,
      "z": 12,
      "name": "Soil_Snow"
    },
    {
      "x": -10,
      "y": 0,
      "z": 13,
      "name": "Soil_Snow"
    },
    {
      "x": -10,
      "y": 0,
      "z": 14,
      "name": "Soil_Snow"
    },
    {
      "x": -10,
      "y": 0,
      "z": 15,
      "name": "Soil_Snow"
    },
    {
      "x": -10,
      "y": 1,
      "z": 15,
      "name": "Plant_Bush_Winter_Snow",
      "support": 15
    },
    {
      "x": -10,
      "y": 0,
      "z": 16,
      "name": "Soil_Snow"
    },
    {
      "x": -10,
      "y": 1,
      "z": 16,
      "name": "Plant_Bush_Winter_Snow",
      "support": 15
    },
    {
      "x": -10,
      "y": 0,
      "z": 17,
      "name": "Soil_Snow"
    },
    {
      "x": -10,
      "y": 0,
      "z": 18,
      "name": "Soil_Snow"
    },
    {
      "x": -10,
      "y": 0,
      "z": 19,
      "name": "Soil_Snow"
    },
    {
      "x": -10,
      "y": 0,
      "z": 20,
      "name": "Soil_Snow_Half"
    },
    {
      "x": -9,
      "y": 0,
      "z": -20,
      "name": "Soil_Snow_Half"
    },
    {
      "x": -9,
      "y": 0,
      "z": -19,
      "name": "Soil_Snow"
    },
    {
      "x": -9,
      "y": 1,
      "z": -19,
      "name": "Plant_Bush_Winter_Sharp",
      "support": 15
    },
    {
      "x": -9,
      "y": 0,
      "z": -18,
      "name": "Soil_Snow"
    },
    {
      "x": -9,
      "y": 0,
      "z": -17,
      "name": "Soil_Snow"
    },
    {
      "x": -9,
      "y": 0,
      "z": -16,
      "name": "Soil_Snow"
    },
    {
      "x": -9,
      "y": 0,
      "z": -15,
      "name": "Soil_Snow"
    },
    {
      "x": -9,
      "y": 6,
      "z": -15,
      "name": "Wood_Darkwood_Planks_Half",
      "rotation": 8
    },
    {
      "x": -9,
      "y": 7,
      "z": -15,
      "name": "Wood_Darkwood_Roof",
      "rotation": 3
    },
    {
      "x": -9,
      "y": 0,
      "z": -14,
      "name": "Soil_Snow"
    },
    {
      "x": -9,
      "y": 1,
      "z": -14,
      "name": "Plant_Bush_Winter_Snow",
      "support": 15
    },
    {
      "x": -9,
      "y": 6,
      "z": -14,
      "name": "Wood_Darkwood_Planks_Half",
      "rotation": 8
    },
    {
      "x": -9,
      "y": 7,
      "z": -14,
      "name": "Wood_Darkwood_Roof",
      "rotation": 3
    },
    {
      "x": -9,
      "y": 0,
      "z": -13,
      "name": "Soil_Snow"
    },
    {
      "x": -9,
      "y": 1,
      "z": -13,
      "name": "Plant_Bush_Winter_Snow",
      "support": 15
    },
    {
      "x": -9,
      "y": 6,
      "z": -13,
      "name": "Wood_Darkwood_Planks_Half",
      "rotation": 8
    },
    {
      "x": -9,
      "y": 7,
      "z": -13,
      "name": "Wood_Darkwood_Roof",
      "rotation": 3
    },
    {
      "x": -9,
      "y": 0,
      "z": -12,
      "name": "Soil_Snow"
    },
    {
      "x": -9,
      "y": 1,
      "z": -12,
      "name": "Plant_Bush_Winter_Snow",
      "support": 15
    },
    {
      "x": -9,
      "y": 6,
      "z": -12,
      "name": "Wood_Darkwood_Planks_Half",
      "rotation": 8
    },
    {
      "x": -9,
      "y": 7,
      "z": -12,
      "name": "Wood_Darkwood_Roof",
      "rotation": 3
    },
    {
      "x": -9,
      "y": 0,
      "z": -11,
      "name": "Soil_Snow"
    },
    {
      "x": -9,
      "y": 6,
      "z": -11,
      "name": "Wood_Darkwood_Planks_Half",
      "rotation": 8
    },
    {
      "x": -9,
      "y": 7,
      "z": -11,
      "name": "Wood_Darkwood_Roof",
      "rotation": 3
    },
    {
      "x": -9,
      "y": 0,
      "z": -10,
      "name": "Soil_Snow"
    },
    {
      "x": -9,
      "y": 6,
      "z": -10,
      "name": "Wood_Darkwood_Planks_Half",
      "rotation": 8
    },
    {
      "x": -9,
      "y": 7,
      "z": -10,
      "name": "Wood_Darkwood_Roof",
      "rotation": 3
    },
    {
      "x": -9,
      "y": 0,
      "z": -9,
      "name": "Soil_Snow"
    },
    {
      "x": -9,
      "y": 1,
      "z": -9,
      "name": "Plant_Crop_Mana2"
    },
    {
      "x": -9,
      "y": 6,
      "z": -9,
      "name": "Wood_Darkwood_Planks_Half",
      "rotation": 8
    },
    {
      "x": -9,
      "y": 7,
      "z": -9,
      "name": "Wood_Darkwood_Roof",
      "rotation": 3
    },
    {
      "x": -9,
      "y": 0,
      "z": -8,
      "name": "Soil_Snow"
    },
    {
      "x": -9,
      "y": 6,
      "z": -8,
      "name": "Wood_Darkwood_Planks_Half",
      "rotation": 8
    },
    {
      "x": -9,
      "y": 7,
      "z": -8,
      "name": "Wood_Darkwood_Roof",
      "rotation": 3
    },
    {
      "x": -9,
      "y": 0,
      "z": -7,
      "name": "Soil_Clay_Smooth_White"
    },
    {
      "x": -9,
      "y": 6,
      "z": -7,
      "name": "Wood_Darkwood_Planks_Half",
      "rotation": 8
    },
    {
      "x": -9,
      "y": 7,
      "z": -7,
      "name": "Wood_Darkwood_Roof",
      "rotation": 3
    },
    {
      "x": -9,
      "y": 0,
      "z": -6,
      "name": "Soil_Clay_Smooth_White"
    },
    {
      "x": -9,
      "y": 6,
      "z": -6,
      "name": "Wood_Darkwood_Planks_Half",
      "rotation": 8
    },
    {
      "x": -9,
      "y": 7,
      "z": -6,
      "name": "Wood_Darkwood_Roof",
      "rotation": 3
    },
    {
      "x": -9,
      "y": 0,
      "z": -5,
      "name": "Soil_Snow"
    },
    {
      "x": -9,
      "y": 1,
      "z": -5,
      "name": "Wood_Redwood_Fence",
      "rotation": 2
    },
    {
      "x": -9,
      "y": 6,
      "z": -5,
      "name": "Wood_Darkwood_Planks_Half",
      "rotation": 8
    },
    {
      "x": -9,
      "y": 7,
      "z": -5,
      "name": "Wood_Darkwood_Roof",
      "rotation": 3
    },
    {
      "x": -9,
      "y": 0,
      "z": -4,
      "name": "Soil_Snow"
    },
    {
      "x": -9,
      "y": 1,
      "z": -4,
      "name": "Wood_Redwood_Fence",
      "rotation": 2
    },
    {
      "x": -9,
      "y": 6,
      "z": -4,
      "name": "Wood_Darkwood_Planks_Half",
      "rotation": 8
    },
    {
      "x": -9,
      "y": 7,
      "z": -4,
      "name": "Wood_Darkwood_Roof",
      "rotation": 3
    },
    {
      "x": -9,
      "y": 0,
      "z": -3,
      "name": "Soil_Clay_Smooth_White"
    },
    {
      "x": -9,
      "y": 6,
      "z": -3,
      "name": "Wood_Darkwood_Planks_Half",
      "rotation": 8
    },
    {
      "x": -9,
      "y": 7,
      "z": -3,
      "name": "Wood_Darkwood_Roof",
      "rotation": 3
    },
    {
      "x": -9,
      "y": 0,
      "z": -2,
      "name": "Soil_Snow"
    },
    {
      "x": -9,
      "y": 6,
      "z": -2,
      "name": "Wood_Darkwood_Planks_Half",
      "rotation": 8
    },
    {
      "x": -9,
      "y": 7,
      "z": -2,
      "name": "Wood_Darkwood_Roof",
      "rotation": 3
    },
    {
      "x": -9,
      "y": 0,
      "z": -1,
      "name": "Rock_Ice"
    },
    {
      "x": -9,
      "y": 6,
      "z": -1,
      "name": "Wood_Darkwood_Planks_Half",
      "rotation": 8
    },
    {
      "x": -9,
      "y": 7,
      "z": -1,
      "name": "Wood_Darkwood_Roof",
      "rotation": 3
    },
    {
      "x": -9,
      "y": 0,
      "z": 0,
      "name": "Soil_Snow"
    },
    {
      "x": -9,
      "y": 1,
      "z": 0,
      "name": "Plant_Bush_Winter_Sharp",
      "support": 15
    },
    {
      "x": -9,
      "y": 6,
      "z": 0,
      "name": "Wood_Darkwood_Planks_Half",
      "rotation": 8
    },
    {
      "x": -9,
      "y": 7,
      "z": 0,
      "name": "Wood_Darkwood_Roof",
      "rotation": 3
    },
    {
      "x": -9,
      "y": 0,
      "z": 1,
      "name": "Soil_Snow"
    },
    {
      "x": -9,
      "y": 6,
      "z": 1,
      "name": "Wood_Darkwood_Planks_Half",
      "rotation": 8
    },
    {
      "x": -9,
      "y": 7,
      "z": 1,
      "name": "Wood_Darkwood_Roof",
      "rotation": 3
    },
    {
      "x": -9,
      "y": 0,
      "z": 2,
      "name": "Soil_Snow"
    },
    {
      "x": -9,
      "y": 6,
      "z": 2,
      "name": "Wood_Darkwood_Planks_Half",
      "rotation": 8
    },
    {
      "x": -9,
      "y": 7,
      "z": 2,
      "name": "Wood_Darkwood_Roof",
      "rotation": 3
    },
    {
      "x": -9,
      "y": 0,
      "z": 3,
      "name": "Soil_Snow"
    },
    {
      "x": -9,
      "y": 6,
      "z": 3,
      "name": "Wood_Darkwood_Planks_Half",
      "rotation": 8
    },
    {
      "x": -9,
      "y": 7,
      "z": 3,
      "name": "Wood_Darkwood_Roof",
      "rotation": 3
    },
    {
      "x": -9,
      "y": 0,
      "z": 4,
      "name": "Soil_Snow"
    },
    {
      "x": -9,
      "y": 1,
      "z": 4,
      "name": "Plant_Bush_Winter_Snow",
      "support": 15
    },
    {
      "x": -9,
      "y": 6,
      "z": 4,
      "name": "Wood_Darkwood_Planks_Half",
      "rotation": 8
    },
    {
      "x": -9,
      "y": 7,
      "z": 4,
      "name": "Wood_Darkwood_Roof",
      "rotation": 3
    },
    {
      "x": -9,
      "y": 0,
      "z": 5,
      "name": "Soil_Snow"
    },
    {
      "x": -9,
      "y": 1,
      "z": 5,
      "name": "Plant_Bush_Winter_Snow",
      "support": 15
    },
    {
      "x": -9,
      "y": 6,
      "z": 5,
      "name": "Wood_Darkwood_Planks_Half",
      "rotation": 8
    },
    {
      "x": -9,
      "y": 7,
      "z": 5,
      "name": "Wood_Darkwood_Roof",
      "rotation": 3
    },
    {
      "x": -9,
      "y": 0,
      "z": 6,
      "name": "Soil_Snow"
    },
    {
      "x": -9,
      "y": 1,
      "z": 6,
      "name": "Plant_Bush_Winter_Snow",
      "support": 15
    },
    {
      "x": -9,
      "y": 6,
      "z": 6,
      "name": "Wood_Darkwood_Planks_Half",
      "rotation": 8
    },
    {
      "x": -9,
      "y": 7,
      "z": 6,
      "name": "Wood_Darkwood_Roof",
      "rotation": 3
    },
    {
      "x": -9,
      "y": 0,
      "z": 7,
      "name": "Soil_Snow"
    },
    {
      "x": -9,
      "y": 6,
      "z": 7,
      "name": "Wood_Darkwood_Planks_Half",
      "rotation": 8
    },
    {
      "x": -9,
      "y": 7,
      "z": 7,
      "name": "Wood_Darkwood_Roof",
      "rotation": 3
    },
    {
      "x": -9,
      "y": 0,
      "z": 8,
      "name": "Soil_Snow"
    },
    {
      "x": -9,
      "y": 6,
      "z": 8,
      "name": "Wood_Darkwood_Planks_Half",
      "rotation": 8
    },
    {
      "x": -9,
      "y": 7,
      "z": 8,
      "name": "Wood_Darkwood_Roof",
      "rotation": 3
    },
    {
      "x": -9,
      "y": 0,
      "z": 9,
      "name": "Soil_Snow"
    },
    {
      "x": -9,
      "y": 1,
      "z": 9,
      "name": "Plant_Bush_Lush",
      "support": 15
    },
    {
      "x": -9,
      "y": 6,
      "z": 9,
      "name": "Wood_Darkwood_Planks_Half",
      "rotation": 8
    },
    {
      "x": -9,
      "y": 7,
      "z": 9,
      "name": "Wood_Darkwood_Roof",
      "rotation": 3
    },
    {
      "x": -9,
      "y": 0,
      "z": 10,
      "name": "Soil_Snow"
    },
    {
      "x": -9,
      "y": 1,
      "z": 10,
      "name": "Plant_Bush_Lush",
      "support": 15
    },
    {
      "x": -9,
      "y": 0,
      "z": 11,
      "name": "Soil_Snow"
    },
    {
      "x": -9,
      "y": 0,
      "z": 12,
      "name": "Soil_Snow"
    },
    {
      "x": -9,
      "y": 0,
      "z": 13,
      "name": "Soil_Snow"
    },
    {
      "x": -9,
      "y": 0,
      "z": 14,
      "name": "Soil_Snow"
    },
    {
      "x": -9,
      "y": 1,
      "z": 14,
      "name": "Plant_Bush_Winter_Snow",
      "support": 15
    },
    {
      "x": -9,
      "y": 0,
      "z": 15,
      "name": "Soil_Snow"
    },
    {
      "x": -9,
      "y": 1,
      "z": 15,
      "name": "Plant_Bush_Winter_Snow",
      "support": 15
    },
    {
      "x": -9,
      "y": 0,
      "z": 16,
      "name": "Soil_Snow"
    },
    {
      "x": -9,
      "y": 0,
      "z": 17,
      "name": "Soil_Snow"
    },
    {
      "x": -9,
      "y": 0,
      "z": 18,
      "name": "Soil_Snow"
    },
    {
      "x": -9,
      "y": 0,
      "z": 19,
      "name": "Soil_Snow"
    },
    {
      "x": -9,
      "y": 0,
      "z": 20,
      "name": "Soil_Snow"
    },
    {
      "x": -9,
      "y": 1,
      "z": 20,
      "name": "Plant_Bush_Winter_Sharp",
      "support": 15
    },
    {
      "x": -9,
      "y": 0,
      "z": 21,
      "name": "Soil_Snow_Half"
    },
    {
      "x": -8,
      "y": 0,
      "z": -21,
      "name": "Soil_Snow_Half"
    },
    {
      "x": -8,
      "y": 0,
      "z": -20,
      "name": "Soil_Snow"
    },
    {
      "x": -8,
      "y": 0,
      "z": -19,
      "name": "Soil_Snow"
    },
    {
      "x": -8,
      "y": 0,
      "z": -18,
      "name": "Soil_Snow"
    },
    {
      "x": -8,
      "y": 0,
      "z": -17,
      "name": "Soil_Clay_Smooth_White"
    },
    {
      "x": -8,
      "y": 0,
      "z": -16,
      "name": "Soil_Snow"
    },
    {
      "x": -8,
      "y": 0,
      "z": -15,
      "name": "Soil_Snow"
    },
    {
      "x": -8,
      "y": 1,
      "z": -15,
      "name": "Plant_Bush_Lush",
      "support": 15
    },
    {
      "x": -8,
      "y": 7,
      "z": -15,
      "name": "Wood_Darkwood_Stairs",
      "rotation": 11
    },
    {
      "x": -8,
      "y": 8,
      "z": -15,
      "name": "Wood_Darkwood_Roof",
      "rotation": 3
    },
    {
      "x": -8,
      "y": 0,
      "z": -14,
      "name": "Soil_Snow"
    },
    {
      "x": -8,
      "y": 1,
      "z": -14,
      "name": "Wood_Ash_Trunk_Full",
      "support": 15
    },
    {
      "x": -8,
      "y": 2,
      "z": -14,
      "name": "Wood_Ash_Trunk_Full",
      "support": 15
    },
    {
      "x": -8,
      "y": 3,
      "z": -14,
      "name": "Wood_Ash_Trunk_Full",
      "support": 15
    },
    {
      "x": -8,
      "y": 4,
      "z": -14,
      "name": "Wood_Ash_Trunk_Full",
      "support": 15
    },
    {
      "x": -8,
      "y": 5,
      "z": -14,
      "name": "Wood_Ash_Trunk_Full",
      "support": 15
    },
    {
      "x": -8,
      "y": 6,
      "z": -14,
      "name": "Wood_Ash_Trunk_Full",
      "support": 15
    },
    {
      "x": -8,
      "y": 7,
      "z": -14,
      "name": "Wood_Ash_Trunk_Full",
      "support": 15
    },
    {
      "x": -8,
      "y": 8,
      "z": -14,
      "name": "Wood_Darkwood_Roof",
      "rotation": 3
    },
    {
      "x": -8,
      "y": 0,
      "z": -13,
      "name": "Soil_Snow"
    },
    {
      "x": -8,
      "y": 1,
      "z": -13,
      "name": "Rock_Volcanic_Cobble"
    },
    {
      "x": -8,
      "y": 2,
      "z": -13,
      "name": "Rock_Volcanic_Cobble_Stairs",
      "rotation": 3
    },
    {
      "x": -8,
      "y": 3,
      "z": -13,
      "name": "Wood_Ash_Trunk_Full",
      "support": 15,
      "rotation": 4
    },
    {
      "x": -8,
      "y": 4,
      "z": -13,
      "name": "Wood_Ash_Trunk_Full",
      "support": 15,
      "rotation": 4
    },
    {
      "x": -8,
      "y": 5,
      "z": -13,
      "name": "Wood_Ash_Trunk_Full",
      "support": 15,
      "rotation": 4
    },
    {
      "x": -8,
      "y": 6,
      "z": -13,
      "name": "Wood_Ash_Trunk_Full",
      "support": 15,
      "rotation": 4
    },
    {
      "x": -8,
      "y": 7,
      "z": -13,
      "name": "Wood_Darkwood_Planks"
    },
    {
      "x": -8,
      "y": 8,
      "z": -13,
      "name": "Wood_Darkwood_Roof",
      "rotation": 3
    },
    {
      "x": -8,
      "y": 0,
      "z": -12,
      "name": "Soil_Snow"
    },
    {
      "x": -8,
      "y": 1,
      "z": -12,
      "name": "Rock_Volcanic_Cobble"
    },
    {
      "x": -8,
      "y": 2,
      "z": -12,
      "name": "Rock_Volcanic_Cobble"
    },
    {
      "x": -8,
      "y": 3,
      "z": -12,
      "name": "Wood_Ash_Trunk_Full",
      "support": 15,
      "rotation": 4
    },
    {
      "x": -8,
      "y": 4,
      "z": -12,
      "name": "Wood_Ash_Trunk_Full",
      "support": 15,
      "rotation": 4
    },
    {
      "x": -8,
      "y": 5,
      "z": -12,
      "name": "Wood_Ash_Trunk_Full",
      "support": 15,
      "rotation": 4
    },
    {
      "x": -8,
      "y": 6,
      "z": -12,
      "name": "Wood_Ash_Trunk_Full",
      "support": 15,
      "rotation": 4
    },
    {
      "x": -8,
      "y": 7,
      "z": -12,
      "name": "Wood_Darkwood_Planks"
    },
    {
      "x": -8,
      "y": 8,
      "z": -12,
      "name": "Wood_Darkwood_Roof",
      "rotation": 3
    },
    {
      "x": -8,
      "y": 0,
      "z": -11,
      "name": "Soil_Snow"
    },
    {
      "x": -8,
      "y": 1,
      "z": -11,
      "name": "Rock_Volcanic_Cobble"
    },
    {
      "x": -8,
      "y": 2,
      "z": -11,
      "name": "Rock_Volcanic_Cobble"
    },
    {
      "x": -8,
      "y": 3,
      "z": -11,
      "name": "Wood_Ash_Trunk_Full",
      "support": 15,
      "rotation": 4
    },
    {
      "x": -8,
      "y": 4,
      "z": -11,
      "name": "Wood_Ash_Trunk_Full",
      "support": 15,
      "rotation": 4
    },
    {
      "x": -8,
      "y": 5,
      "z": -11,
      "name": "Wood_Ash_Trunk_Full",
      "support": 15,
      "rotation": 4
    },
    {
      "x": -8,
      "y": 6,
      "z": -11,
      "name": "Wood_Ash_Trunk_Full",
      "support": 15,
      "rotation": 4
    },
    {
      "x": -8,
      "y": 7,
      "z": -11,
      "name": "Wood_Darkwood_Planks"
    },
    {
      "x": -8,
      "y": 8,
      "z": -11,
      "name": "Wood_Darkwood_Roof",
      "rotation": 3
    },
    {
      "x": -8,
      "y": 0,
      "z": -10,
      "name": "Soil_Snow"
    },
    {
      "x": -8,
      "y": 1,
      "z": -10,
      "name": "Rock_Volcanic_Cobble"
    },
    {
      "x": -8,
      "y": 2,
      "z": -10,
      "name": "Rock_Volcanic_Cobble_Stairs",
      "rotation": 9
    },
    {
      "x": -8,
      "y": 3,
      "z": -10,
      "name": "Wood_Ash_Trunk_Full",
      "support": 15,
      "rotation": 4
    },
    {
      "x": -8,
      "y": 4,
      "z": -10,
      "name": "Furniture_Tavern_Window",
      "rotation": 1
    },
    {
      "x": -8,
      "y": 5,
      "z": -10,
      "name": "Furniture_Tavern_Window",
      "rotation": 1
    },
    {
      "x": -8,
      "y": 6,
      "z": -10,
      "name": "Wood_Ash_Trunk_Full",
      "support": 15,
      "rotation": 4
    },
    {
      "x": -8,
      "y": 7,
      "z": -10,
      "name": "Wood_Darkwood_Planks"
    },
    {
      "x": -8,
      "y": 8,
      "z": -10,
      "name": "Wood_Darkwood_Roof",
      "rotation": 3
    },
    {
      "x": -8,
      "y": 0,
      "z": -9,
      "name": "Soil_Snow"
    },
    {
      "x": -8,
      "y": 1,
      "z": -9,
      "name": "Rock_Volcanic_Cobble"
    },
    {
      "x": -8,
      "y": 2,
      "z": -9,
      "name": "Rock_Volcanic_Cobble"
    },
    {
      "x": -8,
      "y": 3,
      "z": -9,
      "name": "Wood_Ash_Trunk_Full",
      "support": 15,
      "rotation": 4
    },
    {
      "x": -8,
      "y": 4,
      "z": -9,
      "name": "Furniture_Tavern_Window",
      "rotation": 1
    },
    {
      "x": -8,
      "y": 5,
      "z": -9,
      "name": "Furniture_Tavern_Window",
      "rotation": 1
    },
    {
      "x": -8,
      "y": 6,
      "z": -9,
      "name": "Wood_Ash_Trunk_Full",
      "support": 15,
      "rotation": 4
    },
    {
      "x": -8,
      "y": 7,
      "z": -9,
      "name": "Wood_Darkwood_Planks"
    },
    {
      "x": -8,
      "y": 8,
      "z": -9,
      "name": "Wood_Darkwood_Roof",
      "rotation": 3
    },
    {
      "x": -8,
      "y": 0,
      "z": -8,
      "name": "Rock_Volcanic_Cobble"
    },
    {
      "x": -8,
      "y": 1,
      "z": -8,
      "name": "Furniture_Temple_Dark_Window",
      "rotation": 1
    },
    {
      "x": -8,
      "y": 2,
      "z": -8,
      "name": "Rock_Volcanic_Cobble"
    },
    {
      "x": -8,
      "y": 3,
      "z": -8,
      "name": "Wood_Ash_Trunk_Full",
      "support": 15,
      "rotation": 4
    },
    {
      "x": -8,
      "y": 4,
      "z": -8,
      "name": "Furniture_Tavern_Window",
      "rotation": 1
    },
    {
      "x": -8,
      "y": 5,
      "z": -8,
      "name": "Furniture_Tavern_Window",
      "rotation": 1
    },
    {
      "x": -8,
      "y": 6,
      "z": -8,
      "name": "Wood_Ash_Trunk_Full",
      "support": 15,
      "rotation": 4
    },
    {
      "x": -8,
      "y": 7,
      "z": -8,
      "name": "Wood_Darkwood_Planks"
    },
    {
      "x": -8,
      "y": 8,
      "z": -8,
      "name": "Wood_Darkwood_Roof",
      "rotation": 3
    },
    {
      "x": -8,
      "y": 0,
      "z": -7,
      "name": "Rock_Volcanic_Cobble"
    },
    {
      "x": -8,
      "y": 1,
      "z": -7,
      "name": "Furniture_Temple_Dark_Window",
      "rotation": 1
    },
    {
      "x": -8,
      "y": 2,
      "z": -7,
      "name": "Rock_Volcanic_Cobble"
    },
    {
      "x": -8,
      "y": 3,
      "z": -7,
      "name": "Wood_Ash_Trunk_Full",
      "support": 15,
      "rotation": 4
    },
    {
      "x": -8,
      "y": 4,
      "z": -7,
      "name": "Furniture_Tavern_Window",
      "rotation": 1
    },
    {
      "x": -8,
      "y": 5,
      "z": -7,
      "name": "Furniture_Tavern_Window",
      "rotation": 1
    },
    {
      "x": -8,
      "y": 6,
      "z": -7,
      "name": "Wood_Ash_Trunk_Full",
      "support": 15,
      "rotation": 4
    },
    {
      "x": -8,
      "y": 7,
      "z": -7,
      "name": "Wood_Darkwood_Planks"
    },
    {
      "x": -8,
      "y": 8,
      "z": -7,
      "name": "Wood_Darkwood_Roof",
      "rotation": 3
    },
    {
      "x": -8,
      "y": 0,
      "z": -6,
      "name": "Soil_Snow"
    },
    {
      "x": -8,
      "y": 1,
      "z": -6,
      "name": "Rock_Volcanic_Cobble_Stairs"
    },
    {
      "x": -8,
      "y": 2,
      "z": -6,
      "name": "Rock_Volcanic_Cobble"
    },
    {
      "x": -8,
      "y": 3,
      "z": -6,
      "name": "Wood_Ash_Trunk_Full",
      "support": 15,
      "rotation": 4
    },
    {
      "x": -8,
      "y": 4,
      "z": -6,
      "name": "Wood_Ash_Trunk_Full",
      "support": 15,
      "rotation": 4
    },
    {
      "x": -8,
      "y": 5,
      "z": -6,
      "name": "Wood_Ash_Trunk_Full",
      "support": 15,
      "rotation": 4
    },
    {
      "x": -8,
      "y": 6,
      "z": -6,
      "name": "Wood_Ash_Trunk_Full",
      "support": 15,
      "rotation": 4
    },
    {
      "x": -8,
      "y": 7,
      "z": -6,
      "name": "Wood_Darkwood_Planks"
    },
    {
      "x": -8,
      "y": 8,
      "z": -6,
      "name": "Wood_Darkwood_Roof",
      "rotation": 3
    },
    {
      "x": -8,
      "y": 0,
      "z": -5,
      "name": "Soil_Snow"
    },
    {
      "x": -8,
      "y": 1,
      "z": -5,
      "name": "Rock_Volcanic_Cobble"
    },
    {
      "x": -8,
      "y": 2,
      "z": -5,
      "name": "Rock_Volcanic_Cobble"
    },
    {
      "x": -8,
      "y": 3,
      "z": -5,
      "name": "Wood_Ash_Trunk_Full",
      "support": 15,
      "rotation": 4
    },
    {
      "x": -8,
      "y": 4,
      "z": -5,
      "name": "Wood_Ash_Trunk_Full",
      "support": 15,
      "rotation": 4
    },
    {
      "x": -8,
      "y": 5,
      "z": -5,
      "name": "Wood_Ash_Trunk_Full",
      "support": 15,
      "rotation": 4
    },
    {
      "x": -8,
      "y": 6,
      "z": -5,
      "name": "Wood_Ash_Trunk_Full",
      "support": 15,
      "rotation": 4
    },
    {
      "x": -8,
      "y": 7,
      "z": -5,
      "name": "Wood_Darkwood_Planks"
    },
    {
      "x": -8,
      "y": 8,
      "z": -5,
      "name": "Wood_Darkwood_Roof",
      "rotation": 3
    },
    {
      "x": -8,
      "y": 0,
      "z": -4,
      "name": "Soil_Snow"
    },
    {
      "x": -8,
      "y": 1,
      "z": -4,
      "name": "Wood_Ash_Trunk_Full",
      "support": 15
    },
    {
      "x": -8,
      "y": 2,
      "z": -4,
      "name": "Wood_Ash_Trunk_Full",
      "support": 15
    },
    {
      "x": -8,
      "y": 3,
      "z": -4,
      "name": "Wood_Ash_Trunk_Full",
      "support": 15
    },
    {
      "x": -8,
      "y": 4,
      "z": -4,
      "name": "Wood_Ash_Trunk_Full",
      "support": 15
    },
    {
      "x": -8,
      "y": 5,
      "z": -4,
      "name": "Wood_Ash_Trunk_Full",
      "support": 15
    },
    {
      "x": -8,
      "y": 6,
      "z": -4,
      "name": "Wood_Ash_Trunk_Full",
      "support": 15
    },
    {
      "x": -8,
      "y": 7,
      "z": -4,
      "name": "Wood_Ash_Trunk_Full",
      "support": 15
    },
    {
      "x": -8,
      "y": 8,
      "z": -4,
      "name": "Wood_Darkwood_Roof",
      "rotation": 3
    },
    {
      "x": -8,
      "y": 0,
      "z": -3,
      "name": "Soil_Snow"
    },
    {
      "x": -8,
      "y": 1,
      "z": -3,
      "name": "Wood_Fir_Trunk_Full",
      "support": 15
    },
    {
      "x": -8,
      "y": 2,
      "z": -3,
      "name": "Wood_Fir_Trunk_Full",
      "support": 15
    },
    {
      "x": -8,
      "y": 3,
      "z": -3,
      "name": "Wood_Darkwood_Fence",
      "rotation": 3
    },
    {
      "x": -8,
      "y": 4,
      "z": -3,
      "name": "Wood_Darkwood_Beam"
    },
    {
      "x": -8,
      "y": 5,
      "z": -3,
      "name": "Wood_Darkwood_Beam"
    },
    {
      "x": -8,
      "y": 6,
      "z": -3,
      "name": "Wood_Darkwood_Beam"
    },
    {
      "x": -8,
      "y": 7,
      "z": -3,
      "name": "Wood_Darkwood_Stairs",
      "rotation": 11
    },
    {
      "x": -8,
      "y": 8,
      "z": -3,
      "name": "Wood_Darkwood_Roof",
      "rotation": 3
    },
    {
      "x": -8,
      "y": 0,
      "z": -2,
      "name": "Soil_Snow"
    },
    {
      "x": -8,
      "y": 1,
      "z": -2,
      "name": "Wood_Darkwood_Decorative"
    },
    {
      "x": -8,
      "y": 2,
      "z": -2,
      "name": "Wood_Darkwood_Planks"
    },
    {
      "x": -8,
      "y": 3,
      "z": -2,
      "name": "Wood_Darkwood_Fence",
      "rotation": 3
    },
    {
      "x": -8,
      "y": 8,
      "z": -2,
      "name": "Wood_Darkwood_Roof_Hollow",
      "rotation": 3
    },
    {
      "x": -8,
      "y": 0,
      "z": -1,
      "name": "Soil_Snow"
    },
    {
      "x": -8,
      "y": 1,
      "z": -1,
      "name": "Wood_Darkwood_Decorative"
    },
    {
      "x": -8,
      "y": 2,
      "z": -1,
      "name": "Wood_Darkwood_Planks"
    },
    {
      "x": -8,
      "y": 3,
      "z": -1,
      "name": "Wood_Darkwood_Fence",
      "rotation": 3
    },
    {
      "x": -8,
      "y": 8,
      "z": -1,
      "name": "Wood_Darkwood_Roof_Hollow",
      "rotation": 3
    },
    {
      "x": -8,
      "y": 0,
      "z": 0,
      "name": "Soil_Snow"
    },
    {
      "x": -8,
      "y": 1,
      "z": 0,
      "name": "Wood_Darkwood_Decorative"
    },
    {
      "x": -8,
      "y": 2,
      "z": 0,
      "name": "Wood_Darkwood_Planks"
    },
    {
      "x": -8,
      "y": 3,
      "z": 0,
      "name": "Wood_Darkwood_Fence",
      "rotation": 3
    },
    {
      "x": -8,
      "y": 8,
      "z": 0,
      "name": "Wood_Darkwood_Roof_Hollow",
      "rotation": 3
    },
    {
      "x": -8,
      "y": 0,
      "z": 1,
      "name": "Soil_Snow"
    },
    {
      "x": -8,
      "y": 1,
      "z": 1,
      "name": "Wood_Darkwood_Decorative"
    },
    {
      "x": -8,
      "y": 2,
      "z": 1,
      "name": "Wood_Darkwood_Planks"
    },
    {
      "x": -8,
      "y": 3,
      "z": 1,
      "name": "Wood_Darkwood_Fence",
      "rotation": 3
    },
    {
      "x": -8,
      "y": 8,
      "z": 1,
      "name": "Wood_Darkwood_Roof_Hollow",
      "rotation": 3
    },
    {
      "x": -8,
      "y": 0,
      "z": 2,
      "name": "Soil_Snow"
    },
    {
      "x": -8,
      "y": 1,
      "z": 2,
      "name": "Wood_Darkwood_Decorative"
    },
    {
      "x": -8,
      "y": 2,
      "z": 2,
      "name": "Wood_Darkwood_Planks"
    },
    {
      "x": -8,
      "y": 3,
      "z": 2,
      "name": "Wood_Darkwood_Fence",
      "rotation": 3
    },
    {
      "x": -8,
      "y": 8,
      "z": 2,
      "name": "Wood_Darkwood_Roof_Hollow",
      "rotation": 3
    },
    {
      "x": -8,
      "y": 0,
      "z": 3,
      "name": "Soil_Snow"
    },
    {
      "x": -8,
      "y": 1,
      "z": 3,
      "name": "Wood_Darkwood_Decorative"
    },
    {
      "x": -8,
      "y": 2,
      "z": 3,
      "name": "Wood_Darkwood_Planks"
    },
    {
      "x": -8,
      "y": 3,
      "z": 3,
      "name": "Wood_Darkwood_Fence",
      "rotation": 3
    },
    {
      "x": -8,
      "y": 8,
      "z": 3,
      "name": "Wood_Darkwood_Roof_Hollow",
      "rotation": 3
    },
    {
      "x": -8,
      "y": 0,
      "z": 4,
      "name": "Soil_Snow"
    },
    {
      "x": -8,
      "y": 1,
      "z": 4,
      "name": "Wood_Darkwood_Decorative"
    },
    {
      "x": -8,
      "y": 2,
      "z": 4,
      "name": "Wood_Darkwood_Planks"
    },
    {
      "x": -8,
      "y": 3,
      "z": 4,
      "name": "Wood_Darkwood_Fence",
      "rotation": 3
    },
    {
      "x": -8,
      "y": 8,
      "z": 4,
      "name": "Wood_Darkwood_Roof_Hollow",
      "rotation": 3
    },
    {
      "x": -8,
      "y": 0,
      "z": 5,
      "name": "Soil_Snow"
    },
    {
      "x": -8,
      "y": 1,
      "z": 5,
      "name": "Wood_Darkwood_Decorative"
    },
    {
      "x": -8,
      "y": 2,
      "z": 5,
      "name": "Wood_Darkwood_Planks"
    },
    {
      "x": -8,
      "y": 3,
      "z": 5,
      "name": "Wood_Darkwood_Fence",
      "rotation": 3
    },
    {
      "x": -8,
      "y": 8,
      "z": 5,
      "name": "Wood_Darkwood_Roof_Hollow",
      "rotation": 3
    },
    {
      "x": -8,
      "y": 0,
      "z": 6,
      "name": "Soil_Snow"
    },
    {
      "x": -8,
      "y": 1,
      "z": 6,
      "name": "Wood_Darkwood_Decorative"
    },
    {
      "x": -8,
      "y": 2,
      "z": 6,
      "name": "Wood_Darkwood_Planks"
    },
    {
      "x": -8,
      "y": 3,
      "z": 6,
      "name": "Wood_Darkwood_Fence",
      "rotation": 3
    },
    {
      "x": -8,
      "y": 8,
      "z": 6,
      "name": "Wood_Darkwood_Roof_Hollow",
      "rotation": 3
    },
    {
      "x": -8,
      "y": 0,
      "z": 7,
      "name": "Soil_Snow"
    },
    {
      "x": -8,
      "y": 1,
      "z": 7,
      "name": "Wood_Darkwood_Decorative"
    },
    {
      "x": -8,
      "y": 2,
      "z": 7,
      "name": "Wood_Darkwood_Planks"
    },
    {
      "x": -8,
      "y": 3,
      "z": 7,
      "name": "Wood_Darkwood_Fence",
      "rotation": 3
    },
    {
      "x": -8,
      "y": 8,
      "z": 7,
      "name": "Wood_Darkwood_Roof_Hollow",
      "rotation": 3
    },
    {
      "x": -8,
      "y": 0,
      "z": 8,
      "name": "Soil_Snow"
    },
    {
      "x": -8,
      "y": 1,
      "z": 8,
      "name": "Wood_Darkwood_Decorative"
    },
    {
      "x": -8,
      "y": 2,
      "z": 8,
      "name": "Wood_Darkwood_Planks"
    },
    {
      "x": -8,
      "y": 3,
      "z": 8,
      "name": "Wood_Darkwood_Fence",
      "rotation": 3
    },
    {
      "x": -8,
      "y": 8,
      "z": 8,
      "name": "Wood_Darkwood_Roof_Hollow",
      "rotation": 3
    },
    {
      "x": -8,
      "y": 0,
      "z": 9,
      "name": "Soil_Snow"
    },
    {
      "x": -8,
      "y": 1,
      "z": 9,
      "name": "Wood_Fir_Trunk_Full",
      "support": 15
    },
    {
      "x": -8,
      "y": 2,
      "z": 9,
      "name": "Wood_Fir_Trunk_Full",
      "support": 15
    },
    {
      "x": -8,
      "y": 3,
      "z": 9,
      "name": "*Wood_Darkwood_Fence_State_Definitions_Corner",
      "rotation": 2
    },
    {
      "x": -8,
      "y": 4,
      "z": 9,
      "name": "Wood_Darkwood_Beam"
    },
    {
      "x": -8,
      "y": 5,
      "z": 9,
      "name": "Wood_Darkwood_Beam"
    },
    {
      "x": -8,
      "y": 6,
      "z": 9,
      "name": "Wood_Darkwood_Beam"
    },
    {
      "x": -8,
      "y": 7,
      "z": 9,
      "name": "Wood_Darkwood_Stairs",
      "rotation": 11
    },
    {
      "x": -8,
      "y": 8,
      "z": 9,
      "name": "Wood_Darkwood_Roof",
      "rotation": 3
    },
    {
      "x": -8,
      "y": 0,
      "z": 10,
      "name": "Soil_Snow"
    },
    {
      "x": -8,
      "y": 1,
      "z": 10,
      "name": "Plant_Bush_Lush",
      "support": 15
    },
    {
      "x": -8,
      "y": 0,
      "z": 11,
      "name": "Soil_Snow"
    },
    {
      "x": -8,
      "y": 0,
      "z": 12,
      "name": "Soil_Snow"
    },
    {
      "x": -8,
      "y": 0,
      "z": 13,
      "name": "Soil_Snow"
    },
    {
      "x": -8,
      "y": 0,
      "z": 14,
      "name": "Soil_Snow"
    },
    {
      "x": -8,
      "y": 0,
      "z": 15,
      "name": "Soil_Snow"
    },
    {
      "x": -8,
      "y": 0,
      "z": 16,
      "name": "Soil_Snow"
    },
    {
      "x": -8,
      "y": 0,
      "z": 17,
      "name": "Soil_Clay_Smooth_White"
    },
    {
      "x": -8,
      "y": 0,
      "z": 18,
      "name": "Soil_Clay_Smooth_White"
    },
    {
      "x": -8,
      "y": 3,
      "z": 18,
      "name": "Plant_Leaves_Fir",
      "support": 15,
      "rotation": 3
    },
    {
      "x": -8,
      "y": 0,
      "z": 19,
      "name": "Soil_Snow"
    },
    {
      "x": -8,
      "y": 0,
      "z": 20,
      "name": "Soil_Snow"
    },
    {
      "x": -8,
      "y": 0,
      "z": 21,
      "name": "Soil_Snow_Half"
    },
    {
      "x": -7,
      "y": 0,
      "z": -22,
      "name": "Soil_Snow_Half"
    },
    {
      "x": -7,
      "y": 0,
      "z": -21,
      "name": "Soil_Snow"
    },
    {
      "x": -7,
      "y": 0,
      "z": -20,
      "name": "Soil_Snow"
    },
    {
      "x": -7,
      "y": 0,
      "z": -19,
      "name": "Soil_Snow"
    },
    {
      "x": -7,
      "y": 0,
      "z": -18,
      "name": "Soil_Clay_Smooth_White"
    },
    {
      "x": -7,
      "y": 0,
      "z": -17,
      "name": "Soil_Snow"
    },
    {
      "x": -7,
      "y": 0,
      "z": -16,
      "name": "Soil_Snow"
    },
    {
      "x": -7,
      "y": 1,
      "z": -16,
      "name": "Plant_Bush_Lush",
      "support": 15
    },
    {
      "x": -7,
      "y": 0,
      "z": -15,
      "name": "Soil_Snow"
    },
    {
      "x": -7,
      "y": 1,
      "z": -15,
      "name": "Plant_Crop_Mana2"
    },
    {
      "x": -7,
      "y": 8,
      "z": -15,
      "name": "Wood_Darkwood_Stairs",
      "rotation": 11
    },
    {
      "x": -7,
      "y": 9,
      "z": -15,
      "name": "Wood_Darkwood_Roof",
      "rotation": 3
    },
    {
      "x": -7,
      "y": 0,
      "z": -14,
      "name": "Soil_Snow"
    },
    {
      "x": -7,
      "y": 1,
      "z": -14,
      "name": "Rock_Volcanic_Cobble"
    },
    {
      "x": -7,
      "y": 2,
      "z": -14,
      "name": "Rock_Volcanic_Cobble"
    },
    {
      "x": -7,
      "y": 3,
      "z": -14,
      "name": "Wood_Ash_Trunk_Full",
      "support": 15,
      "rotation": 5
    },
    {
      "x": -7,
      "y": 4,
      "z": -14,
      "name": "Wood_Ash_Trunk_Full",
      "support": 15,
      "rotation": 5
    },
    {
      "x": -7,
      "y": 5,
      "z": -14,
      "name": "Wood_Ash_Trunk_Full",
      "support": 15,
      "rotation": 5
    },
    {
      "x": -7,
      "y": 6,
      "z": -14,
      "name": "Wood_Ash_Trunk_Full",
      "support": 15,
      "rotation": 5
    },
    {
      "x": -7,
      "y": 7,
      "z": -14,
      "name": "Wood_Darkwood_Planks"
    },
    {
      "x": -7,
      "y": 8,
      "z": -14,
      "name": "Wood_Darkwood_Planks"
    },
    {
      "x": -7,
      "y": 9,
      "z": -14,
      "name": "Wood_Darkwood_Roof",
      "rotation": 3
    },
    {
      "x": -7,
      "y": 0,
      "z": -13,
      "name": "Soil_Snow"
    },
    {
      "x": -7,
      "y": 2,
      "z": -13,
      "name": "Rock_Stone_Brick"
    },
    {
      "x": -7,
      "y": 3,
      "z": -13,
      "name": "Furniture_Tavern_Barrel"
    },
    {
      "x": -7,
      "y": 4,
      "z": -13,
      "name": "Furniture_Tavern_Platform",
      "rotation": 1
    },
    {
      "x": -7,
      "y": 9,
      "z": -13,
      "name": "Wood_Darkwood_Roof_Hollow",
      "rotation": 3
    },
    {
      "x": -7,
      "y": 0,
      "z": -12,
      "name": "Soil_Snow"
    },
    {
      "x": -7,
      "y": 2,
      "z": -12,
      "name": "Rock_Stone_Brick"
    },
    {
      "x": -7,
      "y": 3,
      "z": -12,
      "name": "Furniture_Tavern_Barrel"
    },
    {
      "x": -7,
      "y": 4,
      "z": -12,
      "name": "Furniture_Tavern_Platform",
      "rotation": 1
    },
    {
      "x": -7,
      "y": 7,
      "z": -12,
      "name": "Furniture_Tavern_Shelf",
      "rotation": 1
    },
    {
      "x": -7,
      "y": 8,
      "z": -12,
      "name": "Deco_Nest"
    },
    {
      "x": -7,
      "y": 9,
      "z": -12,
      "name": "Wood_Darkwood_Roof_Hollow",
      "rotation": 3
    },
    {
      "x": -7,
      "y": 0,
      "z": -11,
      "name": "Soil_Snow"
    },
    {
      "x": -7,
      "y": 2,
      "z": -11,
      "name": "Rock_Stone_Brick"
    },
    {
      "x": -7,
      "y": 4,
      "z": -11,
      "name": "Furniture_Tavern_Platform",
      "rotation": 1
    },
    {
      "x": -7,
      "y": 9,
      "z": -11,
      "name": "Wood_Darkwood_Roof_Hollow",
      "rotation": 3
    },
    {
      "x": -7,
      "y": 0,
      "z": -10,
      "name": "Soil_Snow"
    },
    {
      "x": -7,
      "y": 2,
      "z": -10,
      "name": "Rock_Stone_Brick_Smooth"
    },
    {
      "x": -7,
      "y": 6,
      "z": -10,
      "name": "Furniture_Tavern_Shelf",
      "rotation": 1
    },
    {
      "x": -7,
      "y": 9,
      "z": -10,
      "name": "Wood_Darkwood_Roof_Hollow",
      "rotation": 3
    },
    {
      "x": -7,
      "y": 0,
      "z": -9,
      "name": "Soil_Snow"
    },
    {
      "x": -7,
      "y": 2,
      "z": -9,
      "name": "Rock_Stone_Brick_Smooth"
    },
    {
      "x": -7,
      "y": 9,
      "z": -9,
      "name": "Wood_Darkwood_Roof_Hollow",
      "rotation": 3
    },
    {
      "x": -7,
      "y": 0,
      "z": -8,
      "name": "Cloth_Block_Wool_Black"
    },
    {
      "x": -7,
      "y": 1,
      "z": -8,
      "name": "Cloth_Block_Wool_Black"
    },
    {
      "x": -7,
      "y": 2,
      "z": -8,
      "name": "Rock_Stone_Brick"
    },
    {
      "x": -7,
      "y": 6,
      "z": -8,
      "name": "Furniture_Tavern_Shelf",
      "rotation": 1
    },
    {
      "x": -7,
      "y": 9,
      "z": -8,
      "name": "Wood_Darkwood_Roof_Hollow",
      "rotation": 3
    },
    {
      "x": -7,
      "y": 0,
      "z": -7,
      "name": "Cloth_Block_Wool_Black"
    },
    {
      "x": -7,
      "y": 1,
      "z": -7,
      "name": "Cloth_Block_Wool_Black"
    },
    {
      "x": -7,
      "y": 2,
      "z": -7,
      "name": "Rock_Stone_Brick"
    },
    {
      "x": -7,
      "y": 3,
      "z": -7,
      "name": "Deco_Iron_Stack",
      "support": 15,
      "rotation": 1
    },
    {
      "x": -7,
      "y": 9,
      "z": -7,
      "name": "Wood_Darkwood_Roof_Hollow",
      "rotation": 3
    },
    {
      "x": -7,
      "y": 0,
      "z": -6,
      "name": "Soil_Snow"
    },
    {
      "x": -7,
      "y": 1,
      "z": -6,
      "name": "Rock_Slate_Cobble"
    },
    {
      "x": -7,
      "y": 2,
      "z": -6,
      "name": "Rock_Stone_Brick"
    },
    {
      "x": -7,
      "y": 3,
      "z": -6,
      "name": "Bench_Weapon",
      "components": {
        "Components": {
          "PlacedByInteraction": {
            "WhoPlacedUuid": {
              "$binary": "8MNzt+rrQc+vPEn2EjVTCw==",
              "$type": "04"
            }
          },
          "crafting": {
            "Position": {
              "X": 19,
              "Y": 83,
              "Z": 3
            },
            "TierLevel": 1,
            "UpgradeItems": []
          }
        }
      },
      "rotation": 1
    },
    {
      "x": -7,
      "y": 4,
      "z": -6,
      "name": "Bench_Weapon",
      "filler": 1024,
      "rotation": 1
    },
    {
      "x": -7,
      "y": 5,
      "z": -6,
      "name": "Furniture_Tavern_Shelf",
      "rotation": 1
    },
    {
      "x": -7,
      "y": 9,
      "z": -6,
      "name": "Wood_Darkwood_Roof_Hollow",
      "rotation": 3
    },
    {
      "x": -7,
      "y": 0,
      "z": -5,
      "name": "Soil_Snow"
    },
    {
      "x": -7,
      "y": 2,
      "z": -5,
      "name": "Rock_Stone_Brick"
    },
    {
      "x": -7,
      "y": 3,
      "z": -5,
      "name": "Bench_Weapon",
      "filler": 32,
      "rotation": 1
    },
    {
      "x": -7,
      "y": 4,
      "z": -5,
      "name": "Bench_Weapon",
      "filler": 1056,
      "rotation": 1
    },
    {
      "x": -7,
      "y": 9,
      "z": -5,
      "name": "Wood_Darkwood_Roof_Hollow",
      "rotation": 3
    },
    {
      "x": -7,
      "y": 0,
      "z": -4,
      "name": "Soil_Snow"
    },
    {
      "x": -7,
      "y": 3,
      "z": -4,
      "name": "Wood_Ash_Trunk_Full",
      "support": 15,
      "rotation": 5
    },
    {
      "x": -7,
      "y": 4,
      "z": -4,
      "name": "Wood_Ash_Trunk_Full",
      "support": 15,
      "rotation": 5
    },
    {
      "x": -7,
      "y": 5,
      "z": -4,
      "name": "Wood_Ash_Trunk_Full",
      "support": 15,
      "rotation": 5
    },
    {
      "x": -7,
      "y": 6,
      "z": -4,
      "name": "Wood_Ash_Trunk_Full",
      "support": 15,
      "rotation": 5
    },
    {
      "x": -7,
      "y": 7,
      "z": -4,
      "name": "Wood_Darkwood_Planks"
    },
    {
      "x": -7,
      "y": 8,
      "z": -4,
      "name": "Wood_Darkwood_Planks"
    },
    {
      "x": -7,
      "y": 9,
      "z": -4,
      "name": "Wood_Darkwood_Roof",
      "rotation": 3
    },
    {
      "x": -7,
      "y": 0,
      "z": -3,
      "name": "Soil_Snow"
    },
    {
      "x": -7,
      "y": 2,
      "z": -3,
      "name": "Wood_Darkwood_Planks"
    },
    {
      "x": -7,
      "y": 3,
      "z": -3,
      "name": "Furniture_Tavern_Planter"
    },
    {
      "x": -7,
      "y": 4,
      "z": -3,
      "name": "Deco_Lantern"
    },
    {
      "x": -7,
      "y": 8,
      "z": -3,
      "name": "Wood_Darkwood_Stairs",
      "rotation": 11
    },
    {
      "x": -7,
      "y": 9,
      "z": -3,
      "name": "Wood_Darkwood_Roof",
      "rotation": 3
    },
    {
      "x": -7,
      "y": 0,
      "z": -2,
      "name": "Soil_Snow"
    },
    {
      "x": -7,
      "y": 2,
      "z": -2,
      "name": "Wood_Darkwood_Planks"
    },
    {
      "x": -7,
      "y": 9,
      "z": -2,
      "name": "Wood_Darkwood_Roof_Hollow",
      "rotation": 3
    },
    {
      "x": -7,
      "y": 0,
      "z": -1,
      "name": "Soil_Snow"
    },
    {
      "x": -7,
      "y": 2,
      "z": -1,
      "name": "Wood_Darkwood_Planks"
    },
    {
      "x": -7,
      "y": 9,
      "z": -1,
      "name": "Wood_Darkwood_Roof_Hollow",
      "rotation": 3
    },
    {
      "x": -7,
      "y": 0,
      "z": 0,
      "name": "Soil_Snow"
    },
    {
      "x": -7,
      "y": 2,
      "z": 0,
      "name": "Wood_Darkwood_Planks"
    },
    {
      "x": -7,
      "y": 9,
      "z": 0,
      "name": "Wood_Darkwood_Roof_Hollow",
      "rotation": 3
    },
    {
      "x": -7,
      "y": 0,
      "z": 1,
      "name": "Soil_Snow"
    },
    {
      "x": -7,
      "y": 2,
      "z": 1,
      "name": "Wood_Darkwood_Planks"
    },
    {
      "x": -7,
      "y": 9,
      "z": 1,
      "name": "Wood_Darkwood_Roof_Hollow",
      "rotation": 3
    },
    {
      "x": -7,
      "y": 0,
      "z": 2,
      "name": "Soil_Snow"
    },
    {
      "x": -7,
      "y": 2,
      "z": 2,
      "name": "Wood_Darkwood_Planks"
    },
    {
      "x": -7,
      "y": 9,
      "z": 2,
      "name": "Wood_Darkwood_Roof_Hollow",
      "rotation": 3
    },
    {
      "x": -7,
      "y": 0,
      "z": 3,
      "name": "Soil_Snow"
    },
    {
      "x": -7,
      "y": 2,
      "z": 3,
      "name": "Wood_Darkwood_Planks"
    },
    {
      "x": -7,
      "y": 9,
      "z": 3,
      "name": "Wood_Darkwood_Roof_Hollow",
      "rotation": 3
    },
    {
      "x": -7,
      "y": 0,
      "z": 4,
      "name": "Soil_Snow"
    },
    {
      "x": -7,
      "y": 2,
      "z": 4,
      "name": "Wood_Darkwood_Planks"
    },
    {
      "x": -7,
      "y": 6,
      "z": 4,
      "name": "Deco_Lantern_Ceiling"
    },
    {
      "x": -7,
      "y": 7,
      "z": 4,
      "name": "Wood_Darkwood_Beam"
    },
    {
      "x": -7,
      "y": 8,
      "z": 4,
      "name": "Wood_Darkwood_Beam"
    },
    {
      "x": -7,
      "y": 9,
      "z": 4,
      "name": "Wood_Darkwood_Roof",
      "rotation": 3
    },
    {
      "x": -7,
      "y": 0,
      "z": 5,
      "name": "Soil_Snow"
    },
    {
      "x": -7,
      "y": 2,
      "z": 5,
      "name": "Wood_Darkwood_Planks"
    },
    {
      "x": -7,
      "y": 9,
      "z": 5,
      "name": "Wood_Darkwood_Roof_Hollow",
      "rotation": 3
    },
    {
      "x": -7,
      "y": 0,
      "z": 6,
      "name": "Soil_Snow"
    },
    {
      "x": -7,
      "y": 2,
      "z": 6,
      "name": "Wood_Darkwood_Planks"
    },
    {
      "x": -7,
      "y": 9,
      "z": 6,
      "name": "Wood_Darkwood_Roof_Hollow",
      "rotation": 3
    },
    {
      "x": -7,
      "y": 0,
      "z": 7,
      "name": "Soil_Snow"
    },
    {
      "x": -7,
      "y": 2,
      "z": 7,
      "name": "Wood_Darkwood_Planks"
    },
    {
      "x": -7,
      "y": 9,
      "z": 7,
      "name": "Wood_Darkwood_Roof_Hollow",
      "rotation": 3
    },
    {
      "x": -7,
      "y": 0,
      "z": 8,
      "name": "Soil_Snow"
    },
    {
      "x": -7,
      "y": 2,
      "z": 8,
      "name": "Wood_Darkwood_Planks"
    },
    {
      "x": -7,
      "y": 9,
      "z": 8,
      "name": "Wood_Darkwood_Roof_Hollow",
      "rotation": 3
    },
    {
      "x": -7,
      "y": 0,
      "z": 9,
      "name": "Soil_Snow"
    },
    {
      "x": -7,
      "y": 1,
      "z": 9,
      "name": "Wood_Darkwood_Decorative"
    },
    {
      "x": -7,
      "y": 2,
      "z": 9,
      "name": "Wood_Darkwood_Planks"
    },
    {
      "x": -7,
      "y": 3,
      "z": 9,
      "name": "Wood_Darkwood_Fence"
    },
    {
      "x": -7,
      "y": 8,
      "z": 9,
      "name": "Wood_Darkwood_Stairs",
      "rotation": 11
    },
    {
      "x": -7,
      "y": 9,
      "z": 9,
      "name": "Wood_Darkwood_Roof",
      "rotation": 3
    },
    {
      "x": -7,
      "y": 0,
      "z": 10,
      "name": "Soil_Snow"
    },
    {
      "x": -7,
      "y": 1,
      "z": 10,
      "name": "Plant_Bush_Lush",
      "support": 15
    },
    {
      "x": -7,
      "y": 0,
      "z": 11,
      "name": "Soil_Snow"
    },
    {
      "x": -7,
      "y": 0,
      "z": 12,
      "name": "Soil_Snow"
    },
    {
      "x": -7,
      "y": 1,
      "z": 12,
      "name": "Plant_Bush_Winter_Sharp",
      "support": 15
    },
    {
      "x": -7,
      "y": 0,
      "z": 13,
      "name": "Soil_Snow"
    },
    {
      "x": -7,
      "y": 0,
      "z": 14,
      "name": "Soil_Snow"
    },
    {
      "x": -7,
      "y": 0,
      "z": 15,
      "name": "Soil_Snow"
    },
    {
      "x": -7,
      "y": 0,
      "z": 16,
      "name": "Soil_Snow"
    },
    {
      "x": -7,
      "y": 0,
      "z": 17,
      "name": "Soil_Snow"
    },
    {
      "x": -7,
      "y": 3,
      "z": 17,
      "name": "Plant_Leaves_Fir",
      "support": 15,
      "rotation": 3
    },
    {
      "x": -7,
      "y": 4,
      "z": 17,
      "name": "Plant_Leaves_Fir",
      "support": 15,
      "rotation": 3
    },
    {
      "x": -7,
      "y": 0,
      "z": 18,
      "name": "Soil_Clay_Smooth_White"
    },
    {
      "x": -7,
      "y": 3,
      "z": 18,
      "name": "Plant_Leaves_Fir",
      "support": 15,
      "rotation": 3
    },
    {
      "x": -7,
      "y": 4,
      "z": 18,
      "name": "Plant_Leaves_Fir",
      "support": 15,
      "rotation": 3
    },
    {
      "x": -7,
      "y": 0,
      "z": 19,
      "name": "Soil_Clay_Smooth_White"
    },
    {
      "x": -7,
      "y": 3,
      "z": 19,
      "name": "Plant_Leaves_Fir",
      "support": 15,
      "rotation": 3
    },
    {
      "x": -7,
      "y": 0,
      "z": 20,
      "name": "Soil_Snow"
    },
    {
      "x": -7,
      "y": 0,
      "z": 21,
      "name": "Soil_Snow"
    },
    {
      "x": -7,
      "y": 0,
      "z": 22,
      "name": "Soil_Snow_Half"
    },
    {
      "x": -6,
      "y": 0,
      "z": -22,
      "name": "Soil_Snow_Half"
    },
    {
      "x": -6,
      "y": 0,
      "z": -21,
      "name": "Soil_Snow"
    },
    {
      "x": -6,
      "y": 0,
      "z": -20,
      "name": "Soil_Snow"
    },
    {
      "x": -6,
      "y": 1,
      "z": -20,
      "name": "Plant_Bush_Winter_Snow",
      "support": 15
    },
    {
      "x": -6,
      "y": 0,
      "z": -19,
      "name": "Soil_Snow"
    },
    {
      "x": -6,
      "y": 0,
      "z": -18,
      "name": "Soil_Snow"
    },
    {
      "x": -6,
      "y": 0,
      "z": -17,
      "name": "Soil_Snow"
    },
    {
      "x": -6,
      "y": 0,
      "z": -16,
      "name": "Rock_Ice"
    },
    {
      "x": -6,
      "y": 0,
      "z": -15,
      "name": "Soil_Snow"
    },
    {
      "x": -6,
      "y": 1,
      "z": -15,
      "name": "Plant_Bush_Lush",
      "support": 15
    },
    {
      "x": -6,
      "y": 9,
      "z": -15,
      "name": "Wood_Darkwood_Stairs",
      "rotation": 11
    },
    {
      "x": -6,
      "y": 10,
      "z": -15,
      "name": "Wood_Darkwood_Roof",
      "rotation": 3
    },
    {
      "x": -6,
      "y": 0,
      "z": -14,
      "name": "Soil_Snow"
    },
    {
      "x": -6,
      "y": 1,
      "z": -14,
      "name": "Rock_Volcanic_Cobble"
    },
    {
      "x": -6,
      "y": 2,
      "z": -14,
      "name": "Rock_Volcanic_Cobble"
    },
    {
      "x": -6,
      "y": 3,
      "z": -14,
      "name": "Wood_Ash_Trunk_Full",
      "support": 15,
      "rotation": 5
    },
    {
      "x": -6,
      "y": 4,
      "z": -14,
      "name": "Wood_Ash_Trunk_Full",
      "support": 15,
      "rotation": 5
    },
    {
      "x": -6,
      "y": 5,
      "z": -14,
      "name": "Wood_Ash_Trunk_Full",
      "support": 15,
      "rotation": 5
    },
    {
      "x": -6,
      "y": 6,
      "z": -14,
      "name": "Wood_Ash_Trunk_Full",
      "support": 15,
      "rotation": 5
    },
    {
      "x": -6,
      "y": 7,
      "z": -14,
      "name": "Wood_Darkwood_Planks"
    },
    {
      "x": -6,
      "y": 8,
      "z": -14,
      "name": "Wood_Darkwood_Planks"
    },
    {
      "x": -6,
      "y": 9,
      "z": -14,
      "name": "Wood_Darkwood_Planks"
    },
    {
      "x": -6,
      "y": 10,
      "z": -14,
      "name": "Wood_Darkwood_Roof",
      "rotation": 3
    },
    {
      "x": -6,
      "y": 0,
      "z": -13,
      "name": "Soil_Snow"
    },
    {
      "x": -6,
      "y": 2,
      "z": -13,
      "name": "Rock_Stone_Brick"
    },
    {
      "x": -6,
      "y": 3,
      "z": -13,
      "name": "Rock_Stone_Cobble_Half",
      "rotation": 7
    },
    {
      "x": -6,
      "y": 4,
      "z": -13,
      "name": "Rock_Stone_Brick_Half",
      "rotation": 7
    },
    {
      "x": -6,
      "y": 5,
      "z": -13,
      "name": "Rock_Stone_Brick_Half",
      "rotation": 7
    },
    {
      "x": -6,
      "y": 10,
      "z": -13,
      "name": "Wood_Darkwood_Roof_Hollow",
      "rotation": 3
    },
    {
      "x": -6,
      "y": 0,
      "z": -12,
      "name": "Soil_Snow"
    },
    {
      "x": -6,
      "y": 2,
      "z": -12,
      "name": "Rock_Stone_Brick"
    },
    {
      "x": -6,
      "y": 10,
      "z": -12,
      "name": "Wood_Darkwood_Roof_Hollow",
      "rotation": 3
    },
    {
      "x": -6,
      "y": 0,
      "z": -11,
      "name": "Soil_Snow"
    },
