{
  "version": 8,
  "blockIdVersion": 11,
  "anchorX": 0,
  "anchorY": 0,
  "anchorZ": 0,
  "blocks": [
    {
      "x": -66,
      "y": 18,
      "z": -7,
      "name": "*Rock_Calcite_Cobble_Roof_Hollow_State_Definitions_Corner_Right",
      "rotation": 3
    },
    {
      "x": -66,
      "y": 18,
      "z": -6,
      "name": "Rock_Calcite_Cobble_Roof_Hollow",
      "rotation": 3
    },
    {
      "x": -66,
      "y": 18,
      "z": -5,
      "name": "Rock_Calcite_Cobble_Roof_Hollow",
      "rotation": 3
    },
    {
      "x": -66,
      "y": 18,
      "z": -4,
      "name": "Rock_Calcite_Cobble_Roof_Hollow",
      "rotation": 3
    },
    {
      "x": -66,
      "y": 18,
      "z": -3,
      "name": "Rock_Calcite_Cobble_Roof_Hollow",
      "rotation": 3
    },
    {
      "x": -66,
      "y": 18,
      "z": -2,
      "name": "Rock_Calcite_Cobble_Roof_Hollow",
      "rotation": 3
    },
    {
      "x": -66,
      "y": 18,
      "z": -1,
      "name": "Rock_Calcite_Cobble_Roof_Hollow",
      "rotation": 3
    },
    {
      "x": -66,
      "y": 18,
      "z": 0,
      "name": "Rock_Calcite_Cobble_Roof_Hollow",
      "rotation": 3
    },
    {
      "x": -66,
      "y": 18,
      "z": 1,
      "name": "Rock_Calcite_Cobble_Roof_Hollow",
      "rotation": 3
    },
    {
      "x": -66,
      "y": 18,
      "z": 2,
      "name": "Rock_Calcite_Cobble_Roof_Hollow",
      "rotation": 3
    },
    {
      "x": -66,
      "y": 18,
      "z": 3,
      "name": "Rock_Calcite_Cobble_Roof_Hollow",
      "rotation": 3
    },
    {
      "x": -66,
      "y": 18,
      "z": 4,
      "name": "Rock_Calcite_Cobble_Roof_Hollow",
      "rotation": 3
    },
    {
      "x": -66,
      "y": 18,
      "z": 5,
      "name": "Rock_Calcite_Cobble_Roof_Hollow",
      "rotation": 3
    },
    {
      "x": -66,
      "y": 18,
      "z": 6,
      "name": "Rock_Calcite_Cobble_Roof_Hollow",
      "rotation": 3
    },
    {
      "x": -66,
      "y": 18,
      "z": 7,
      "name": "Rock_Calcite_Cobble_Roof_Hollow",
      "rotation": 3
    },
    {
      "x": -66,
      "y": 18,
      "z": 8,
      "name": "*Rock_Calcite_Cobble_Roof_Hollow_State_Definitions_Corner_Right"
    },
    {
      "x": -66,
      "y": 11,
      "z": 10,
      "name": "*Rock_Calcite_Cobble_Roof_Hollow_State_Definitions_Corner_Left",
      "rotation": 2
    },
    {
      "x": -66,
      "y": 11,
      "z": 11,
      "name": "Rock_Calcite_Cobble_Roof_Hollow",
      "rotation": 3
    },
    {
      "x": -66,
      "y": 11,
      "z": 12,
      "name": "Rock_Calcite_Cobble_Roof_Hollow",
      "rotation": 3
    },
    {
      "x": -66,
      "y": 11,
      "z": 13,
      "name": "Rock_Calcite_Cobble_Roof_Hollow",
      "rotation": 3
    },
    {
      "x": -66,
      "y": 11,
      "z": 14,
      "name": "Rock_Calcite_Cobble_Roof_Hollow",
      "rotation": 3
    },
    {
      "x": -66,
      "y": 11,
      "z": 15,
      "name": "Rock_Calcite_Cobble_Roof_Hollow",
      "rotation": 3
    },
    {
      "x": -66,
      "y": 11,
      "z": 16,
      "name": "Rock_Calcite_Cobble_Roof_Hollow",
      "rotation": 3
    },
    {
      "x": -66,
      "y": 11,
      "z": 17,
      "name": "Rock_Calcite_Cobble_Roof_Hollow",
      "rotation": 3
    },
    {
      "x": -66,
      "y": 11,
      "z": 18,
      "name": "Rock_Calcite_Cobble_Roof_Hollow",
      "rotation": 3
    },
    {
      "x": -66,
      "y": 11,
      "z": 19,
      "name": "Rock_Calcite_Cobble_Roof_Hollow",
      "rotation": 3
    },
    {
      "x": -66,
      "y": 11,
      "z": 20,
      "name": "Rock_Calcite_Cobble_Roof_Hollow",
      "rotation": 3
    },
    {
      "x": -66,
      "y": 11,
      "z": 21,
      "name": "Rock_Calcite_Cobble_Roof_Hollow",
      "rotation": 3
    },
    {
      "x": -66,
      "y": 11,
      "z": 22,
      "name": "Rock_Calcite_Cobble_Roof_Hollow",
      "rotation": 3
    },
    {
      "x": -66,
      "y": 11,
      "z": 23,
      "name": "Rock_Calcite_Cobble_Roof_Hollow",
      "rotation": 3
    },
    {
      "x": -66,
      "y": 11,
      "z": 24,
      "name": "Rock_Calcite_Cobble_Roof_Hollow",
      "rotation": 3
    },
    {
      "x": -66,
      "y": 11,
      "z": 25,
      "name": "Rock_Calcite_Cobble_Roof_Hollow",
      "rotation": 3
    },
    {
      "x": -66,
      "y": 11,
      "z": 26,
      "name": "Rock_Calcite_Cobble_Roof_Hollow",
      "rotation": 3
    },
    {
      "x": -66,
      "y": 11,
      "z": 27,
      "name": "Rock_Calcite_Cobble_Roof_Hollow",
      "rotation": 3
    },
    {
      "x": -66,
      "y": 11,
      "z": 28,
      "name": "Rock_Calcite_Cobble_Roof_Hollow",
      "rotation": 3
    },
    {
      "x": -66,
      "y": 11,
      "z": 29,
      "name": "Rock_Calcite_Cobble_Roof_Hollow",
      "rotation": 3
    },
    {
      "x": -66,
      "y": 11,
      "z": 30,
      "name": "Rock_Calcite_Cobble_Roof_Hollow",
      "rotation": 3
    },
    {
      "x": -66,
      "y": 11,
      "z": 31,
      "name": "Rock_Calcite_Cobble_Roof_Hollow",
      "rotation": 3
    },
    {
      "x": -66,
      "y": 11,
      "z": 32,
      "name": "Rock_Calcite_Cobble_Roof_Hollow",
      "rotation": 3
    },
    {
      "x": -66,
      "y": 11,
      "z": 33,
      "name": "*Rock_Calcite_Cobble_Roof_Hollow_State_Definitions_Corner_Left",
      "rotation": 3
    },
    {
      "x": -65,
      "y": 18,
      "z": -7,
      "name": "Rock_Calcite_Cobble_Roof_Hollow",
      "rotation": 2
    },
    {
      "x": -65,
      "y": 18,
      "z": -6,
      "name": "Wood_Deadwood_Planks"
    },
    {
      "x": -65,
      "y": 19,
      "z": -6,
      "name": "*Rock_Calcite_Cobble_Roof_Steep_State_Definitions_Corner_Right",
      "rotation": 3
    },
    {
      "x": -65,
      "y": 20,
      "z": -6,
      "name": "*Rock_Calcite_Cobble_Roof_Steep_State_Definitions_Corner_Right",
      "filler": 1024,
      "rotation": 3
    },
    {
      "x": -65,
      "y": 18,
      "z": -5,
      "name": "Wood_Deadwood_Planks"
    },
    {
      "x": -65,
      "y": 19,
      "z": -5,
      "name": "Rock_Calcite_Cobble_Roof_Steep",
      "rotation": 3
    },
    {
      "x": -65,
      "y": 20,
      "z": -5,
      "name": "Rock_Calcite_Cobble_Roof_Steep",
      "filler": 1024,
      "rotation": 3
    },
    {
      "x": -65,
      "y": 18,
      "z": -4,
      "name": "Wood_Deadwood_Planks"
    },
    {
      "x": -65,
      "y": 19,
      "z": -4,
      "name": "Rock_Calcite_Cobble_Roof_Steep",
      "rotation": 3
    },
    {
      "x": -65,
      "y": 20,
      "z": -4,
      "name": "Rock_Calcite_Cobble_Roof_Steep",
      "filler": 1024,
      "rotation": 3
    },
    {
      "x": -65,
      "y": 18,
      "z": -3,
      "name": "Wood_Deadwood_Planks"
    },
    {
      "x": -65,
      "y": 19,
      "z": -3,
      "name": "Rock_Calcite_Cobble_Roof_Steep",
      "rotation": 3
    },
    {
      "x": -65,
      "y": 20,
      "z": -3,
      "name": "Rock_Calcite_Cobble_Roof_Steep",
      "filler": 1024,
      "rotation": 3
    },
    {
      "x": -65,
      "y": 18,
      "z": -2,
      "name": "Wood_Deadwood_Planks"
    },
    {
      "x": -65,
      "y": 19,
      "z": -2,
      "name": "Rock_Calcite_Cobble_Roof_Steep",
      "rotation": 3
    },
    {
      "x": -65,
      "y": 20,
      "z": -2,
      "name": "Rock_Calcite_Cobble_Roof_Steep",
      "filler": 1024,
      "rotation": 3
    },
    {
      "x": -65,
      "y": 18,
      "z": -1,
      "name": "Wood_Deadwood_Planks"
    },
    {
      "x": -65,
      "y": 19,
      "z": -1,
      "name": "Rock_Calcite_Cobble_Roof_Steep",
      "rotation": 3
    },
    {
      "x": -65,
      "y": 20,
      "z": -1,
      "name": "Rock_Calcite_Cobble_Roof_Steep",
      "filler": 1024,
      "rotation": 3
    },
    {
      "x": -65,
      "y": 18,
      "z": 0,
      "name": "Wood_Deadwood_Planks"
    },
    {
      "x": -65,
      "y": 19,
      "z": 0,
      "name": "Rock_Calcite_Cobble_Roof_Steep",
      "rotation": 3
    },
    {
      "x": -65,
      "y": 20,
      "z": 0,
      "name": "Rock_Calcite_Cobble_Roof_Steep",
      "filler": 1024,
      "rotation": 3
    },
    {
      "x": -65,
      "y": 18,
      "z": 1,
      "name": "Wood_Deadwood_Planks"
    },
    {
      "x": -65,
      "y": 19,
      "z": 1,
      "name": "Rock_Calcite_Cobble_Roof_Steep",
      "rotation": 3
    },
    {
      "x": -65,
      "y": 20,
      "z": 1,
      "name": "Rock_Calcite_Cobble_Roof_Steep",
      "filler": 1024,
      "rotation": 3
    },
    {
      "x": -65,
      "y": 18,
      "z": 2,
      "name": "Wood_Deadwood_Planks"
    },
    {
      "x": -65,
      "y": 19,
      "z": 2,
      "name": "Rock_Calcite_Cobble_Roof_Steep",
      "rotation": 3
    },
    {
      "x": -65,
      "y": 20,
      "z": 2,
      "name": "Rock_Calcite_Cobble_Roof_Steep",
      "filler": 1024,
      "rotation": 3
    },
    {
      "x": -65,
      "y": 18,
      "z": 3,
      "name": "Wood_Deadwood_Planks"
    },
    {
      "x": -65,
      "y": 19,
      "z": 3,
      "name": "Rock_Calcite_Cobble_Roof_Steep",
      "rotation": 3
    },
    {
      "x": -65,
      "y": 20,
      "z": 3,
      "name": "Rock_Calcite_Cobble_Roof_Steep",
      "filler": 1024,
      "rotation": 3
    },
    {
      "x": -65,
      "y": 18,
      "z": 4,
      "name": "Wood_Deadwood_Planks"
    },
    {
      "x": -65,
      "y": 19,
      "z": 4,
      "name": "Rock_Calcite_Cobble_Roof_Steep",
      "rotation": 3
    },
    {
      "x": -65,
      "y": 20,
      "z": 4,
      "name": "Rock_Calcite_Cobble_Roof_Steep",
      "filler": 1024,
      "rotation": 3
    },
    {
      "x": -65,
      "y": 18,
      "z": 5,
      "name": "Wood_Deadwood_Planks"
    },
    {
      "x": -65,
      "y": 19,
      "z": 5,
      "name": "Rock_Calcite_Cobble_Roof_Steep",
      "rotation": 3
    },
    {
      "x": -65,
      "y": 20,
      "z": 5,
      "name": "Rock_Calcite_Cobble_Roof_Steep",
      "filler": 1024,
      "rotation": 3
    },
    {
      "x": -65,
      "y": 18,
      "z": 6,
      "name": "Wood_Deadwood_Planks"
    },
    {
      "x": -65,
      "y": 19,
      "z": 6,
      "name": "Rock_Calcite_Cobble_Roof_Steep",
      "rotation": 3
    },
    {
      "x": -65,
      "y": 20,
      "z": 6,
      "name": "Rock_Calcite_Cobble_Roof_Steep",
      "filler": 1024,
      "rotation": 3
    },
    {
      "x": -65,
      "y": 18,
      "z": 7,
      "name": "Wood_Deadwood_Planks"
    },
    {
      "x": -65,
      "y": 19,
      "z": 7,
      "name": "*Rock_Calcite_Cobble_Roof_Steep_State_Definitions_Corner_Right"
    },
    {
      "x": -65,
      "y": 20,
      "z": 7,
      "name": "*Rock_Calcite_Cobble_Roof_Steep_State_Definitions_Corner_Right",
      "filler": 1024
    },
    {
      "x": -65,
      "y": 18,
      "z": 8,
      "name": "Rock_Calcite_Cobble_Roof_Hollow"
    },
    {
      "x": -65,
      "y": 11,
      "z": 10,
      "name": "Rock_Calcite_Cobble_Roof_Hollow",
      "rotation": 2
    },
    {
      "x": -65,
      "y": 11,
      "z": 11,
      "name": "Wood_Deadwood_Planks"
    },
    {
      "x": -65,
      "y": 12,
      "z": 11,
      "name": "*Rock_Calcite_Cobble_Roof_State_Definitions_Corner_Right",
      "rotation": 3
    },
    {
      "x": -65,
      "y": 11,
      "z": 12,
      "name": "Wood_Deadwood_Planks"
    },
    {
      "x": -65,
      "y": 12,
      "z": 12,
      "name": "Rock_Calcite_Cobble_Roof",
      "rotation": 3
    },
    {
      "x": -65,
      "y": 11,
      "z": 13,
      "name": "Wood_Deadwood_Planks"
    },
    {
      "x": -65,
      "y": 12,
      "z": 13,
      "name": "Rock_Calcite_Cobble_Roof",
      "rotation": 3
    },
    {
      "x": -65,
      "y": 11,
      "z": 14,
      "name": "Wood_Deadwood_Planks"
    },
    {
      "x": -65,
      "y": 12,
      "z": 14,
      "name": "Rock_Calcite_Cobble_Roof",
      "rotation": 3
    },
    {
      "x": -65,
      "y": 11,
      "z": 15,
      "name": "Wood_Deadwood_Planks"
    },
    {
      "x": -65,
      "y": 12,
      "z": 15,
      "name": "Rock_Calcite_Cobble_Roof",
      "rotation": 3
    },
    {
      "x": -65,
      "y": 11,
      "z": 16,
      "name": "Wood_Deadwood_Planks"
    },
    {
      "x": -65,
      "y": 12,
      "z": 16,
      "name": "Rock_Calcite_Cobble_Roof",
      "rotation": 3
    },
    {
      "x": -65,
      "y": 11,
      "z": 17,
      "name": "Wood_Deadwood_Planks"
    },
    {
      "x": -65,
      "y": 12,
      "z": 17,
      "name": "Rock_Calcite_Cobble_Roof",
      "rotation": 3
    },
    {
      "x": -65,
      "y": 11,
      "z": 18,
      "name": "Wood_Deadwood_Planks"
    },
    {
      "x": -65,
      "y": 12,
      "z": 18,
      "name": "Rock_Calcite_Cobble_Roof",
      "rotation": 3
    },
    {
      "x": -65,
      "y": 11,
      "z": 19,
      "name": "Wood_Deadwood_Planks"
    },
    {
      "x": -65,
      "y": 12,
      "z": 19,
      "name": "Rock_Calcite_Cobble_Roof",
      "rotation": 3
    },
    {
      "x": -65,
      "y": 11,
      "z": 20,
      "name": "Wood_Deadwood_Planks"
    },
    {
      "x": -65,
      "y": 12,
      "z": 20,
      "name": "Rock_Calcite_Cobble_Roof",
      "rotation": 3
    },
    {
      "x": -65,
      "y": 11,
      "z": 21,
      "name": "Wood_Deadwood_Planks"
    },
    {
      "x": -65,
      "y": 12,
      "z": 21,
      "name": "Rock_Calcite_Cobble_Roof",
      "rotation": 3
    },
    {
      "x": -65,
      "y": 11,
      "z": 22,
      "name": "Wood_Deadwood_Planks"
    },
    {
      "x": -65,
      "y": 12,
      "z": 22,
      "name": "Rock_Calcite_Cobble_Roof",
      "rotation": 3
    },
    {
      "x": -65,
      "y": 11,
      "z": 23,
      "name": "Wood_Deadwood_Planks"
    },
    {
      "x": -65,
      "y": 12,
      "z": 23,
      "name": "Rock_Calcite_Cobble_Roof",
      "rotation": 3
    },
    {
      "x": -65,
      "y": 11,
      "z": 24,
      "name": "Wood_Deadwood_Planks"
    },
    {
      "x": -65,
      "y": 12,
      "z": 24,
      "name": "Rock_Calcite_Cobble_Roof",
      "rotation": 3
    },
    {
      "x": -65,
      "y": 11,
      "z": 25,
      "name": "Wood_Deadwood_Planks"
    },
    {
      "x": -65,
      "y": 12,
      "z": 25,
      "name": "Rock_Calcite_Cobble_Roof",
      "rotation": 3
    },
    {
      "x": -65,
      "y": 11,
      "z": 26,
      "name": "Wood_Deadwood_Planks"
    },
    {
      "x": -65,
      "y": 12,
      "z": 26,
      "name": "Rock_Calcite_Cobble_Roof",
      "rotation": 3
    },
    {
      "x": -65,
      "y": 11,
      "z": 27,
      "name": "Wood_Deadwood_Planks"
    },
    {
      "x": -65,
      "y": 12,
      "z": 27,
      "name": "Rock_Calcite_Cobble_Roof",
      "rotation": 3
    },
    {
      "x": -65,
      "y": 11,
      "z": 28,
      "name": "Wood_Deadwood_Planks"
    },
    {
      "x": -65,
      "y": 12,
      "z": 28,
      "name": "Rock_Calcite_Cobble_Roof",
      "rotation": 3
    },
    {
      "x": -65,
      "y": 11,
      "z": 29,
      "name": "Wood_Deadwood_Planks"
    },
    {
      "x": -65,
      "y": 12,
      "z": 29,
      "name": "Rock_Calcite_Cobble_Roof",
      "rotation": 3
    },
    {
      "x": -65,
      "y": 11,
      "z": 30,
      "name": "Wood_Deadwood_Planks"
    },
    {
      "x": -65,
      "y": 12,
      "z": 30,
      "name": "Rock_Calcite_Cobble_Roof",
      "rotation": 3
    },
    {
      "x": -65,
      "y": 11,
      "z": 31,
      "name": "Wood_Deadwood_Planks"
    },
    {
      "x": -65,
      "y": 12,
      "z": 31,
      "name": "Rock_Calcite_Cobble_Roof",
      "rotation": 3
    },
    {
      "x": -65,
      "y": 11,
      "z": 32,
      "name": "Wood_Deadwood_Planks"
    },
    {
      "x": -65,
      "y": 12,
      "z": 32,
      "name": "*Rock_Calcite_Cobble_Roof_State_Definitions_Corner_Right"
    },
    {
      "x": -65,
      "y": 11,
      "z": 33,
      "name": "Rock_Calcite_Cobble_Roof_Hollow"
    },
    {
      "x": -64,
      "y": 14,
      "z": -22,
      "name": "Rock_Calcite_Cobble_Roof_Hollow",
      "rotation": 3
    },
    {
      "x": -64,
      "y": 14,
      "z": -21,
      "name": "Rock_Calcite_Cobble_Roof_Hollow",
      "rotation": 3
    },
    {
      "x": -64,
      "y": 14,
      "z": -20,
      "name": "Rock_Calcite_Cobble_Roof_Hollow",
      "rotation": 3
    },
    {
      "x": -64,
      "y": 14,
      "z": -19,
      "name": "Rock_Calcite_Cobble_Roof_Hollow",
      "rotation": 3
    },
    {
      "x": -64,
      "y": 14,
      "z": -18,
      "name": "Rock_Calcite_Cobble_Roof_Hollow",
      "rotation": 3
    },
    {
      "x": -64,
      "y": 14,
      "z": -17,
      "name": "Rock_Calcite_Cobble_Roof_Hollow",
      "rotation": 3
    },
    {
      "x": -64,
      "y": 14,
      "z": -16,
      "name": "Rock_Calcite_Cobble_Roof_Hollow",
      "rotation": 3
    },
    {
      "x": -64,
      "y": 14,
      "z": -15,
      "name": "Rock_Calcite_Cobble_Roof_Hollow",
      "rotation": 3
    },
    {
      "x": -64,
      "y": 14,
      "z": -14,
      "name": "Rock_Calcite_Cobble_Roof_Hollow",
      "rotation": 3
    },
    {
      "x": -64,
      "y": 14,
      "z": -13,
      "name": "Rock_Calcite_Cobble_Roof_Hollow",
      "rotation": 3
    },
    {
      "x": -64,
      "y": 14,
      "z": -12,
      "name": "Rock_Calcite_Cobble_Roof_Hollow",
      "rotation": 3
    },
    {
      "x": -64,
      "y": 14,
      "z": -11,
      "name": "Rock_Calcite_Cobble_Roof_Hollow",
      "rotation": 3
    },
    {
      "x": -64,
      "y": 14,
      "z": -10,
      "name": "Rock_Calcite_Cobble_Roof_Hollow",
      "rotation": 3
    },
    {
      "x": -64,
      "y": 14,
      "z": -9,
      "name": "Rock_Calcite_Cobble_Roof_Hollow",
      "rotation": 3
    },
    {
      "x": -64,
      "y": 14,
      "z": -8,
      "name": "Rock_Calcite_Cobble_Roof_Hollow",
      "rotation": 3
    },
    {
      "x": -64,
      "y": 14,
      "z": -7,
      "name": "Rock_Calcite_Cobble_Roof_Hollow",
      "rotation": 3
    },
    {
      "x": -64,
      "y": 18,
      "z": -7,
      "name": "Rock_Calcite_Cobble_Roof_Hollow",
      "rotation": 2
    },
    {
      "x": -64,
      "y": 18,
      "z": -6,
      "name": "Wood_Deadwood_Planks"
    },
    {
      "x": -64,
      "y": 19,
      "z": -6,
      "name": "Rock_Calcite_Cobble_Roof_Steep",
      "rotation": 2
    },
    {
      "x": -64,
      "y": 20,
      "z": -6,
      "name": "Rock_Calcite_Cobble_Roof_Steep",
      "filler": 1024,
      "rotation": 2
    },
    {
      "x": -64,
      "y": 20,
      "z": -5,
      "name": "Wood_Deadwood_Planks"
    },
    {
      "x": -64,
      "y": 21,
      "z": -5,
      "name": "*Rock_Calcite_Cobble_Roof_Steep_State_Definitions_Corner_Right",
      "rotation": 3
    },
    {
      "x": -64,
      "y": 22,
      "z": -5,
      "name": "*Rock_Calcite_Cobble_Roof_Steep_State_Definitions_Corner_Right",
      "filler": 1024,
      "rotation": 3
    },
    {
      "x": -64,
      "y": 20,
      "z": -4,
      "name": "Wood_Deadwood_Planks"
    },
    {
      "x": -64,
      "y": 21,
      "z": -4,
      "name": "Rock_Calcite_Cobble_Roof_Steep",
      "rotation": 3
    },
    {
      "x": -64,
      "y": 22,
      "z": -4,
      "name": "Rock_Calcite_Cobble_Roof_Steep",
      "filler": 1024,
      "rotation": 3
    },
    {
      "x": -64,
      "y": 20,
      "z": -3,
      "name": "Wood_Deadwood_Planks"
    },
    {
      "x": -64,
      "y": 21,
      "z": -3,
      "name": "Rock_Calcite_Cobble_Roof_Steep",
      "rotation": 3
    },
    {
      "x": -64,
      "y": 22,
      "z": -3,
      "name": "Rock_Calcite_Cobble_Roof_Steep",
      "filler": 1024,
      "rotation": 3
    },
    {
      "x": -64,
      "y": 20,
      "z": -2,
      "name": "Wood_Deadwood_Planks"
    },
    {
      "x": -64,
      "y": 21,
      "z": -2,
      "name": "Rock_Calcite_Cobble_Roof_Steep",
      "rotation": 3
    },
    {
      "x": -64,
      "y": 22,
      "z": -2,
      "name": "Rock_Calcite_Cobble_Roof_Steep",
      "filler": 1024,
      "rotation": 3
    },
    {
      "x": -64,
      "y": 20,
      "z": -1,
      "name": "Wood_Deadwood_Planks"
    },
    {
      "x": -64,
      "y": 21,
      "z": -1,
      "name": "Rock_Calcite_Cobble_Roof_Steep",
      "rotation": 3
    },
    {
      "x": -64,
      "y": 22,
      "z": -1,
      "name": "Rock_Calcite_Cobble_Roof_Steep",
      "filler": 1024,
      "rotation": 3
    },
    {
      "x": -64,
      "y": 20,
      "z": 0,
      "name": "Wood_Deadwood_Planks"
    },
    {
      "x": -64,
      "y": 21,
      "z": 0,
      "name": "Rock_Calcite_Cobble_Roof_Steep",
      "rotation": 3
    },
    {
      "x": -64,
      "y": 22,
      "z": 0,
      "name": "Rock_Calcite_Cobble_Roof_Steep",
      "filler": 1024,
      "rotation": 3
    },
    {
      "x": -64,
      "y": 20,
      "z": 1,
      "name": "Wood_Deadwood_Planks"
    },
    {
      "x": -64,
      "y": 21,
      "z": 1,
      "name": "Rock_Calcite_Cobble_Roof_Steep",
      "rotation": 3
    },
    {
      "x": -64,
      "y": 22,
      "z": 1,
      "name": "Rock_Calcite_Cobble_Roof_Steep",
      "filler": 1024,
      "rotation": 3
    },
    {
      "x": -64,
      "y": 20,
      "z": 2,
      "name": "Wood_Deadwood_Planks"
    },
    {
      "x": -64,
      "y": 21,
      "z": 2,
      "name": "Rock_Calcite_Cobble_Roof_Steep",
      "rotation": 3
    },
    {
      "x": -64,
      "y": 22,
      "z": 2,
      "name": "Rock_Calcite_Cobble_Roof_Steep",
      "filler": 1024,
      "rotation": 3
    },
    {
      "x": -64,
      "y": 20,
      "z": 3,
      "name": "Wood_Deadwood_Planks"
    },
    {
      "x": -64,
      "y": 21,
      "z": 3,
      "name": "Rock_Calcite_Cobble_Roof_Steep",
      "rotation": 3
    },
    {
      "x": -64,
      "y": 22,
      "z": 3,
      "name": "Rock_Calcite_Cobble_Roof_Steep",
      "filler": 1024,
      "rotation": 3
    },
    {
      "x": -64,
      "y": 20,
      "z": 4,
      "name": "Wood_Deadwood_Planks"
    },
    {
      "x": -64,
      "y": 21,
      "z": 4,
      "name": "Rock_Calcite_Cobble_Roof_Steep",
      "rotation": 3
    },
    {
      "x": -64,
      "y": 22,
      "z": 4,
      "name": "Rock_Calcite_Cobble_Roof_Steep",
      "filler": 1024,
      "rotation": 3
    },
    {
      "x": -64,
      "y": 20,
      "z": 5,
      "name": "Wood_Deadwood_Planks"
    },
    {
      "x": -64,
      "y": 21,
      "z": 5,
      "name": "Rock_Calcite_Cobble_Roof_Steep",
      "rotation": 3
    },
    {
      "x": -64,
      "y": 22,
      "z": 5,
      "name": "Rock_Calcite_Cobble_Roof_Steep",
      "filler": 1024,
      "rotation": 3
    },
    {
      "x": -64,
      "y": 20,
      "z": 6,
      "name": "Wood_Deadwood_Planks"
    },
    {
      "x": -64,
      "y": 21,
      "z": 6,
      "name": "*Rock_Calcite_Cobble_Roof_Steep_State_Definitions_Corner_Right"
    },
    {
      "x": -64,
      "y": 22,
      "z": 6,
      "name": "*Rock_Calcite_Cobble_Roof_Steep_State_Definitions_Corner_Right",
      "filler": 1024
    },
    {
      "x": -64,
      "y": 18,
      "z": 7,
      "name": "Wood_Deadwood_Planks"
    },
    {
      "x": -64,
      "y": 19,
      "z": 7,
      "name": "Rock_Calcite_Cobble_Roof_Steep"
    },
    {
      "x": -64,
      "y": 20,
      "z": 7,
      "name": "Rock_Calcite_Cobble_Roof_Steep",
      "filler": 1024
    },
    {
      "x": -64,
      "y": 18,
      "z": 8,
      "name": "Rock_Calcite_Cobble_Roof_Hollow"
    },
    {
      "x": -64,
      "y": 11,
      "z": 10,
      "name": "Rock_Calcite_Cobble_Roof_Hollow",
      "rotation": 2
    },
    {
      "x": -64,
      "y": 11,
      "z": 11,
      "name": "Wood_Deadwood_Planks"
    },
    {
      "x": -64,
      "y": 12,
      "z": 11,
      "name": "Rock_Calcite_Cobble_Roof",
      "rotation": 2
    },
    {
      "x": -64,
      "y": 12,
      "z": 12,
      "name": "Wood_Deadwood_Planks"
    },
    {
      "x": -64,
      "y": 13,
      "z": 12,
      "name": "*Rock_Calcite_Cobble_Roof_State_Definitions_Corner_Right",
      "rotation": 3
    },
    {
      "x": -64,
      "y": 12,
      "z": 13,
      "name": "Wood_Deadwood_Planks"
    },
    {
      "x": -64,
      "y": 13,
      "z": 13,
      "name": "Rock_Calcite_Cobble_Roof",
      "rotation": 3
    },
    {
      "x": -64,
      "y": 12,
      "z": 14,
      "name": "Wood_Deadwood_Planks"
    },
    {
      "x": -64,
      "y": 13,
      "z": 14,
      "name": "Rock_Calcite_Cobble_Roof",
      "rotation": 3
    },
    {
      "x": -64,
      "y": 12,
      "z": 15,
      "name": "Wood_Deadwood_Planks"
    },
    {
      "x": -64,
      "y": 13,
      "z": 15,
      "name": "Rock_Calcite_Cobble_Roof",
      "rotation": 3
    },
    {
      "x": -64,
      "y": 12,
      "z": 16,
      "name": "Wood_Deadwood_Planks"
    },
    {
      "x": -64,
      "y": 13,
      "z": 16,
      "name": "Rock_Calcite_Cobble_Roof",
      "rotation": 3
    },
    {
      "x": -64,
      "y": 12,
      "z": 17,
      "name": "Wood_Deadwood_Planks"
    },
    {
      "x": -64,
      "y": 13,
      "z": 17,
      "name": "Rock_Calcite_Cobble_Roof",
      "rotation": 3
    },
    {
      "x": -64,
      "y": 12,
      "z": 18,
      "name": "Wood_Deadwood_Planks"
    },
    {
      "x": -64,
      "y": 13,
      "z": 18,
      "name": "Rock_Calcite_Cobble_Roof",
      "rotation": 3
    },
    {
      "x": -64,
      "y": 12,
      "z": 19,
      "name": "Wood_Deadwood_Planks"
    },
    {
      "x": -64,
      "y": 13,
      "z": 19,
      "name": "Rock_Calcite_Cobble_Roof",
      "rotation": 3
    },
    {
      "x": -64,
      "y": 12,
      "z": 20,
      "name": "Wood_Deadwood_Planks"
    },
    {
      "x": -64,
      "y": 13,
      "z": 20,
      "name": "Rock_Calcite_Cobble_Roof",
      "rotation": 3
    },
    {
      "x": -64,
      "y": 12,
      "z": 21,
      "name": "Wood_Deadwood_Planks"
    },
    {
      "x": -64,
      "y": 13,
      "z": 21,
      "name": "Rock_Calcite_Cobble_Roof",
      "rotation": 3
    },
    {
      "x": -64,
      "y": 12,
      "z": 22,
      "name": "Wood_Deadwood_Planks"
    },
    {
      "x": -64,
      "y": 13,
      "z": 22,
      "name": "Rock_Calcite_Cobble_Roof",
      "rotation": 3
    },
    {
      "x": -64,
      "y": 12,
      "z": 23,
      "name": "Wood_Deadwood_Planks"
    },
    {
      "x": -64,
      "y": 13,
      "z": 23,
      "name": "Rock_Calcite_Cobble_Roof",
      "rotation": 3
    },
    {
      "x": -64,
      "y": 12,
      "z": 24,
      "name": "Wood_Deadwood_Planks"
    },
    {
      "x": -64,
      "y": 13,
      "z": 24,
      "name": "Rock_Calcite_Cobble_Roof",
      "rotation": 3
    },
    {
      "x": -64,
      "y": 12,
      "z": 25,
      "name": "Wood_Deadwood_Planks"
    },
    {
      "x": -64,
      "y": 13,
      "z": 25,
      "name": "Rock_Calcite_Cobble_Roof",
      "rotation": 3
    },
    {
      "x": -64,
      "y": 12,
      "z": 26,
      "name": "Wood_Deadwood_Planks"
    },
    {
      "x": -64,
      "y": 13,
      "z": 26,
      "name": "Rock_Calcite_Cobble_Roof",
      "rotation": 3
    },
    {
      "x": -64,
      "y": 12,
      "z": 27,
      "name": "Wood_Deadwood_Planks"
    },
    {
      "x": -64,
      "y": 13,
      "z": 27,
      "name": "Rock_Calcite_Cobble_Roof",
      "rotation": 3
    },
    {
      "x": -64,
      "y": 12,
      "z": 28,
      "name": "Wood_Deadwood_Planks"
    },
    {
      "x": -64,
      "y": 13,
      "z": 28,
      "name": "Rock_Calcite_Cobble_Roof",
      "rotation": 3
    },
    {
      "x": -64,
      "y": 12,
      "z": 29,
      "name": "Wood_Deadwood_Planks"
    },
    {
      "x": -64,
      "y": 13,
      "z": 29,
      "name": "Rock_Calcite_Cobble_Roof",
      "rotation": 3
    },
    {
      "x": -64,
      "y": 12,
      "z": 30,
      "name": "Wood_Deadwood_Planks"
    },
    {
      "x": -64,
      "y": 13,
      "z": 30,
      "name": "Rock_Calcite_Cobble_Roof",
      "rotation": 3
    },
    {
      "x": -64,
      "y": 12,
      "z": 31,
      "name": "Wood_Deadwood_Planks"
    },
    {
      "x": -64,
      "y": 13,
      "z": 31,
      "name": "*Rock_Calcite_Cobble_Roof_State_Definitions_Corner_Right"
    },
    {
      "x": -64,
      "y": 11,
      "z": 32,
      "name": "Wood_Deadwood_Planks"
    },
    {
      "x": -64,
      "y": 12,
      "z": 32,
      "name": "Rock_Calcite_Cobble_Roof"
    },
    {
      "x": -64,
      "y": 11,
      "z": 33,
      "name": "Rock_Calcite_Cobble_Roof_Hollow"
    },
    {
      "x": -63,
      "y": 5,
      "z": -22,
      "name": "Wood_Deadwood_Planks"
    },
    {
      "x": -63,
      "y": 6,
      "z": -22,
      "name": "Wood_Deadwood_Planks"
    },
    {
      "x": -63,
      "y": 7,
      "z": -22,
      "name": "Wood_Deadwood_Planks"
    },
    {
      "x": -63,
      "y": 8,
      "z": -22,
      "name": "Wood_Deadwood_Planks"
    },
    {
      "x": -63,
      "y": 9,
      "z": -22,
      "name": "Wood_Deadwood_Planks"
    },
    {
      "x": -63,
      "y": 10,
      "z": -22,
      "name": "Wood_Deadwood_Planks"
    },
    {
      "x": -63,
      "y": 11,
      "z": -22,
      "name": "Wood_Deadwood_Planks"
    },
    {
      "x": -63,
      "y": 12,
      "z": -22,
      "name": "Wood_Deadwood_Planks"
    },
    {
      "x": -63,
      "y": 13,
      "z": -22,
      "name": "Wood_Deadwood_Planks"
    },
    {
      "x": -63,
      "y": 14,
      "z": -22,
      "name": "Wood_Deadwood_Planks"
    },
    {
      "x": -63,
      "y": 15,
      "z": -22,
      "name": "Rock_Calcite_Cobble_Roof_Shallow",
      "rotation": 3
    },
    {
      "x": -63,
      "y": 5,
      "z": -21,
      "name": "Wood_Deadwood_Planks"
    },
    {
      "x": -63,
      "y": 6,
      "z": -21,
      "name": "Wood_Deadwood_Planks"
    },
    {
      "x": -63,
      "y": 7,
      "z": -21,
      "name": "Wood_Deadwood_Planks"
    },
    {
      "x": -63,
      "y": 8,
      "z": -21,
      "name": "Wood_Deadwood_Planks"
    },
    {
      "x": -63,
      "y": 9,
      "z": -21,
      "name": "Wood_Deadwood_Planks"
    },
    {
      "x": -63,
      "y": 10,
      "z": -21,
      "name": "Wood_Deadwood_Planks"
    },
    {
      "x": -63,
      "y": 11,
      "z": -21,
      "name": "Wood_Deadwood_Planks"
    },
    {
      "x": -63,
      "y": 12,
      "z": -21,
      "name": "Wood_Deadwood_Planks"
    },
    {
      "x": -63,
      "y": 13,
      "z": -21,
      "name": "Wood_Deadwood_Planks"
    },
    {
      "x": -63,
      "y": 14,
      "z": -21,
      "name": "Wood_Deadwood_Planks"
    },
    {
      "x": -63,
      "y": 15,
      "z": -21,
      "name": "Rock_Calcite_Cobble_Roof_Shallow",
      "rotation": 3
    },
    {
      "x": -63,
      "y": 5,
      "z": -20,
      "name": "Wood_Deadwood_Planks"
    },
    {
      "x": -63,
      "y": 6,
      "z": -20,
      "name": "Wood_Deadwood_Planks"
    },
    {
      "x": -63,
      "y": 7,
      "z": -20,
      "name": "Wood_Deadwood_Planks"
    },
    {
      "x": -63,
      "y": 8,
      "z": -20,
      "name": "Wood_Deadwood_Planks"
    },
    {
      "x": -63,
      "y": 9,
      "z": -20,
      "name": "Wood_Deadwood_Planks"
    },
    {
      "x": -63,
      "y": 10,
      "z": -20,
      "name": "Wood_Deadwood_Planks"
    },
    {
      "x": -63,
      "y": 11,
      "z": -20,
      "name": "Wood_Deadwood_Planks"
    },
    {
      "x": -63,
      "y": 12,
      "z": -20,
      "name": "Wood_Deadwood_Planks"
    },
    {
      "x": -63,
      "y": 13,
      "z": -20,
      "name": "Wood_Deadwood_Planks"
    },
    {
      "x": -63,
      "y": 14,
      "z": -20,
      "name": "Wood_Deadwood_Planks"
    },
    {
      "x": -63,
      "y": 15,
      "z": -20,
      "name": "Rock_Calcite_Cobble_Roof_Shallow",
      "rotation": 3
    },
    {
      "x": -63,
      "y": 5,
      "z": -19,
      "name": "Wood_Deadwood_Planks"
    },
    {
      "x": -63,
      "y": 6,
      "z": -19,
      "name": "Wood_Deadwood_Planks"
    },
    {
      "x": -63,
      "y": 7,
      "z": -19,
      "name": "Wood_Deadwood_Planks"
    },
    {
      "x": -63,
      "y": 8,
      "z": -19,
      "name": "Wood_Deadwood_Planks"
    },
    {
      "x": -63,
      "y": 9,
      "z": -19,
      "name": "Wood_Deadwood_Planks"
    },
    {
      "x": -63,
      "y": 10,
      "z": -19,
      "name": "Wood_Deadwood_Planks"
    },
    {
      "x": -63,
      "y": 11,
      "z": -19,
      "name": "Wood_Deadwood_Planks"
    },
    {
      "x": -63,
      "y": 12,
      "z": -19,
      "name": "Wood_Deadwood_Planks"
    },
    {
      "x": -63,
      "y": 13,
      "z": -19,
      "name": "Wood_Deadwood_Planks"
    },
    {
      "x": -63,
      "y": 14,
      "z": -19,
      "name": "Wood_Deadwood_Planks"
    },
    {
      "x": -63,
      "y": 15,
      "z": -19,
      "name": "Rock_Calcite_Cobble_Roof_Shallow",
      "rotation": 3
    },
    {
      "x": -63,
      "y": 5,
      "z": -18,
      "name": "Wood_Deadwood_Planks"
    },
    {
      "x": -63,
      "y": 6,
      "z": -18,
      "name": "Wood_Deadwood_Planks"
    },
    {
      "x": -63,
      "y": 7,
      "z": -18,
      "name": "Wood_Deadwood_Planks"
    },
    {
      "x": -63,
      "y": 8,
      "z": -18,
      "name": "Wood_Deadwood_Planks"
    },
    {
      "x": -63,
      "y": 9,
      "z": -18,
      "name": "Wood_Deadwood_Planks"
    },
    {
      "x": -63,
      "y": 10,
      "z": -18,
      "name": "Wood_Deadwood_Planks"
    },
    {
      "x": -63,
      "y": 11,
      "z": -18,
      "name": "Wood_Deadwood_Planks"
    },
    {
      "x": -63,
      "y": 12,
      "z": -18,
      "name": "Wood_Deadwood_Planks"
    },
    {
      "x": -63,
      "y": 13,
      "z": -18,
      "name": "Wood_Deadwood_Planks"
    },
    {
      "x": -63,
      "y": 14,
      "z": -18,
      "name": "Wood_Deadwood_Planks"
    },
    {
      "x": -63,
      "y": 15,
      "z": -18,
      "name": "Rock_Calcite_Cobble_Roof_Shallow",
      "rotation": 3
    },
    {
      "x": -63,
      "y": 5,
      "z": -17,
      "name": "Wood_Deadwood_Planks"
    },
    {
      "x": -63,
      "y": 6,
      "z": -17,
      "name": "Wood_Deadwood_Planks"
    },
    {
      "x": -63,
      "y": 7,
      "z": -17,
      "name": "Wood_Deadwood_Planks"
    },
    {
      "x": -63,
      "y": 8,
      "z": -17,
      "name": "Wood_Deadwood_Planks"
    },
    {
      "x": -63,
      "y": 9,
      "z": -17,
      "name": "Wood_Deadwood_Planks"
    },
    {
      "x": -63,
      "y": 10,
      "z": -17,
      "name": "Wood_Deadwood_Planks"
    },
    {
      "x": -63,
      "y": 11,
      "z": -17,
      "name": "Wood_Deadwood_Planks"
    },
    {
      "x": -63,
      "y": 12,
      "z": -17,
      "name": "Wood_Deadwood_Planks"
    },
    {
      "x": -63,
      "y": 13,
      "z": -17,
      "name": "Wood_Deadwood_Planks"
    },
    {
      "x": -63,
      "y": 14,
      "z": -17,
      "name": "Wood_Deadwood_Planks"
    },
    {
      "x": -63,
      "y": 15,
      "z": -17,
      "name": "Rock_Calcite_Cobble_Roof_Shallow",
      "rotation": 3
    },
    {
      "x": -63,
      "y": 14,
      "z": -16,
      "name": "Wood_Deadwood_Planks"
    },
    {
      "x": -63,
      "y": 15,
      "z": -16,
      "name": "Rock_Calcite_Cobble_Roof_Shallow",
      "rotation": 3
    },
    {
      "x": -63,
      "y": 14,
      "z": -15,
      "name": "Wood_Deadwood_Planks"
    },
    {
      "x": -63,
      "y": 15,
      "z": -15,
      "name": "Rock_Calcite_Cobble_Roof_Shallow",
      "rotation": 3
    },
    {
      "x": -63,
      "y": 14,
      "z": -14,
      "name": "Wood_Deadwood_Planks"
    },
    {
      "x": -63,
      "y": 15,
      "z": -14,
      "name": "Rock_Calcite_Cobble_Roof_Shallow",
      "rotation": 3
    },
    {
      "x": -63,
      "y": 14,
      "z": -13,
      "name": "Wood_Deadwood_Planks"
    },
    {
      "x": -63,
      "y": 15,
      "z": -13,
      "name": "Rock_Calcite_Cobble_Roof_Shallow",
      "rotation": 3
    },
    {
      "x": -63,
      "y": 14,
      "z": -12,
      "name": "Wood_Deadwood_Planks"
    },
    {
      "x": -63,
      "y": 15,
      "z": -12,
      "name": "Rock_Calcite_Cobble_Roof_Shallow",
      "rotation": 3
    },
    {
      "x": -63,
      "y": 14,
      "z": -11,
      "name": "Wood_Deadwood_Planks"
    },
    {
      "x": -63,
      "y": 15,
      "z": -11,
      "name": "Rock_Calcite_Cobble_Roof_Shallow",
      "rotation": 3
    },
    {
      "x": -63,
      "y": 14,
      "z": -10,
      "name": "Wood_Deadwood_Planks"
    },
    {
      "x": -63,
      "y": 15,
      "z": -10,
      "name": "Rock_Calcite_Cobble_Roof_Shallow",
      "rotation": 3
    },
    {
      "x": -63,
      "y": 14,
      "z": -9,
      "name": "Wood_Deadwood_Planks"
    },
    {
      "x": -63,
      "y": 15,
      "z": -9,
      "name": "Rock_Calcite_Cobble_Roof_Shallow",
      "rotation": 3
    },
    {
      "x": -63,
      "y": 14,
      "z": -8,
      "name": "Wood_Deadwood_Planks"
    },
    {
      "x": -63,
      "y": 15,
      "z": -8,
      "name": "Rock_Calcite_Cobble_Roof_Shallow",
      "rotation": 3
    },
    {
      "x": -63,
      "y": 14,
      "z": -7,
      "name": "Wood_Deadwood_Planks"
    },
    {
      "x": -63,
      "y": 15,
      "z": -7,
      "name": "Rock_Calcite_Cobble_Roof_Shallow",
      "rotation": 3
    },
    {
      "x": -63,
      "y": 18,
      "z": -7,
      "name": "Rock_Calcite_Cobble_Roof_Hollow",
      "rotation": 2
    },
    {
      "x": -63,
      "y": 18,
      "z": -6,
      "name": "Wood_Deadwood_Planks"
    },
    {
      "x": -63,
      "y": 19,
      "z": -6,
      "name": "Rock_Calcite_Cobble_Roof_Steep",
      "rotation": 2
    },
    {
      "x": -63,
      "y": 20,
      "z": -6,
      "name": "Rock_Calcite_Cobble_Roof_Steep",
      "filler": 1024,
      "rotation": 2
    },
    {
      "x": -63,
      "y": 20,
      "z": -5,
      "name": "Wood_Deadwood_Planks"
    },
    {
      "x": -63,
      "y": 21,
      "z": -5,
      "name": "Rock_Calcite_Cobble_Roof_Steep",
      "rotation": 2
    },
    {
      "x": -63,
      "y": 22,
      "z": -5,
      "name": "Rock_Calcite_Cobble_Roof_Steep",
      "filler": 1024,
      "rotation": 2
    },
    {
      "x": -63,
      "y": 22,
      "z": -4,
      "name": "Wood_Deadwood_Planks"
    },
    {
      "x": -63,
      "y": 23,
      "z": -4,
      "name": "*Rock_Calcite_Cobble_Roof_Steep_State_Definitions_Corner_Right",
      "rotation": 3
    },
    {
      "x": -63,
      "y": 24,
      "z": -4,
      "name": "*Rock_Calcite_Cobble_Roof_Steep_State_Definitions_Corner_Right",
      "filler": 1024,
      "rotation": 3
    },
    {
      "x": -63,
      "y": 22,
      "z": -3,
      "name": "Wood_Deadwood_Planks"
    },
    {
      "x": -63,
      "y": 23,
      "z": -3,
      "name": "Rock_Calcite_Cobble_Roof_Steep",
      "rotation": 3
    },
    {
      "x": -63,
      "y": 24,
      "z": -3,
      "name": "Rock_Calcite_Cobble_Roof_Steep",
      "filler": 1024,
      "rotation": 3
    },
    {
      "x": -63,
      "y": 22,
      "z": -2,
      "name": "Wood_Deadwood_Planks"
    },
    {
      "x": -63,
      "y": 23,
      "z": -2,
      "name": "Rock_Calcite_Cobble_Roof_Steep",
      "rotation": 3
    },
    {
      "x": -63,
      "y": 24,
      "z": -2,
      "name": "Rock_Calcite_Cobble_Roof_Steep",
      "filler": 1024,
      "rotation": 3
    },
    {
      "x": -63,
      "y": 22,
      "z": -1,
      "name": "Wood_Deadwood_Planks"
    },
    {
      "x": -63,
      "y": 23,
      "z": -1,
      "name": "Rock_Calcite_Cobble_Roof_Steep",
      "rotation": 3
    },
    {
      "x": -63,
      "y": 24,
      "z": -1,
      "name": "Rock_Calcite_Cobble_Roof_Steep",
      "filler": 1024,
      "rotation": 3
    },
    {
      "x": -63,
      "y": 22,
      "z": 0,
      "name": "Wood_Deadwood_Planks"
    },
    {
      "x": -63,
      "y": 23,
      "z": 0,
      "name": "Rock_Calcite_Cobble_Roof_Steep",
      "rotation": 3
    },
    {
      "x": -63,
      "y": 24,
      "z": 0,
      "name": "Rock_Calcite_Cobble_Roof_Steep",
      "filler": 1024,
      "rotation": 3
    },
    {
      "x": -63,
      "y": 22,
      "z": 1,
      "name": "Wood_Deadwood_Planks"
    },
    {
      "x": -63,
      "y": 23,
      "z": 1,
      "name": "Rock_Calcite_Cobble_Roof_Steep",
      "rotation": 3
    },
    {
      "x": -63,
      "y": 24,
      "z": 1,
      "name": "Rock_Calcite_Cobble_Roof_Steep",
      "filler": 1024,
      "rotation": 3
    },
    {
      "x": -63,
      "y": 22,
      "z": 2,
      "name": "Wood_Deadwood_Planks"
    },
    {
      "x": -63,
      "y": 23,
      "z": 2,
      "name": "Rock_Calcite_Cobble_Roof_Steep",
      "rotation": 3
    },
    {
      "x": -63,
      "y": 24,
      "z": 2,
      "name": "Rock_Calcite_Cobble_Roof_Steep",
      "filler": 1024,
      "rotation": 3
    },
    {
      "x": -63,
      "y": 22,
      "z": 3,
      "name": "Wood_Deadwood_Planks"
    },
    {
      "x": -63,
      "y": 23,
      "z": 3,
      "name": "Rock_Calcite_Cobble_Roof_Steep",
      "rotation": 3
    },
    {
      "x": -63,
      "y": 24,
      "z": 3,
      "name": "Rock_Calcite_Cobble_Roof_Steep",
      "filler": 1024,
      "rotation": 3
    },
    {
      "x": -63,
      "y": 22,
      "z": 4,
      "name": "Wood_Deadwood_Planks"
    },
    {
      "x": -63,
      "y": 23,
      "z": 4,
      "name": "Rock_Calcite_Cobble_Roof_Steep",
      "rotation": 3
    },
    {
      "x": -63,
      "y": 24,
      "z": 4,
      "name": "Rock_Calcite_Cobble_Roof_Steep",
      "filler": 1024,
      "rotation": 3
    },
    {
      "x": -63,
      "y": 22,
      "z": 5,
      "name": "Wood_Deadwood_Planks"
    },
    {
      "x": -63,
      "y": 23,
      "z": 5,
      "name": "*Rock_Calcite_Cobble_Roof_Steep_State_Definitions_Corner_Right"
    },
    {
      "x": -63,
      "y": 24,
      "z": 5,
      "name": "*Rock_Calcite_Cobble_Roof_Steep_State_Definitions_Corner_Right",
      "filler": 1024
    },
    {
      "x": -63,
      "y": 20,
      "z": 6,
      "name": "Wood_Deadwood_Planks"
    },
    {
      "x": -63,
      "y": 21,
      "z": 6,
      "name": "Rock_Calcite_Cobble_Roof_Steep"
    },
    {
      "x": -63,
      "y": 22,
      "z": 6,
      "name": "Rock_Calcite_Cobble_Roof_Steep",
      "filler": 1024
    },
    {
      "x": -63,
      "y": 18,
      "z": 7,
      "name": "Wood_Deadwood_Planks"
    },
    {
      "x": -63,
      "y": 19,
      "z": 7,
      "name": "Rock_Calcite_Cobble_Roof_Steep"
    },
    {
      "x": -63,
      "y": 20,
      "z": 7,
      "name": "Rock_Calcite_Cobble_Roof_Steep",
      "filler": 1024
    },
    {
      "x": -63,
      "y": 18,
      "z": 8,
      "name": "Rock_Calcite_Cobble_Roof_Hollow"
    },
    {
      "x": -63,
      "y": 11,
      "z": 10,
      "name": "Rock_Calcite_Cobble_Roof_Hollow",
      "rotation": 2
    },
    {
      "x": -63,
      "y": 11,
      "z": 11,
      "name": "Wood_Deadwood_Planks"
    },
    {
      "x": -63,
      "y": 12,
      "z": 11,
      "name": "Rock_Calcite_Cobble_Roof",
      "rotation": 2
    },
    {
      "x": -63,
      "y": 12,
      "z": 12,
      "name": "Wood_Deadwood_Planks"
    },
    {
      "x": -63,
      "y": 13,
      "z": 12,
      "name": "Rock_Calcite_Cobble_Roof",
      "rotation": 2
    },
    {
      "x": -63,
      "y": 13,
      "z": 13,
      "name": "Wood_Deadwood_Planks"
    },
    {
      "x": -63,
      "y": 14,
      "z": 13,
      "name": "*Rock_Calcite_Cobble_Roof_Shallow_State_Definitions_Corner_Left",
      "rotation": 2
    },
    {
      "x": -63,
      "y": 13,
      "z": 14,
      "name": "Wood_Deadwood_Planks"
    },
    {
      "x": -63,
      "y": 14,
      "z": 14,
      "name": "*Rock_Calcite_Cobble_Roof_Shallow_State_Definitions_Corner_Left",
      "filler": 32,
      "rotation": 2
    },
    {
      "x": -63,
      "y": 13,
      "z": 15,
      "name": "Wood_Deadwood_Planks"
    },
    {
      "x": -63,
      "y": 14,
      "z": 15,
      "name": "Rock_Calcite_Cobble_Roof_Shallow",
      "rotation": 3
    },
    {
      "x": -63,
      "y": 13,
      "z": 16,
      "name": "Wood_Deadwood_Planks"
    },
    {
      "x": -63,
      "y": 14,
      "z": 16,
      "name": "Rock_Calcite_Cobble_Roof_Shallow",
      "rotation": 3
    },
    {
      "x": -63,
      "y": 13,
      "z": 17,
      "name": "Wood_Deadwood_Planks"
    },
    {
      "x": -63,
      "y": 14,
      "z": 17,
      "name": "Rock_Calcite_Cobble_Roof_Shallow",
      "rotation": 3
    },
    {
      "x": -63,
      "y": 13,
      "z": 18,
      "name": "Wood_Deadwood_Planks"
    },
    {
      "x": -63,
      "y": 14,
      "z": 18,
      "name": "Rock_Calcite_Cobble_Roof_Shallow",
      "rotation": 3
    },
    {
      "x": -63,
      "y": 13,
      "z": 19,
      "name": "Wood_Deadwood_Planks"
    },
    {
      "x": -63,
      "y": 14,
      "z": 19,
      "name": "Rock_Calcite_Cobble_Roof_Shallow",
      "rotation": 3
    },
    {
      "x": -63,
      "y": 13,
      "z": 20,
      "name": "Wood_Deadwood_Planks"
    },
    {
      "x": -63,
      "y": 14,
      "z": 20,
      "name": "Rock_Calcite_Cobble_Roof_Shallow",
      "rotation": 3
    },
    {
      "x": -63,
      "y": 13,
      "z": 21,
      "name": "Wood_Deadwood_Planks"
    },
    {
      "x": -63,
      "y": 14,
      "z": 21,
      "name": "Rock_Calcite_Cobble_Roof_Shallow",
      "rotation": 3
    },
    {
      "x": -63,
      "y": 13,
      "z": 22,
      "name": "Wood_Deadwood_Planks"
    },
    {
      "x": -63,
      "y": 14,
      "z": 22,
      "name": "Rock_Calcite_Cobble_Roof_Shallow",
      "rotation": 3
    },
    {
      "x": -63,
      "y": 13,
      "z": 23,
      "name": "Wood_Deadwood_Planks"
    },
    {
      "x": -63,
      "y": 14,
      "z": 23,
      "name": "Rock_Calcite_Cobble_Roof_Shallow",
      "rotation": 3
    },
    {
      "x": -63,
      "y": 13,
      "z": 24,
      "name": "Wood_Deadwood_Planks"
    },
    {
      "x": -63,
      "y": 14,
      "z": 24,
      "name": "Rock_Calcite_Cobble_Roof_Shallow",
      "rotation": 3
    },
    {
      "x": -63,
      "y": 13,
      "z": 25,
      "name": "Wood_Deadwood_Planks"
    },
    {
      "x": -63,
      "y": 14,
      "z": 25,
      "name": "Rock_Calcite_Cobble_Roof_Shallow",
      "rotation": 3
    },
    {
      "x": -63,
      "y": 13,
      "z": 26,
      "name": "Wood_Deadwood_Planks"
    },
    {
      "x": -63,
      "y": 14,
      "z": 26,
      "name": "Rock_Calcite_Cobble_Roof_Shallow",
      "rotation": 3
    },
    {
      "x": -63,
      "y": 13,
      "z": 27,
      "name": "Wood_Deadwood_Planks"
    },
    {
      "x": -63,
      "y": 14,
      "z": 27,
      "name": "Rock_Calcite_Cobble_Roof_Shallow",
      "rotation": 3
    },
    {
      "x": -63,
      "y": 13,
      "z": 28,
      "name": "Wood_Deadwood_Planks"
    },
    {
      "x": -63,
      "y": 14,
      "z": 28,
      "name": "Rock_Calcite_Cobble_Roof_Shallow",
      "rotation": 3
    },
    {
      "x": -63,
      "y": 13,
      "z": 29,
      "name": "Wood_Deadwood_Planks"
    },
    {
      "x": -63,
      "y": 14,
      "z": 29,
      "name": "*Rock_Calcite_Cobble_Roof_Shallow_State_Definitions_Corner_Left",
      "filler": 992,
      "rotation": 3
    },
    {
      "x": -63,
      "y": 13,
      "z": 30,
      "name": "Wood_Deadwood_Planks"
    },
    {
      "x": -63,
      "y": 14,
      "z": 30,
      "name": "*Rock_Calcite_Cobble_Roof_Shallow_State_Definitions_Corner_Left",
      "rotation": 3
    },
    {
      "x": -63,
      "y": 12,
      "z": 31,
      "name": "Wood_Deadwood_Planks"
    },
    {
      "x": -63,
      "y": 13,
      "z": 31,
      "name": "Rock_Calcite_Cobble_Roof"
    },
    {
      "x": -63,
      "y": 11,
      "z": 32,
      "name": "Wood_Deadwood_Planks"
    },
    {
      "x": -63,
      "y": 12,
      "z": 32,
      "name": "Rock_Calcite_Cobble_Roof"
    },
    {
      "x": -63,
      "y": 11,
      "z": 33,
      "name": "Rock_Calcite_Cobble_Roof_Hollow"
    },
    {
      "x": -62,
      "y": 5,
      "z": -22,
      "name": "Wood_Deadwood_Planks"
    },
    {
      "x": -62,
      "y": 6,
      "z": -22,
      "name": "Wood_Deadwood_Planks"
    },
    {
      "x": -62,
      "y": 7,
      "z": -22,
      "name": "Wood_Deadwood_Planks"
    },
    {
      "x": -62,
      "y": 8,
      "z": -22,
      "name": "Wood_Deadwood_Planks"
    },
    {
      "x": -62,
      "y": 9,
      "z": -22,
      "name": "Wood_Deadwood_Planks"
    },
    {
      "x": -62,
      "y": 10,
      "z": -22,
      "name": "Wood_Deadwood_Planks"
    },
    {
      "x": -62,
      "y": 11,
      "z": -22,
      "name": "Wood_Deadwood_Planks"
    },
    {
      "x": -62,
      "y": 12,
      "z": -22,
      "name": "Wood_Deadwood_Planks"
    },
    {
      "x": -62,
      "y": 13,
      "z": -22,
      "name": "Wood_Deadwood_Planks"
    },
    {
      "x": -62,
      "y": 14,
      "z": -22,
      "name": "Wood_Deadwood_Planks"
    },
    {
      "x": -62,
      "y": 15,
      "z": -22,
      "name": "Rock_Calcite_Cobble_Roof_Shallow",
      "filler": 1,
      "rotation": 3
    },
    {
      "x": -62,
      "y": 5,
      "z": -21,
      "name": "Wood_Deadwood_Planks"
    },
    {
      "x": -62,
      "y": 11,
      "z": -21,
      "name": "Wood_Deadwood_Planks"
    },
    {
      "x": -62,
      "y": 15,
      "z": -21,
      "name": "Rock_Calcite_Cobble_Roof_Shallow",
      "filler": 1,
      "rotation": 3
    },
    {
      "x": -62,
      "y": 5,
      "z": -20,
      "name": "Wood_Deadwood_Planks"
    },
    {
      "x": -62,
      "y": 11,
      "z": -20,
      "name": "Wood_Deadwood_Planks"
    },
    {
      "x": -62,
      "y": 15,
      "z": -20,
      "name": "Rock_Calcite_Cobble_Roof_Shallow",
      "filler": 1,
      "rotation": 3
    },
    {
      "x": -62,
      "y": 5,
      "z": -19,
      "name": "Wood_Deadwood_Planks"
    },
    {
      "x": -62,
      "y": 11,
      "z": -19,
      "name": "Wood_Deadwood_Planks"
    },
    {
      "x": -62,
      "y": 15,
      "z": -19,
      "name": "Rock_Calcite_Cobble_Roof_Shallow",
      "filler": 1,
      "rotation": 3
    },
    {
      "x": -62,
      "y": 5,
      "z": -18,
      "name": "Wood_Deadwood_Planks"
    },
    {
      "x": -62,
      "y": 11,
      "z": -18,
      "name": "Wood_Deadwood_Planks"
    },
    {
      "x": -62,
      "y": 15,
      "z": -18,
      "name": "Rock_Calcite_Cobble_Roof_Shallow",
      "filler": 1,
      "rotation": 3
    },
    {
      "x": -62,
      "y": 5,
      "z": -17,
      "name": "Wood_Deadwood_Planks"
    },
    {
      "x": -62,
      "y": 6,
      "z": -17,
      "name": "Wood_Deadwood_Planks"
    },
    {
      "x": -62,
      "y": 7,
      "z": -17,
      "name": "Wood_Deadwood_Planks"
    },
    {
      "x": -62,
      "y": 8,
      "z": -17,
      "name": "Wood_Deadwood_Planks"
    },
    {
      "x": -62,
      "y": 9,
      "z": -17,
      "name": "Wood_Deadwood_Planks"
    },
    {
      "x": -62,
      "y": 10,
      "z": -17,
      "name": "Wood_Deadwood_Planks"
    },
    {
      "x": -62,
      "y": 11,
      "z": -17,
      "name": "Wood_Deadwood_Planks"
    },
    {
      "x": -62,
      "y": 12,
      "z": -17,
      "name": "Wood_Deadwood_Planks"
    },
    {
      "x": -62,
      "y": 13,
      "z": -17,
      "name": "Wood_Deadwood_Planks"
    },
    {
      "x": -62,
      "y": 15,
      "z": -17,
      "name": "Rock_Calcite_Cobble_Roof_Shallow",
      "filler": 1,
      "rotation": 3
    },
    {
      "x": -62,
      "y": 15,
      "z": -16,
      "name": "Rock_Calcite_Cobble_Roof_Shallow",
      "filler": 1,
      "rotation": 3
    },
    {
      "x": -62,
      "y": 15,
      "z": -15,
      "name": "Rock_Calcite_Cobble_Roof_Shallow",
      "filler": 1,
      "rotation": 3
    },
    {
      "x": -62,
      "y": 15,
      "z": -14,
      "name": "Rock_Calcite_Cobble_Roof_Shallow",
      "filler": 1,
      "rotation": 3
    },
    {
      "x": -62,
      "y": 15,
      "z": -13,
      "name": "Rock_Calcite_Cobble_Roof_Shallow",
      "filler": 1,
      "rotation": 3
    },
    {
      "x": -62,
      "y": 15,
      "z": -12,
      "name": "Rock_Calcite_Cobble_Roof_Shallow",
      "filler": 1,
      "rotation": 3
    },
    {
      "x": -62,
      "y": 15,
      "z": -11,
      "name": "Rock_Calcite_Cobble_Roof_Shallow",
      "filler": 1,
      "rotation": 3
    },
    {
      "x": -62,
      "y": 15,
      "z": -10,
      "name": "Rock_Calcite_Cobble_Roof_Shallow",
      "filler": 1,
      "rotation": 3
    },
    {
      "x": -62,
      "y": 15,
      "z": -9,
      "name": "Rock_Calcite_Cobble_Roof_Shallow",
      "filler": 1,
      "rotation": 3
    },
    {
      "x": -62,
      "y": 15,
      "z": -8,
      "name": "Rock_Calcite_Cobble_Roof_Shallow",
      "filler": 1,
      "rotation": 3
    },
    {
      "x": -62,
      "y": 14,
      "z": -7,
      "name": "Wood_Deadwood_Planks"
    },
    {
      "x": -62,
      "y": 15,
      "z": -7,
      "name": "Rock_Calcite_Cobble_Roof_Shallow",
      "filler": 1,
      "rotation": 3
    },
    {
      "x": -62,
      "y": 18,
      "z": -7,
      "name": "Rock_Calcite_Cobble_Roof_Hollow",
      "rotation": 2
    },
    {
      "x": -62,
      "y": 18,
      "z": -6,
      "name": "Wood_Deadwood_Planks"
    },
    {
      "x": -62,
      "y": 19,
      "z": -6,
      "name": "Rock_Calcite_Cobble_Roof_Steep",
      "rotation": 2
    },
    {
      "x": -62,
      "y": 20,
      "z": -6,
      "name": "Rock_Calcite_Cobble_Roof_Steep",
      "filler": 1024,
      "rotation": 2
    },
    {
      "x": -62,
      "y": 20,
      "z": -5,
      "name": "Wood_Deadwood_Planks"
    },
    {
      "x": -62,
      "y": 21,
      "z": -5,
      "name": "Rock_Calcite_Cobble_Roof_Steep",
      "rotation": 2
    },
    {
      "x": -62,
      "y": 22,
      "z": -5,
      "name": "Rock_Calcite_Cobble_Roof_Steep",
      "filler": 1024,
      "rotation": 2
    },
    {
      "x": -62,
      "y": 22,
      "z": -4,
      "name": "Wood_Deadwood_Planks"
    },
    {
      "x": -62,
      "y": 23,
      "z": -4,
      "name": "Rock_Calcite_Cobble_Roof_Steep",
      "rotation": 2
    },
    {
      "x": -62,
      "y": 24,
      "z": -4,
      "name": "Rock_Calcite_Cobble_Roof_Steep",
      "filler": 1024,
      "rotation": 2
    },
    {
      "x": -62,
      "y": 24,
      "z": -3,
      "name": "Wood_Deadwood_Planks"
    },
    {
      "x": -62,
      "y": 25,
      "z": -3,
      "name": "*Rock_Calcite_Cobble_Roof_Steep_State_Definitions_Corner_Right",
      "rotation": 3
    },
    {
      "x": -62,
      "y": 26,
      "z": -3,
      "name": "*Rock_Calcite_Cobble_Roof_Steep_State_Definitions_Corner_Right",
      "filler": 1024,
      "rotation": 3
    },
    {
      "x": -62,
      "y": 24,
      "z": -2,
      "name": "Wood_Deadwood_Planks"
    },
    {
      "x": -62,
      "y": 25,
      "z": -2,
      "name": "Rock_Calcite_Cobble_Roof_Steep",
      "rotation": 3
    },
    {
      "x": -62,
      "y": 26,
      "z": -2,
      "name": "Rock_Calcite_Cobble_Roof_Steep",
      "filler": 1024,
      "rotation": 3
    },
    {
      "x": -62,
      "y": 24,
      "z": -1,
      "name": "Wood_Deadwood_Planks"
    },
    {
      "x": -62,
      "y": 25,
      "z": -1,
      "name": "Rock_Calcite_Cobble_Roof_Steep",
      "rotation": 3
    },
    {
      "x": -62,
      "y": 26,
      "z": -1,
      "name": "Rock_Calcite_Cobble_Roof_Steep",
      "filler": 1024,
      "rotation": 3
    },
    {
      "x": -62,
      "y": 24,
      "z": 0,
      "name": "Wood_Deadwood_Planks"
    },
    {
      "x": -62,
      "y": 25,
      "z": 0,
      "name": "Rock_Calcite_Cobble_Roof_Steep",
      "rotation": 3
    },
    {
      "x": -62,
      "y": 26,
      "z": 0,
      "name": "Rock_Calcite_Cobble_Roof_Steep",
      "filler": 1024,
      "rotation": 3
    },
    {
      "x": -62,
      "y": 24,
      "z": 1,
      "name": "Wood_Deadwood_Planks"
    },
    {
      "x": -62,
      "y": 25,
      "z": 1,
      "name": "Rock_Calcite_Cobble_Roof_Steep",
      "rotation": 3
    },
    {
      "x": -62,
      "y": 26,
      "z": 1,
      "name": "Rock_Calcite_Cobble_Roof_Steep",
      "filler": 1024,
      "rotation": 3
    },
    {
      "x": -62,
      "y": 24,
      "z": 2,
      "name": "Wood_Deadwood_Planks"
    },
    {
      "x": -62,
      "y": 25,
      "z": 2,
      "name": "Rock_Calcite_Cobble_Roof_Steep",
      "rotation": 3
    },
    {
      "x": -62,
      "y": 26,
      "z": 2,
      "name": "Rock_Calcite_Cobble_Roof_Steep",
      "filler": 1024,
      "rotation": 3
    },
    {
      "x": -62,
      "y": 24,
      "z": 3,
      "name": "Wood_Deadwood_Planks"
    },
    {
      "x": -62,
      "y": 25,
      "z": 3,
      "name": "Rock_Calcite_Cobble_Roof_Steep",
      "rotation": 3
    },
    {
      "x": -62,
      "y": 26,
      "z": 3,
      "name": "Rock_Calcite_Cobble_Roof_Steep",
      "filler": 1024,
      "rotation": 3
    },
    {
      "x": -62,
      "y": 24,
      "z": 4,
      "name": "Wood_Deadwood_Planks"
    },
    {
      "x": -62,
      "y": 25,
      "z": 4,
      "name": "*Rock_Calcite_Cobble_Roof_Steep_State_Definitions_Corner_Right"
    },
    {
      "x": -62,
      "y": 26,
      "z": 4,
      "name": "*Rock_Calcite_Cobble_Roof_Steep_State_Definitions_Corner_Right",
      "filler": 1024
    },
    {
      "x": -62,
      "y": 22,
      "z": 5,
      "name": "Wood_Deadwood_Planks"
    },
    {
      "x": -62,
      "y": 23,
      "z": 5,
      "name": "Rock_Calcite_Cobble_Roof_Steep"
    },
    {
      "x": -62,
      "y": 24,
      "z": 5,
      "name": "Rock_Calcite_Cobble_Roof_Steep",
      "filler": 1024
    },
    {
      "x": -62,
      "y": 20,
      "z": 6,
      "name": "Wood_Deadwood_Planks"
    },
    {
      "x": -62,
      "y": 21,
      "z": 6,
      "name": "Rock_Calcite_Cobble_Roof_Steep"
    },
    {
      "x": -62,
      "y": 22,
      "z": 6,
      "name": "Rock_Calcite_Cobble_Roof_Steep",
      "filler": 1024
    },
    {
      "x": -62,
      "y": 18,
      "z": 7,
      "name": "Wood_Deadwood_Planks"
    },
    {
      "x": -62,
      "y": 19,
      "z": 7,
      "name": "Rock_Calcite_Cobble_Roof_Steep"
    },
    {
      "x": -62,
      "y": 20,
      "z": 7,
      "name": "Rock_Calcite_Cobble_Roof_Steep",
      "filler": 1024
    },
    {
      "x": -62,
      "y": 18,
      "z": 8,
      "name": "Rock_Calcite_Cobble_Roof_Hollow"
    },
    {
      "x": -62,
      "y": 11,
      "z": 10,
      "name": "Rock_Calcite_Cobble_Roof_Hollow",
      "rotation": 2
    },
    {
      "x": -62,
      "y": 11,
      "z": 11,
      "name": "Wood_Deadwood_Planks"
    },
    {
      "x": -62,
      "y": 12,
      "z": 11,
      "name": "Rock_Calcite_Cobble_Roof",
      "rotation": 2
    },
    {
      "x": -62,
      "y": 12,
      "z": 12,
      "name": "Wood_Deadwood_Planks"
    },
    {
      "x": -62,
      "y": 13,
      "z": 12,
      "name": "Rock_Calcite_Cobble_Roof",
      "rotation": 2
    },
    {
      "x": -62,
      "y": 13,
      "z": 13,
      "name": "Wood_Deadwood_Planks"
    },
    {
      "x": -62,
      "y": 14,
      "z": 13,
      "name": "*Rock_Calcite_Cobble_Roof_Shallow_State_Definitions_Corner_Left",
      "filler": 1,
      "rotation": 2
    },
    {
      "x": -62,
      "y": 14,
      "z": 14,
      "name": "*Rock_Calcite_Cobble_Roof_Shallow_State_Definitions_Corner_Left",
      "filler": 33,
      "rotation": 2
    },
    {
      "x": -62,
      "y": 14,
      "z": 15,
      "name": "Rock_Calcite_Cobble_Roof_Shallow",
      "filler": 1,
      "rotation": 3
    },
    {
      "x": -62,
      "y": 14,
      "z": 16,
      "name": "Rock_Calcite_Cobble_Roof_Shallow",
      "filler": 1,
      "rotation": 3
    },
    {
      "x": -62,
      "y": 14,
      "z": 17,
      "name": "Rock_Calcite_Cobble_Roof_Shallow",
      "filler": 1,
      "rotation": 3
    },
    {
      "x": -62,
      "y": 14,
      "z": 18,
      "name": "Rock_Calcite_Cobble_Roof_Shallow",
      "filler": 1,
      "rotation": 3
    },
    {
      "x": -62,
      "y": 14,
      "z": 19,
      "name": "Rock_Calcite_Cobble_Roof_Shallow",
      "filler": 1,
      "rotation": 3
    },
    {
      "x": -62,
      "y": 14,
      "z": 20,
      "name": "Rock_Calcite_Cobble_Roof_Shallow",
      "filler": 1,
      "rotation": 3
    },
    {
      "x": -62,
      "y": 14,
      "z": 21,
      "name": "Rock_Calcite_Cobble_Roof_Shallow",
      "filler": 1,
      "rotation": 3
    },
    {
      "x": -62,
      "y": 14,
      "z": 22,
      "name": "Rock_Calcite_Cobble_Roof_Shallow",
      "filler": 1,
      "rotation": 3
    },
    {
      "x": -62,
      "y": 14,
      "z": 23,
      "name": "Rock_Calcite_Cobble_Roof_Shallow",
      "filler": 1,
      "rotation": 3
    },
    {
      "x": -62,
      "y": 14,
      "z": 24,
      "name": "Rock_Calcite_Cobble_Roof_Shallow",
      "filler": 1,
      "rotation": 3
    },
    {
      "x": -62,
      "y": 14,
      "z": 25,
      "name": "Rock_Calcite_Cobble_Roof_Shallow",
      "filler": 1,
      "rotation": 3
    },
    {
      "x": -62,
      "y": 14,
      "z": 26,
      "name": "Rock_Calcite_Cobble_Roof_Shallow",
      "filler": 1,
      "rotation": 3
    },
    {
      "x": -62,
      "y": 14,
      "z": 27,
      "name": "Rock_Calcite_Cobble_Roof_Shallow",
      "filler": 1,
      "rotation": 3
    },
    {
      "x": -62,
      "y": 14,
      "z": 28,
      "name": "Rock_Calcite_Cobble_Roof_Shallow",
      "filler": 1,
      "rotation": 3
    },
    {
      "x": -62,
      "y": 14,
      "z": 29,
      "name": "*Rock_Calcite_Cobble_Roof_Shallow_State_Definitions_Corner_Left",
      "filler": 993,
      "rotation": 3
    },
    {
      "x": -62,
      "y": 13,
      "z": 30,
      "name": "Wood_Deadwood_Planks"
    },
    {
      "x": -62,
      "y": 14,
      "z": 30,
      "name": "*Rock_Calcite_Cobble_Roof_Shallow_State_Definitions_Corner_Left",
      "filler": 1,
      "rotation": 3
    },
    {
      "x": -62,
      "y": 12,
      "z": 31,
      "name": "Wood_Deadwood_Planks"
    },
    {
      "x": -62,
      "y": 13,
      "z": 31,
      "name": "Rock_Calcite_Cobble_Roof"
    },
    {
      "x": -62,
      "y": 11,
      "z": 32,
      "name": "Wood_Deadwood_Planks"
    },
    {
      "x": -62,
      "y": 12,
      "z": 32,
      "name": "Rock_Calcite_Cobble_Roof"
    },
    {
      "x": -62,
      "y": 11,
      "z": 33,
      "name": "Rock_Calcite_Cobble_Roof_Hollow"
    },
    {
      "x": -61,
      "y": 5,
      "z": -22,
      "name": "Wood_Deadwood_Planks"
    },
    {
      "x": -61,
      "y": 6,
      "z": -22,
      "name": "Wood_Deadwood_Planks"
    },
    {
      "x": -61,
      "y": 7,
      "z": -22,
      "name": "Wood_Deadwood_Planks"
    },
    {
      "x": -61,
      "y": 8,
      "z": -22,
      "name": "Wood_Deadwood_Planks"
    },
    {
      "x": -61,
      "y": 9,
      "z": -22,
      "name": "Wood_Deadwood_Planks"
    },
    {
      "x": -61,
      "y": 10,
      "z": -22,
      "name": "Wood_Deadwood_Planks"
    },
    {
      "x": -61,
      "y": 11,
      "z": -22,
      "name": "Wood_Deadwood_Planks"
    },
    {
      "x": -61,
      "y": 12,
      "z": -22,
      "name": "Wood_Deadwood_Planks"
    },
    {
      "x": -61,
      "y": 13,
      "z": -22,
      "name": "Wood_Deadwood_Planks"
    },
    {
      "x": -61,
      "y": 14,
      "z": -22,
      "name": "Wood_Deadwood_Planks"
    },
    {
      "x": -61,
      "y": 15,
      "z": -22,
      "name": "Wood_Deadwood_Planks"
    },
    {
      "x": -61,
      "y": 16,
      "z": -22,
      "name": "Rock_Calcite_Cobble_Roof_Shallow",
      "rotation": 3
    },
    {
      "x": -61,
      "y": 5,
      "z": -21,
      "name": "Wood_Deadwood_Planks"
    },
    {
      "x": -61,
      "y": 11,
      "z": -21,
      "name": "Wood_Deadwood_Planks"
    },
    {
      "x": -61,
      "y": 15,
      "z": -21,
      "name": "Wood_Deadwood_Planks"
    },
    {
      "x": -61,
      "y": 16,
      "z": -21,
      "name": "Rock_Calcite_Cobble_Roof_Shallow",
      "rotation": 3
    },
    {
      "x": -61,
      "y": 5,
      "z": -20,
      "name": "Wood_Deadwood_Planks"
    },
    {
      "x": -61,
      "y": 11,
      "z": -20,
      "name": "Wood_Deadwood_Planks"
    },
    {
      "x": -61,
      "y": 15,
      "z": -20,
      "name": "Wood_Deadwood_Planks"
    },
    {
      "x": -61,
      "y": 16,
      "z": -20,
      "name": "Rock_Calcite_Cobble_Roof_Shallow",
      "rotation": 3
    },
    {
      "x": -61,
      "y": 5,
      "z": -19,
      "name": "Wood_Deadwood_Planks"
    },
    {
      "x": -61,
      "y": 11,
      "z": -19,
      "name": "Wood_Deadwood_Planks"
    },
    {
      "x": -61,
      "y": 15,
      "z": -19,
      "name": "Wood_Deadwood_Planks"
    },
    {
      "x": -61,
      "y": 16,
      "z": -19,
      "name": "Rock_Calcite_Cobble_Roof_Shallow",
      "rotation": 3
    },
    {
      "x": -61,
      "y": 5,
      "z": -18,
      "name": "Wood_Deadwood_Planks"
    },
    {
      "x": -61,
      "y": 11,
      "z": -18,
      "name": "Wood_Deadwood_Planks"
    },
    {
      "x": -61,
      "y": 15,
      "z": -18,
      "name": "Wood_Deadwood_Planks"
    },
    {
      "x": -61,
      "y": 16,
      "z": -18,
      "name": "Rock_Calcite_Cobble_Roof_Shallow",
      "rotation": 3
    },
    {
      "x": -61,
      "y": 5,
      "z": -17,
      "name": "Wood_Deadwood_Planks"
    },
    {
      "x": -61,
      "y": 6,
      "z": -17,
      "name": "Wood_Deadwood_Planks"
    },
    {
      "x": -61,
      "y": 7,
      "z": -17,
      "name": "Wood_Deadwood_Planks"
    },
    {
      "x": -61,
      "y": 8,
      "z": -17,
      "name": "Wood_Deadwood_Planks"
    },
    {
      "x": -61,
      "y": 9,
      "z": -17,
      "name": "Wood_Deadwood_Planks"
    },
    {
      "x": -61,
      "y": 10,
      "z": -17,
      "name": "Wood_Deadwood_Planks"
    },
    {
      "x": -61,
      "y": 11,
      "z": -17,
      "name": "Wood_Deadwood_Planks"
    },
    {
      "x": -61,
      "y": 12,
      "z": -17,
      "name": "Wood_Deadwood_Planks"
    },
    {
      "x": -61,
      "y": 13,
      "z": -17,
      "name": "Wood_Deadwood_Planks"
    },
    {
      "x": -61,
      "y": 15,
      "z": -17,
      "name": "Wood_Deadwood_Planks"
    },
    {
      "x": -61,
      "y": 16,
      "z": -17,
      "name": "Rock_Calcite_Cobble_Roof_Shallow",
      "rotation": 3
    },
    {
      "x": -61,
      "y": 15,
      "z": -16,
      "name": "Wood_Deadwood_Planks"
    },
    {
      "x": -61,
      "y": 16,
      "z": -16,
      "name": "Rock_Calcite_Cobble_Roof_Shallow",
      "rotation": 3
    },
    {
      "x": -61,
      "y": 15,
      "z": -15,
      "name": "Wood_Deadwood_Planks"
    },
    {
      "x": -61,
      "y": 16,
      "z": -15,
      "name": "Rock_Calcite_Cobble_Roof_Shallow",
      "rotation": 3
    },
    {
      "x": -61,
      "y": 15,
      "z": -14,
      "name": "Wood_Deadwood_Planks"
    },
    {
      "x": -61,
      "y": 16,
      "z": -14,
      "name": "Rock_Calcite_Cobble_Roof_Shallow",
      "rotation": 3
    },
    {
      "x": -61,
      "y": 15,
      "z": -13,
      "name": "Wood_Deadwood_Planks"
    },
    {
      "x": -61,
      "y": 16,
      "z": -13,
      "name": "Rock_Calcite_Cobble_Roof_Shallow",
      "rotation": 3
    },
    {
      "x": -61,
      "y": 15,
      "z": -12,
      "name": "Wood_Deadwood_Planks"
    },
    {
      "x": -61,
      "y": 16,
      "z": -12,
      "name": "Rock_Calcite_Cobble_Roof_Shallow",
      "rotation": 3
    },
    {
      "x": -61,
      "y": 15,
      "z": -11,
      "name": "Wood_Deadwood_Planks"
    },
    {
      "x": -61,
      "y": 16,
      "z": -11,
      "name": "Rock_Calcite_Cobble_Roof_Shallow",
      "rotation": 3
    },
    {
      "x": -61,
      "y": 15,
      "z": -10,
      "name": "Wood_Deadwood_Planks"
    },
    {
      "x": -61,
      "y": 16,
      "z": -10,
      "name": "Rock_Calcite_Cobble_Roof_Shallow",
      "rotation": 3
    },
    {
      "x": -61,
      "y": 15,
      "z": -9,
      "name": "Wood_Deadwood_Planks"
    },
    {
      "x": -61,
      "y": 16,
      "z": -9,
      "name": "Rock_Calcite_Cobble_Roof_Shallow",
      "rotation": 3
    },
    {
      "x": -61,
      "y": 15,
      "z": -8,
      "name": "Wood_Deadwood_Planks"
    },
    {
      "x": -61,
      "y": 16,
      "z": -8,
      "name": "Rock_Calcite_Cobble_Roof_Shallow",
      "rotation": 3
    },
    {
      "x": -61,
      "y": 14,
      "z": -7,
      "name": "Wood_Deadwood_Planks"
    },
    {
      "x": -61,
      "y": 15,
      "z": -7,
      "name": "Wood_Deadwood_Planks"
    },
    {
      "x": -61,
      "y": 16,
      "z": -7,
      "name": "Rock_Calcite_Cobble_Roof_Shallow",
      "rotation": 3
    },
    {
      "x": -61,
      "y": 18,
      "z": -7,
      "name": "Rock_Calcite_Cobble_Roof_Hollow",
      "rotation": 2
    },
    {
      "x": -61,
      "y": 18,
      "z": -6,
      "name": "Wood_Deadwood_Planks"
    },
    {
      "x": -61,
      "y": 19,
      "z": -6,
      "name": "Rock_Calcite_Cobble_Roof_Steep",
      "rotation": 2
    },
    {
      "x": -61,
      "y": 20,
      "z": -6,
      "name": "Rock_Calcite_Cobble_Roof_Steep",
      "filler": 1024,
      "rotation": 2
    },
    {
      "x": -61,
      "y": 20,
      "z": -5,
      "name": "Wood_Deadwood_Planks"
    },
    {
      "x": -61,
      "y": 21,
      "z": -5,
      "name": "Rock_Calcite_Cobble_Roof_Steep",
      "rotation": 2
    },
    {
      "x": -61,
      "y": 22,
      "z": -5,
      "name": "Rock_Calcite_Cobble_Roof_Steep",
      "filler": 1024,
      "rotation": 2
    },
    {
      "x": -61,
      "y": 22,
      "z": -4,
      "name": "Wood_Deadwood_Planks"
    },
    {
      "x": -61,
      "y": 23,
      "z": -4,
      "name": "Rock_Calcite_Cobble_Roof_Steep",
      "rotation": 2
    },
    {
      "x": -61,
      "y": 24,
      "z": -4,
      "name": "Rock_Calcite_Cobble_Roof_Steep",
      "filler": 1024,
      "rotation": 2
    },
    {
      "x": -61,
      "y": 24,
      "z": -3,
      "name": "Wood_Deadwood_Planks"
    },
    {
      "x": -61,
      "y": 25,
      "z": -3,
      "name": "Rock_Calcite_Cobble_Roof_Steep",
      "rotation": 2
    },
    {
      "x": -61,
      "y": 26,
      "z": -3,
      "name": "Rock_Calcite_Cobble_Roof_Steep",
      "filler": 1024,
      "rotation": 2
    },
    {
      "x": -61,
      "y": 26,
      "z": -2,
      "name": "Wood_Deadwood_Planks"
    },
    {
      "x": -61,
      "y": 27,
      "z": -2,
      "name": "*Rock_Calcite_Cobble_Roof_State_Definitions_Corner_Right",
      "rotation": 3
    },
    {
      "x": -61,
      "y": 26,
      "z": -1,
      "name": "Wood_Deadwood_Planks"
    },
    {
      "x": -61,
      "y": 27,
      "z": -1,
      "name": "Rock_Calcite_Cobble_Roof",
      "rotation": 3
    },
    {
      "x": -61,
      "y": 26,
      "z": 0,
      "name": "Wood_Deadwood_Planks"
    },
    {
      "x": -61,
      "y": 27,
      "z": 0,
      "name": "Rock_Calcite_Cobble_Roof",
      "rotation": 3
    },
    {
      "x": -61,
      "y": 26,
      "z": 1,
      "name": "Wood_Deadwood_Planks"
    },
    {
      "x": -61,
      "y": 27,
      "z": 1,
      "name": "Rock_Calcite_Cobble_Roof",
      "rotation": 3
    },
    {
      "x": -61,
      "y": 26,
      "z": 2,
      "name": "Wood_Deadwood_Planks"
    },
    {
      "x": -61,
      "y": 27,
      "z": 2,
      "name": "Rock_Calcite_Cobble_Roof",
      "rotation": 3
    },
    {
      "x": -61,
      "y": 26,
      "z": 3,
      "name": "Wood_Deadwood_Planks"
    },
    {
      "x": -61,
      "y": 27,
      "z": 3,
      "name": "*Rock_Calcite_Cobble_Roof_State_Definitions_Corner_Right"
    },
    {
      "x": -61,
      "y": 24,
      "z": 4,
      "name": "Wood_Deadwood_Planks"
    },
    {
      "x": -61,
      "y": 25,
      "z": 4,
      "name": "Rock_Calcite_Cobble_Roof_Steep"
    },
    {
      "x": -61,
      "y": 26,
      "z": 4,
      "name": "Rock_Calcite_Cobble_Roof_Steep",
      "filler": 1024
    },
    {
      "x": -61,
      "y": 22,
      "z": 5,
      "name": "Wood_Deadwood_Planks"
    },
    {
      "x": -61,
      "y": 23,
      "z": 5,
      "name": "Rock_Calcite_Cobble_Roof_Steep"
    },
    {
      "x": -61,
      "y": 24,
      "z": 5,
      "name": "Rock_Calcite_Cobble_Roof_Steep",
      "filler": 1024
    },
    {
      "x": -61,
      "y": 20,
      "z": 6,
      "name": "Wood_Deadwood_Planks"
    },
    {
      "x": -61,
      "y": 21,
      "z": 6,
      "name": "Rock_Calcite_Cobble_Roof_Steep"
    },
    {
      "x": -61,
      "y": 22,
      "z": 6,
      "name": "Rock_Calcite_Cobble_Roof_Steep",
      "filler": 1024
    },
    {
      "x": -61,
      "y": 18,
      "z": 7,
      "name": "Wood_Deadwood_Planks"
    },
    {
      "x": -61,
      "y": 19,
      "z": 7,
      "name": "Rock_Calcite_Cobble_Roof_Steep"
    },
    {
      "x": -61,
      "y": 20,
      "z": 7,
      "name": "Rock_Calcite_Cobble_Roof_Steep",
      "filler": 1024
    },
    {
      "x": -61,
      "y": 18,
      "z": 8,
      "name": "Rock_Calcite_Cobble_Roof_Hollow"
    },
    {
      "x": -61,
      "y": 11,
      "z": 10,
      "name": "Rock_Calcite_Cobble_Roof_Hollow",
      "rotation": 2
    },
    {
      "x": -61,
      "y": 11,
      "z": 11,
      "name": "Wood_Deadwood_Planks"
    },
    {
      "x": -61,
      "y": 12,
      "z": 11,
      "name": "Rock_Calcite_Cobble_Roof",
      "rotation": 2
    },
    {
      "x": -61,
      "y": 12,
      "z": 12,
      "name": "Wood_Deadwood_Planks"
    },
    {
      "x": -61,
      "y": 13,
      "z": 12,
      "name": "Rock_Calcite_Cobble_Roof",
      "rotation": 2
    },
    {
      "x": -61,
      "y": 13,
      "z": 13,
      "name": "Wood_Deadwood_Planks"
    },
    {
      "x": -61,
      "y": 14,
      "z": 13,
      "name": "Rock_Calcite_Cobble_Roof_Shallow",
      "rotation": 2
    },
    {
      "x": -61,
      "y": 14,
      "z": 14,
      "name": "Rock_Calcite_Cobble_Roof_Shallow",
      "filler": 32,
      "rotation": 2
    },
    {
      "x": -61,
      "y": 14,
      "z": 15,
      "name": "Wood_Deadwood_Planks"
    },
    {
      "x": -61,
      "y": 15,
      "z": 15,
      "name": "*Rock_Calcite_Cobble_Roof_Shallow_State_Definitions_Corner_Left",
      "rotation": 2
    },
    {
      "x": -61,
      "y": 14,
      "z": 16,
      "name": "Wood_Deadwood_Planks"
    },
    {
      "x": -61,
      "y": 15,
      "z": 16,
      "name": "*Rock_Calcite_Cobble_Roof_Shallow_State_Definitions_Corner_Left",
      "filler": 32,
      "rotation": 2
    },
    {
      "x": -61,
      "y": 14,
      "z": 17,
      "name": "Wood_Deadwood_Planks"
    },
    {
      "x": -61,
      "y": 15,
      "z": 17,
      "name": "Rock_Calcite_Cobble_Roof_Shallow",
      "rotation": 3
    },
    {
      "x": -61,
      "y": 14,
      "z": 18,
      "name": "Wood_Deadwood_Planks"
    },
    {
      "x": -61,
      "y": 15,
      "z": 18,
      "name": "Rock_Calcite_Cobble_Roof_Shallow",
      "rotation": 3
    },
    {
      "x": -61,
      "y": 14,
      "z": 19,
      "name": "Wood_Deadwood_Planks"
    },
    {
      "x": -61,
      "y": 15,
      "z": 19,
      "name": "Rock_Calcite_Cobble_Roof_Shallow",
      "rotation": 3
    },
    {
      "x": -61,
      "y": 14,
      "z": 20,
      "name": "Wood_Deadwood_Planks"
    },
    {
      "x": -61,
      "y": 15,
      "z": 20,
      "name": "Rock_Calcite_Cobble_Roof_Shallow",
      "rotation": 3
    },
    {
      "x": -61,
      "y": 14,
      "z": 21,
      "name": "Wood_Deadwood_Planks"
    },
    {
      "x": -61,
      "y": 15,
      "z": 21,
      "name": "Rock_Calcite_Cobble_Roof_Shallow",
      "rotation": 3
    },
    {
      "x": -61,
      "y": 14,
      "z": 22,
      "name": "Wood_Deadwood_Planks"
    },
    {
      "x": -61,
      "y": 15,
      "z": 22,
      "name": "Rock_Calcite_Cobble_Roof_Shallow",
      "rotation": 3
    },
    {
      "x": -61,
      "y": 14,
      "z": 23,
      "name": "Wood_Deadwood_Planks"
    },
    {
      "x": -61,
      "y": 15,
      "z": 23,
      "name": "Rock_Calcite_Cobble_Roof_Shallow",
      "rotation": 3
    },
    {
      "x": -61,
      "y": 14,
      "z": 24,
      "name": "Wood_Deadwood_Planks"
    },
    {
      "x": -61,
      "y": 15,
      "z": 24,
      "name": "Rock_Calcite_Cobble_Roof_Shallow",
      "rotation": 3
    },
    {
      "x": -61,
      "y": 14,
      "z": 25,
      "name": "Wood_Deadwood_Planks"
    },
    {
      "x": -61,
      "y": 15,
      "z": 25,
      "name": "Rock_Calcite_Cobble_Roof_Shallow",
      "rotation": 3
    },
    {
      "x": -61,
      "y": 14,
      "z": 26,
      "name": "Wood_Deadwood_Planks"
    },
    {
      "x": -61,
      "y": 15,
      "z": 26,
      "name": "Rock_Calcite_Cobble_Roof_Shallow",
      "rotation": 3
    },
    {
      "x": -61,
      "y": 14,
      "z": 27,
      "name": "Wood_Deadwood_Planks"
    },
    {
      "x": -61,
      "y": 15,
      "z": 27,
      "name": "*Rock_Calcite_Cobble_Roof_Shallow_State_Definitions_Corner_Left",
      "filler": 992,
      "rotation": 3
    },
    {
      "x": -61,
      "y": 14,
      "z": 28,
      "name": "Wood_Deadwood_Planks"
    },
    {
      "x": -61,
      "y": 15,
      "z": 28,
      "name": "*Rock_Calcite_Cobble_Roof_Shallow_State_Definitions_Corner_Left",
      "rotation": 3
    },
    {
      "x": -61,
      "y": 14,
      "z": 29,
      "name": "Rock_Calcite_Cobble_Roof_Shallow",
      "filler": 992
    },
    {
      "x": -61,
      "y": 13,
      "z": 30,
      "name": "Wood_Deadwood_Planks"
    },
    {
      "x": -61,
      "y": 14,
      "z": 30,
      "name": "Rock_Calcite_Cobble_Roof_Shallow"
    },
    {
      "x": -61,
      "y": 12,
      "z": 31,
      "name": "Wood_Deadwood_Planks"
    },
    {
      "x": -61,
      "y": 13,
      "z": 31,
      "name": "Rock_Calcite_Cobble_Roof"
    },
    {
      "x": -61,
      "y": 11,
      "z": 32,
      "name": "Wood_Deadwood_Planks"
    },
    {
      "x": -61,
      "y": 12,
      "z": 32,
      "name": "Rock_Calcite_Cobble_Roof"
    },
    {
      "x": -61,
      "y": 11,
      "z": 33,
      "name": "Rock_Calcite_Cobble_Roof_Hollow"
    },
    {
      "x": -60,
      "y": 5,
      "z": -22,
      "name": "Wood_Deadwood_Planks"
    },
    {
      "x": -60,
      "y": 6,
      "z": -22,
      "name": "Wood_Deadwood_Planks"
    },
    {
      "x": -60,
      "y": 7,
      "z": -22,
      "name": "Wood_Deadwood_Planks"
    },
    {
      "x": -60,
      "y": 8,
      "z": -22,
      "name": "Wood_Deadwood_Planks"
    },
    {
      "x": -60,
      "y": 9,
      "z": -22,
      "name": "Wood_Deadwood_Planks"
    },
    {
      "x": -60,
      "y": 10,
      "z": -22,
      "name": "Wood_Deadwood_Planks"
    },
    {
      "x": -60,
      "y": 11,
      "z": -22,
      "name": "Wood_Deadwood_Planks"
    },
    {
      "x": -60,
      "y": 12,
      "z": -22,
      "name": "Wood_Deadwood_Planks"
    },
    {
      "x": -60,
      "y": 13,
      "z": -22,
      "name": "Wood_Deadwood_Planks"
    },
    {
      "x": -60,
      "y": 14,
      "z": -22,
      "name": "Wood_Deadwood_Planks"
    },
    {
      "x": -60,
      "y": 16,
      "z": -22,
      "name": "Rock_Calcite_Cobble_Roof_Shallow",
      "filler": 1,
      "rotation": 3
    },
    {
      "x": -60,
      "y": 5,
      "z": -21,
      "name": "Wood_Deadwood_Planks"
    },
    {
      "x": -60,
      "y": 11,
      "z": -21,
      "name": "Wood_Deadwood_Planks"
    },
    {
      "x": -60,
      "y": 16,
      "z": -21,
      "name": "Rock_Calcite_Cobble_Roof_Shallow",
      "filler": 1,
      "rotation": 3
    },
    {
      "x": -60,
      "y": 5,
      "z": -20,
      "name": "Wood_Deadwood_Planks"
    },
    {
      "x": -60,
      "y": 11,
      "z": -20,
      "name": "Wood_Deadwood_Planks"
    },
    {
      "x": -60,
      "y": 16,
      "z": -20,
      "name": "Rock_Calcite_Cobble_Roof_Shallow",
      "filler": 1,
      "rotation": 3
    },
    {
      "x": -60,
      "y": 5,
      "z": -19,
      "name": "Wood_Deadwood_Planks"
    },
    {
      "x": -60,
      "y": 11,
      "z": -19,
      "name": "Wood_Deadwood_Planks"
    },
    {
      "x": -60,
      "y": 16,
      "z": -19,
      "name": "Rock_Calcite_Cobble_Roof_Shallow",
      "filler": 1,
      "rotation": 3
    },
    {
      "x": -60,
      "y": 0,
      "z": -18,
      "name": "Wood_Deadwood_Planks"
    },
    {
      "x": -60,
      "y": 1,
      "z": -18,
      "name": "Wood_Deadwood_Planks"
    },
    {
      "x": -60,
      "y": 2,
      "z": -18,
      "name": "Wood_Deadwood_Planks"
    },
    {
      "x": -60,
      "y": 3,
      "z": -18,
      "name": "Wood_Deadwood_Planks"
    },
    {
      "x": -60,
      "y": 4,
      "z": -18,
      "name": "Wood_Deadwood_Planks"
    },
    {
      "x": -60,
      "y": 5,
      "z": -18,
      "name": "Wood_Deadwood_Planks"
    },
    {
      "x": -60,
      "y": 11,
      "z": -18,
      "name": "Wood_Deadwood_Planks"
    },
    {
      "x": -60,
      "y": 16,
      "z": -18,
      "name": "Rock_Calcite_Cobble_Roof_Shallow",
      "filler": 1,
      "rotation": 3
    },
    {
      "x": -60,
      "y": 0,
      "z": -17,
      "name": "Wood_Deadwood_Planks"
    },
    {
      "x": -60,
      "y": 1,
      "z": -17,
      "name": "Wood_Deadwood_Planks"
    },
    {
      "x": -60,
      "y": 2,
      "z": -17,
      "name": "Wood_Deadwood_Planks"
    },
    {
      "x": -60,
      "y": 3,
      "z": -17,
      "name": "Wood_Deadwood_Planks"
    },
    {
      "x": -60,
      "y": 4,
      "z": -17,
      "name": "Wood_Deadwood_Planks"
    },
    {
      "x": -60,
      "y": 5,
      "z": -17,
      "name": "Wood_Deadwood_Planks"
    },
    {
      "x": -60,
      "y": 6,
      "z": -17,
      "name": "Wood_Deadwood_Planks"
    },
    {
      "x": -60,
      "y": 7,
      "z": -17,
      "name": "Wood_Deadwood_Planks"
    },
    {
      "x": -60,
      "y": 8,
      "z": -17,
      "name": "Wood_Deadwood_Planks"
    },
    {
      "x": -60,
      "y": 9,
      "z": -17,
      "name": "Wood_Deadwood_Planks"
    },
    {
      "x": -60,
      "y": 10,
      "z": -17,
      "name": "Wood_Deadwood_Planks"
    },
    {
      "x": -60,
      "y": 11,
      "z": -17,
      "name": "Wood_Deadwood_Planks"
    },
    {
      "x": -60,
      "y": 12,
      "z": -17,
      "name": "Wood_Deadwood_Planks"
    },
    {
      "x": -60,
      "y": 13,
      "z": -17,
      "name": "Wood_Deadwood_Planks"
    },
    {
      "x": -60,
      "y": 16,
      "z": -17,
      "name": "Rock_Calcite_Cobble_Roof_Shallow",
      "filler": 1,
      "rotation": 3
    },
    {
      "x": -60,
      "y": 0,
      "z": -16,
      "name": "Wood_Deadwood_Planks"
    },
    {
      "x": -60,
      "y": 1,
      "z": -16,
      "name": "Wood_Deadwood_Planks"
    },
    {
      "x": -60,
      "y": 2,
      "z": -16,
      "name": "Wood_Deadwood_Planks"
    },
    {
      "x": -60,
      "y": 3,
      "z": -16,
      "name": "Wood_Deadwood_Planks"
    },
    {
      "x": -60,
      "y": 4,
      "z": -16,
      "name": "Wood_Deadwood_Planks"
    },
    {
      "x": -60,
      "y": 5,
      "z": -16,
      "name": "Wood_Deadwood_Planks"
    },
    {
      "x": -60,
      "y": 6,
      "z": -16,
      "name": "Wood_Deadwood_Planks"
    },
    {
      "x": -60,
      "y": 7,
      "z": -16,
      "name": "Wood_Deadwood_Planks"
    },
    {
      "x": -60,
      "y": 8,
      "z": -16,
      "name": "Wood_Deadwood_Planks"
    },
    {
      "x": -60,
      "y": 9,
      "z": -16,
      "name": "Wood_Deadwood_Planks"
    },
    {
      "x": -60,
      "y": 10,
      "z": -16,
      "name": "Wood_Deadwood_Planks"
    },
    {
      "x": -60,
      "y": 16,
      "z": -16,
      "name": "Rock_Calcite_Cobble_Roof_Shallow",
      "filler": 1,
      "rotation": 3
    },
    {
      "x": -60,
      "y": 0,
      "z": -15,
      "name": "Wood_Deadwood_Planks"
    },
    {
      "x": -60,
      "y": 1,
      "z": -15,
      "name": "Wood_Deadwood_Planks"
    },
    {
      "x": -60,
      "y": 2,
      "z": -15,
      "name": "Wood_Deadwood_Planks"
    },
    {
      "x": -60,
      "y": 3,
      "z": -15,
      "name": "Wood_Deadwood_Planks"
    },
    {
      "x": -60,
      "y": 4,
      "z": -15,
      "name": "Wood_Deadwood_Planks"
    },
    {
      "x": -60,
      "y": 5,
      "z": -15,
      "name": "Wood_Deadwood_Planks"
    },
    {
      "x": -60,
      "y": 6,
      "z": -15,
      "name": "Wood_Deadwood_Planks"
    },
    {
      "x": -60,
      "y": 7,
      "z": -15,
      "name": "Wood_Deadwood_Planks"
    },
    {
      "x": -60,
      "y": 8,
      "z": -15,
      "name": "Wood_Deadwood_Planks"
    },
    {
      "x": -60,
      "y": 9,
      "z": -15,
      "name": "Wood_Deadwood_Planks"
    },
    {
      "x": -60,
      "y": 10,
      "z": -15,
      "name": "Wood_Deadwood_Planks"
    },
    {
      "x": -60,
      "y": 16,
      "z": -15,
      "name": "Rock_Calcite_Cobble_Roof_Shallow",
      "filler": 1,
      "rotation": 3
    },
    {
      "x": -60,
      "y": 0,
      "z": -14,
      "name": "Wood_Deadwood_Planks"
    },
    {
      "x": -60,
      "y": 1,
      "z": -14,
      "name": "Wood_Deadwood_Planks"
    },
    {
      "x": -60,
      "y": 2,
      "z": -14,
      "name": "Wood_Deadwood_Planks"
    },
    {
      "x": -60,
      "y": 3,
      "z": -14,
      "name": "Wood_Deadwood_Planks"
    },
    {
      "x": -60,
      "y": 4,
      "z": -14,
      "name": "Wood_Deadwood_Planks"
    },
    {
      "x": -60,
      "y": 5,
      "z": -14,
      "name": "Wood_Deadwood_Planks"
    },
    {
      "x": -60,
      "y": 6,
      "z": -14,
      "name": "Wood_Deadwood_Planks"
    },
    {
      "x": -60,
      "y": 7,
      "z": -14,
      "name": "Wood_Deadwood_Planks"
    },
    {
      "x": -60,
      "y": 8,
      "z": -14,
      "name": "Wood_Deadwood_Planks"
    },
    {
      "x": -60,
      "y": 9,
      "z": -14,
      "name": "Wood_Deadwood_Planks"
    },
    {
      "x": -60,
      "y": 10,
      "z": -14,
      "name": "Wood_Deadwood_Planks"
    },
    {
      "x": -60,
      "y": 16,
      "z": -14,
      "name": "Rock_Calcite_Cobble_Roof_Shallow",
      "filler": 1,
      "rotation": 3
    },
    {
      "x": -60,
      "y": 0,
      "z": -13,
      "name": "Wood_Deadwood_Planks"
    },
    {
      "x": -60,
      "y": 1,
      "z": -13,
      "name": "Wood_Deadwood_Planks"
    },
    {
      "x": -60,
      "y": 2,
      "z": -13,
      "name": "Wood_Deadwood_Planks"
    },
    {
      "x": -60,
      "y": 3,
      "z": -13,
      "name": "Wood_Deadwood_Planks"
    },
    {
      "x": -60,
      "y": 4,
      "z": -13,
      "name": "Wood_Deadwood_Planks"
    },
    {
      "x": -60,
      "y": 5,
      "z": -13,
      "name": "Wood_Deadwood_Planks"
    },
    {
      "x": -60,
      "y": 6,
      "z": -13,
      "name": "Wood_Deadwood_Planks"
    },
    {
      "x": -60,
      "y": 7,
      "z": -13,
      "name": "Wood_Deadwood_Planks"
    },
    {
      "x": -60,
      "y": 8,
      "z": -13,
      "name": "Wood_Deadwood_Planks"
    },
    {
      "x": -60,
      "y": 9,
      "z": -13,
      "name": "Wood_Deadwood_Planks"
    },
    {
      "x": -60,
      "y": 10,
      "z": -13,
      "name": "Wood_Deadwood_Planks"
    },
    {
      "x": -60,
      "y": 16,
      "z": -13,
      "name": "Rock_Calcite_Cobble_Roof_Shallow",
      "filler": 1,
      "rotation": 3
    },
    {
      "x": -60,
      "y": 0,
      "z": -12,
      "name": "Wood_Deadwood_Planks"
    },
    {
      "x": -60,
      "y": 1,
      "z": -12,
      "name": "Wood_Deadwood_Planks"
    },
    {
      "x": -60,
      "y": 2,
      "z": -12,
      "name": "Wood_Deadwood_Planks"
    },
    {
      "x": -60,
      "y": 3,
      "z": -12,
      "name": "Wood_Deadwood_Planks"
    },
    {
      "x": -60,
      "y": 4,
      "z": -12,
      "name": "Wood_Deadwood_Planks"
    },
    {
      "x": -60,
      "y": 5,
      "z": -12,
      "name": "Wood_Deadwood_Planks"
    },
    {
      "x": -60,
      "y": 6,
      "z": -12,
      "name": "Wood_Deadwood_Planks"
    },
    {
      "x": -60,
      "y": 7,
      "z": -12,
      "name": "Wood_Deadwood_Planks"
    },
    {
      "x": -60,
      "y": 8,
      "z": -12,
      "name": "Wood_Deadwood_Planks"
    },
    {
      "x": -60,
      "y": 9,
      "z": -12,
      "name": "Wood_Deadwood_Planks"
    },
    {
      "x": -60,
      "y": 10,
      "z": -12,
      "name": "Wood_Deadwood_Planks"
    },
    {
      "x": -60,
      "y": 16,
      "z": -12,
      "name": "Rock_Calcite_Cobble_Roof_Shallow",
      "filler": 1,
      "rotation": 3
    },
    {
      "x": -60,
      "y": 0,
      "z": -11,
      "name": "Wood_Deadwood_Planks"
    },
    {
      "x": -60,
      "y": 1,
      "z": -11,
      "name": "Wood_Deadwood_Planks"
    },
    {
      "x": -60,
      "y": 2,
      "z": -11,
      "name": "Wood_Deadwood_Planks"
    },
    {
      "x": -60,
      "y": 3,
      "z": -11,
      "name": "Wood_Deadwood_Planks"
    },
    {
      "x": -60,
      "y": 4,
      "z": -11,
      "name": "Wood_Deadwood_Planks"
    },
    {
      "x": -60,
      "y": 5,
      "z": -11,
      "name": "Furniture_Village_Window",
      "rotation": 1
    },
    {
      "x": -60,
      "y": 6,
      "z": -11,
      "name": "Furniture_Village_Window",
      "rotation": 1
    },
    {
      "x": -60,
      "y": 7,
      "z": -11,
      "name": "Furniture_Village_Window",
      "rotation": 1
    },
    {
      "x": -60,
      "y": 8,
      "z": -11,
      "name": "Furniture_Village_Window",
      "rotation": 1
    },
    {
      "x": -60,
      "y": 9,
      "z": -11,
      "name": "Wood_Deadwood_Planks"
    },
    {
      "x": -60,
      "y": 10,
      "z": -11,
      "name": "Wood_Deadwood_Planks"
    },
    {
      "x": -60,
      "y": 16,
      "z": -11,
      "name": "Rock_Calcite_Cobble_Roof_Shallow",
      "filler": 1,
      "rotation": 3
    },
    {
      "x": -60,
      "y": 0,
      "z": -10,
      "name": "Wood_Deadwood_Planks"
    },
    {
      "x": -60,
      "y": 1,
      "z": -10,
      "name": "Wood_Deadwood_Planks"
    },
    {
      "x": -60,
      "y": 2,
      "z": -10,
      "name": "Wood_Deadwood_Planks"
    },
    {
      "x": -60,
      "y": 3,
      "z": -10,
      "name": "Wood_Deadwood_Planks"
    },
    {
      "x": -60,
      "y": 4,
      "z": -10,
      "name": "Wood_Deadwood_Planks"
    },
    {
      "x": -60,
      "y": 5,
      "z": -10,
      "name": "Furniture_Village_Window",
      "rotation": 1
    },
    {
      "x": -60,
      "y": 6,
      "z": -10,
      "name": "Furniture_Village_Window",
      "rotation": 1
    },
    {
      "x": -60,
      "y": 7,
      "z": -10,
      "name": "Furniture_Village_Window",
      "rotation": 1
    },
    {
      "x": -60,
      "y": 8,
      "z": -10,
      "name": "Furniture_Village_Window",
      "rotation": 1
    },
    {
      "x": -60,
      "y": 9,
      "z": -10,
      "name": "Wood_Deadwood_Planks"
    },
    {
      "x": -60,
      "y": 10,
      "z": -10,
      "name": "Wood_Deadwood_Planks"
    },
    {
      "x": -60,
      "y": 16,
      "z": -10,
      "name": "Rock_Calcite_Cobble_Roof_Shallow",
      "filler": 1,
      "rotation": 3
    },
    {
      "x": -60,
      "y": 0,
      "z": -9,
      "name": "Wood_Deadwood_Planks"
    },
    {
      "x": -60,
      "y": 1,
      "z": -9,
      "name": "Wood_Deadwood_Planks"
    },
    {
      "x": -60,
      "y": 2,
      "z": -9,
      "name": "Wood_Deadwood_Planks"
    },
    {
      "x": -60,
      "y": 3,
      "z": -9,
      "name": "Wood_Deadwood_Planks"
    },
    {
      "x": -60,
      "y": 4,
      "z": -9,
      "name": "Wood_Deadwood_Planks"
    },
    {
      "x": -60,
      "y": 5,
      "z": -9,
      "name": "Furniture_Village_Window",
      "rotation": 1
    },
    {
      "x": -60,
      "y": 6,
      "z": -9,
      "name": "Furniture_Village_Window",
      "rotation": 1
    },
    {
      "x": -60,
      "y": 7,
      "z": -9,
      "name": "Furniture_Village_Window",
      "rotation": 1
    },
    {
      "x": -60,
      "y": 8,
      "z": -9,
      "name": "Furniture_Village_Window",
      "rotation": 1
    },
    {
      "x": -60,
      "y": 9,
      "z": -9,
      "name": "Wood_Deadwood_Planks"
    },
    {
      "x": -60,
      "y": 10,
      "z": -9,
      "name": "Wood_Deadwood_Planks"
    },
    {
      "x": -60,
      "y": 16,
      "z": -9,
      "name": "Rock_Calcite_Cobble_Roof_Shallow",
      "filler": 1,
      "rotation": 3
    },
    {
      "x": -60,
      "y": 0,
      "z": -8,
      "name": "Wood_Deadwood_Planks"
    },
    {
      "x": -60,
      "y": 1,
      "z": -8,
      "name": "Wood_Deadwood_Planks"
    },
    {
      "x": -60,
      "y": 2,
      "z": -8,
      "name": "Wood_Deadwood_Planks"
    },
    {
      "x": -60,
      "y": 3,
      "z": -8,
      "name": "Wood_Deadwood_Planks"
    },
    {
      "x": -60,
      "y": 4,
      "z": -8,
      "name": "Wood_Deadwood_Planks"
    },
    {
      "x": -60,
      "y": 5,
      "z": -8,
      "name": "Wood_Deadwood_Planks"
    },
    {
      "x": -60,
      "y": 6,
      "z": -8,
      "name": "Wood_Deadwood_Planks"
    },
    {
      "x": -60,
      "y": 7,
      "z": -8,
      "name": "Wood_Deadwood_Planks"
    },
    {
      "x": -60,
      "y": 8,
      "z": -8,
      "name": "Wood_Deadwood_Planks"
    },
    {
      "x": -60,
      "y": 9,
      "z": -8,
      "name": "Wood_Deadwood_Planks"
    },
    {
      "x": -60,
      "y": 10,
      "z": -8,
      "name": "Wood_Deadwood_Planks"
    },
    {
      "x": -60,
      "y": 16,
      "z": -8,
      "name": "Rock_Calcite_Cobble_Roof_Shallow",
      "filler": 1,
      "rotation": 3
    },
    {
      "x": -60,
      "y": 0,
      "z": -7,
      "name": "Wood_Deadwood_Planks"
    },
    {
      "x": -60,
      "y": 1,
      "z": -7,
      "name": "Wood_Deadwood_Planks"
    },
    {
      "x": -60,
      "y": 2,
      "z": -7,
      "name": "Wood_Deadwood_Planks"
    },
    {
      "x": -60,
      "y": 3,
      "z": -7,
      "name": "Wood_Deadwood_Planks"
    },
    {
      "x": -60,
      "y": 4,
      "z": -7,
      "name": "Wood_Deadwood_Planks"
    },
    {
      "x": -60,
      "y": 5,
      "z": -7,
      "name": "Wood_Deadwood_Planks"
    },
    {
      "x": -60,
      "y": 6,
      "z": -7,
      "name": "Wood_Deadwood_Planks"
    },
    {
      "x": -60,
      "y": 7,
      "z": -7,
      "name": "Wood_Deadwood_Planks"
    },
    {
      "x": -60,
      "y": 8,
      "z": -7,
      "name": "Wood_Deadwood_Planks"
    },
    {
      "x": -60,
      "y": 9,
      "z": -7,
      "name": "Wood_Deadwood_Planks"
    },
    {
      "x": -60,
      "y": 10,
      "z": -7,
      "name": "Wood_Deadwood_Planks"
    },
    {
      "x": -60,
      "y": 15,
      "z": -7,
      "name": "Wood_Deadwood_Planks"
    },
    {
      "x": -60,
      "y": 16,
      "z": -7,
      "name": "Rock_Calcite_Cobble_Roof_Shallow",
      "filler": 1,
      "rotation": 3
    },
    {
      "x": -60,
      "y": 18,
      "z": -7,
      "name": "Rock_Calcite_Cobble_Roof_Hollow",
      "rotation": 2
    },
    {
      "x": -60,
      "y": 18,
      "z": -6,
      "name": "Wood_Deadwood_Planks"
    },
    {
      "x": -60,
      "y": 19,
      "z": -6,
      "name": "Rock_Calcite_Cobble_Roof_Steep",
      "rotation": 2
    },
    {
      "x": -60,
      "y": 20,
      "z": -6,
      "name": "Rock_Calcite_Cobble_Roof_Steep",
      "filler": 1024,
      "rotation": 2
    },
    {
      "x": -60,
      "y": 20,
      "z": -5,
      "name": "Wood_Deadwood_Planks"
    },
    {
      "x": -60,
      "y": 21,
      "z": -5,
      "name": "Rock_Calcite_Cobble_Roof_Steep",
      "rotation": 2
    },
    {
      "x": -60,
      "y": 22,
      "z": -5,
      "name": "Rock_Calcite_Cobble_Roof_Steep",
      "filler": 1024,
      "rotation": 2
    },
    {
      "x": -60,
      "y": 22,
      "z": -4,
      "name": "Wood_Deadwood_Planks"
    },
    {
      "x": -60,
      "y": 23,
      "z": -4,
      "name": "Rock_Calcite_Cobble_Roof_Steep",
      "rotation": 2
    },
    {
      "x": -60,
      "y": 24,
      "z": -4,
      "name": "Rock_Calcite_Cobble_Roof_Steep",
      "filler": 1024,
      "rotation": 2
    },
    {
      "x": -60,
      "y": 24,
      "z": -3,
      "name": "Wood_Deadwood_Planks"
    },
    {
      "x": -60,
      "y": 25,
      "z": -3,
      "name": "Rock_Calcite_Cobble_Roof_Steep",
      "rotation": 2
    },
    {
      "x": -60,
      "y": 26,
      "z": -3,
      "name": "Rock_Calcite_Cobble_Roof_Steep",
      "filler": 1024,
      "rotation": 2
    },
    {
      "x": -60,
      "y": 26,
      "z": -2,
      "name": "Wood_Deadwood_Planks"
    },
    {
      "x": -60,
      "y": 27,
      "z": -2,
      "name": "Rock_Calcite_Cobble_Roof",
      "rotation": 2
    },
    {
      "x": -60,
      "y": 26,
      "z": -1,
      "name": "Wood_Deadwood_Planks"
    },
    {
      "x": -60,
      "y": 27,
      "z": -1,
      "name": "Wood_Deadwood_Planks"
    },
    {
      "x": -60,
      "y": 28,
      "z": -1,
      "name": "Rock_Calcite_Cobble_Roof_Flat",
      "rotation": 3
    },
    {
      "x": -60,
      "y": 26,
      "z": 0,
      "name": "Wood_Deadwood_Planks"
    },
    {
      "x": -60,
      "y": 27,
      "z": 0,
      "name": "Wood_Deadwood_Planks"
    },
    {
      "x": -60,
      "y": 28,
      "z": 0,
      "name": "Rock_Calcite_Cobble_Roof_Flat",
      "rotation": 3
    },
    {
      "x": -60,
      "y": 26,
      "z": 1,
      "name": "Wood_Deadwood_Planks"
    },
    {
      "x": -60,
      "y": 27,
      "z": 1,
      "name": "Wood_Deadwood_Planks"
    },
    {
      "x": -60,
      "y": 28,
      "z": 1,
      "name": "Rock_Calcite_Cobble_Roof_Flat",
      "rotation": 3
    },
    {
      "x": -60,
      "y": 26,
      "z": 2,
      "name": "Wood_Deadwood_Planks"
    },
    {
      "x": -60,
      "y": 27,
      "z": 2,
      "name": "Wood_Deadwood_Planks"
    },
    {
      "x": -60,
      "y": 28,
      "z": 2,
      "name": "Rock_Calcite_Cobble_Roof_Flat",
      "rotation": 3
    },
    {
      "x": -60,
      "y": 26,
      "z": 3,
      "name": "Wood_Deadwood_Planks"
    },
    {
      "x": -60,
      "y": 27,
      "z": 3,
      "name": "Rock_Calcite_Cobble_Roof"
    },
    {
      "x": -60,
      "y": 24,
      "z": 4,
      "name": "Wood_Deadwood_Planks"
    },
    {
      "x": -60,
      "y": 25,
      "z": 4,
      "name": "Rock_Calcite_Cobble_Roof_Steep"
    },
    {
      "x": -60,
      "y": 26,
      "z": 4,
      "name": "Rock_Calcite_Cobble_Roof_Steep",
      "filler": 1024
    },
    {
      "x": -60,
      "y": 22,
      "z": 5,
      "name": "Wood_Deadwood_Planks"
    },
    {
      "x": -60,
      "y": 23,
      "z": 5,
      "name": "Rock_Calcite_Cobble_Roof_Steep"
    },
    {
      "x": -60,
      "y": 24,
      "z": 5,
      "name": "Rock_Calcite_Cobble_Roof_Steep",
      "filler": 1024
    },
    {
      "x": -60,
      "y": 20,
      "z": 6,
      "name": "Wood_Deadwood_Planks"
    },
    {
      "x": -60,
      "y": 21,
      "z": 6,
      "name": "Rock_Calcite_Cobble_Roof_Steep"
    },
    {
      "x": -60,
      "y": 22,
      "z": 6,
      "name": "Rock_Calcite_Cobble_Roof_Steep",
      "filler": 1024
    },
    {
      "x": -60,
      "y": 18,
      "z": 7,
      "name": "Wood_Deadwood_Planks"
    },
    {
      "x": -60,
      "y": 19,
      "z": 7,
      "name": "Rock_Calcite_Cobble_Roof_Steep"
    },
    {
      "x": -60,
      "y": 20,
      "z": 7,
      "name": "Rock_Calcite_Cobble_Roof_Steep",
      "filler": 1024
    },
    {
      "x": -60,
      "y": 10,
      "z": 8,
      "name": "Rock_Calcite_Cobble_Roof_Hollow",
      "rotation": 3
    },
    {
      "x": -60,
      "y": 18,
      "z": 8,
      "name": "Rock_Calcite_Cobble_Roof_Hollow"
    },
    {
      "x": -60,
      "y": 10,
